#VRML_SIM R2020a utf8
WorldInfo {
  basicTimeStep 16
}
Viewpoint {
  orientation 0.378996663027297 0.9253920124629837 -0.003339563426894918 5.637254841099733
  position -29.01963787541275 16.86453850179187 65.64439710502853
}
TexturedBackground {
  texture "factory"
  luminosity 2
  reflections FALSE
}
Robot {
  translation -0.0241286 0.7 20.15
  rotation 0 1 0 3.14
  children [
    DEF cam_f Camera {
      translation 0 -0.05 1.5
      rotation 0 1 0 3.14
      children [
        Shape {
          appearance PBRAppearance {
            baseColor 0.4 0 0
          }
          geometry Cylinder {
            height 0.1
            radius 0.05
          }
        }
      ]
      boundingObject Cylinder {
        height 0.1
        radius 0.05
      }
      physics Physics {
        density 1
      }
      fieldOfView 0.75
      width 18
      height 10
      far 10
    }
    DEF ls_f LightSensor {
      translation 0 0.2 1.5
      rotation 0 1 0 -1.57
      children [
        Shape {
          appearance PBRAppearance {
            baseColor 0 0 0
            metalness 0
          }
          geometry Box {
            size 0.1 0.1 0.1
          }
        }
      ]
      name "ls_front"
      boundingObject Shape {
        appearance PBRAppearance {
        }
        geometry Cylinder {
          height 0.1
          radius 0.05
        }
      }
      physics Physics {
        density 1
      }
      lookupTable [
        0 0 0
        5 1000 0
      ]
    }
    DEF ds_fl DistanceSensor {
      translation 0.65 -0.2 1.5
      rotation 0 1 0 -1.047
      children [
        Shape {
          appearance PBRAppearance {
          }
          geometry Box {
            size 0.1 0.1 0.1
          }
        }
      ]
      name "ds_fl"
      boundingObject Shape {
        appearance PBRAppearance {
        }
        geometry Box {
          size 0.1 0.1 0.1
        }
      }
      physics Physics {
        density 1
      }
      lookupTable [
        0 0 0
        5 1000 0
      ]
    }
    DEF ds_lf DistanceSensor {
      translation 0.75 -0.2 1.45
      children [
        Shape {
          appearance PBRAppearance {
          }
          geometry Box {
            size 0.1 0.1 0.1
          }
        }
      ]
      name "ds_lf"
      boundingObject Shape {
        appearance PBRAppearance {
        }
        geometry Box {
          size 0.1 0.1 0.1
        }
      }
      physics Physics {
        density 1
      }
      lookupTable [
        0 0 0
        5 1000 0
      ]
    }
    DEF ds_lc DistanceSensor {
      translation 0.75 -0.2 0
      children [
        Shape {
          appearance PBRAppearance {
          }
          geometry Box {
            size 0.1 0.1 0.1
          }
        }
      ]
      name "ds_lc"
      boundingObject Shape {
        appearance PBRAppearance {
        }
        geometry Box {
          size 0.1 0.1 0.1
        }
      }
      physics Physics {
        density 1
      }
      lookupTable [
        0 0 0
        5 1000 0
      ]
    }
    DEF ds_fr DistanceSensor {
      translation -0.65 -0.2 1.5
      rotation 0 1 0 -2.09
      children [
        Shape {
          appearance PBRAppearance {
          }
          geometry Box {
            size 0.1 0.1 0.1
          }
        }
      ]
      name "ds_fr"
      boundingObject Shape {
        appearance PBRAppearance {
        }
        geometry Box {
          size 0.1 0.1 0.1
        }
      }
      physics Physics {
        density 1
      }
      lookupTable [
        0 0 0
        5 1000 0
      ]
    }
    DEF ds_rf DistanceSensor {
      translation -0.75 -0.2 1.45
      rotation 0 1 0 -3.14
      children [
        Shape {
          appearance PBRAppearance {
          }
          geometry Box {
            size 0.1 0.1 0.1
          }
        }
      ]
      name "ds_rf"
      boundingObject Shape {
        appearance PBRAppearance {
        }
        geometry Box {
          size 0.1 0.1 0.1
        }
      }
      physics Physics {
        density 1
      }
      lookupTable [
        0 0 0
        5 1000 0
      ]
    }
    DEF ds_rc DistanceSensor {
      translation -0.75 -0.2 0
      rotation 0 1 0 -3.14
      children [
        Shape {
          appearance PBRAppearance {
          }
          geometry Box {
            size 0.1 0.1 0.1
          }
        }
      ]
      name "ds_rc"
      boundingObject Shape {
        appearance PBRAppearance {
        }
        geometry Box {
          size 0.1 0.1 0.1
        }
      }
      physics Physics {
        density 1
      }
      lookupTable [
        0 0 0
        5 1000 0
      ]
    }
    DEF ds_fc DistanceSensor {
      translation 0 -0.2 1.5
      rotation 0 1 0 -1.57
      children [
        Shape {
          appearance PBRAppearance {
          }
          geometry Box {
            size 0.1 0.1 0.1
          }
        }
      ]
      name "ds_fc"
      boundingObject Shape {
        appearance PBRAppearance {
        }
        geometry Box {
          size 0.1 0.1 0.1
        }
      }
      physics Physics {
        density 1
      }
      lookupTable [
        0 0 0
        5 1000 0
      ]
    }
    DEF ds_fcr DistanceSensor {
      translation -0.325 -0.2 1.5
      rotation 0 1 0 -1.833
      children [
        Shape {
          appearance PBRAppearance {
          }
          geometry Box {
            size 0.1 0.1 0.1
          }
        }
      ]
      name "ds_fcr"
      boundingObject Shape {
        appearance PBRAppearance {
        }
        geometry Box {
          size 0.1 0.1 0.1
        }
      }
      physics Physics {
        density 1
      }
      lookupTable [
        0 0 0
        5 1000 0
      ]
    }
    DEF ds_fcl DistanceSensor {
      translation 0.325 -0.2 1.5
      rotation 0 1 0 -1.309
      children [
        Shape {
          appearance PBRAppearance {
          }
          geometry Box {
            size 0.1 0.1 0.1
          }
        }
      ]
      name "ds_fcl"
      boundingObject Shape {
        appearance PBRAppearance {
        }
        geometry Box {
          size 0.1 0.1 0.1
        }
      }
      physics Physics {
        density 1
      }
      lookupTable [
        0 0 0
        5 1000 0
      ]
    }
    Transform {
      translation 0 0.3 0
      rotation 1 0 0 1.57
      children [
        Shape {
          appearance PBRAppearance {
            transparency 0.5
          }
          geometry Capsule {
            height 0.7
            radius 0.6
          }
        }
      ]
    }
    DEF wheelFL HingeJoint {
      jointParameters HingeJointParameters {
        anchor 0.85 -0.3 0.9
      }
      device [
        DEF wheelFL RotationalMotor {
          name "wheelFL"
          maxTorque 30
        }
      ]
      endPoint DEF wheelFL Solid {
        translation 0.85 -0.3 0.9
        rotation 0 0 1 1.5699999999999963
        children [
          DEF wheel Shape {
            appearance PBRAppearance {
              baseColor 0 0 0
              metalness 0
            }
            geometry Cylinder {
              height 0.2
              radius 0.4
            }
          }
        ]
        name "wheelFL"
        boundingObject USE wheel
        physics DEF physics_wheel Physics {
          density 10
        }
      }
    }
    DEF wheelRL HingeJoint {
      jointParameters HingeJointParameters {
        anchor 0.85 -0.3 -0.9
      }
      device [
        DEF wheelRL RotationalMotor {
          name "wheelRL"
          maxTorque 30
        }
      ]
      endPoint DEF wheelRL Solid {
        translation 0.85 -0.3 -0.9
        rotation 0 0 1 1.5699999999999963
        children [
          DEF wheel Shape {
            appearance PBRAppearance {
              baseColor 0 0 0
              metalness 0
            }
            geometry Cylinder {
              height 0.2
              radius 0.4
            }
          }
        ]
        name "wheelRL"
        boundingObject USE wheel
        physics DEF physics_wheel Physics {
          density 10
        }
      }
    }
    DEF wheelRR HingeJoint {
      jointParameters HingeJointParameters {
        anchor -0.85 -0.3 -0.9
      }
      device [
        DEF wheelRR RotationalMotor {
          name "wheelRR"
          maxTorque 30
        }
      ]
      endPoint DEF wheelRR Solid {
        translation -0.85 -0.3 -0.9
        rotation 0 0 1 1.5699999999999963
        children [
          DEF wheel Shape {
            appearance PBRAppearance {
              baseColor 0 0 0
              metalness 0
            }
            geometry Cylinder {
              height 0.2
              radius 0.4
            }
          }
        ]
        name "wheelRR"
        boundingObject USE wheel
        physics DEF physics_wheel Physics {
          density 10
        }
      }
    }
    DEF wheelFR HingeJoint {
      jointParameters HingeJointParameters {
        anchor -0.85 -0.3 0.9
      }
      device [
        DEF wheelFR RotationalMotor {
          name "wheelFR"
          maxTorque 30
        }
      ]
      endPoint DEF wheelFR Solid {
        translation -0.85 -0.3 0.9
        rotation 0 0 1 1.5699999999999956
        children [
          DEF wheel Shape {
            appearance PBRAppearance {
              baseColor 0 0 0
              metalness 0
            }
            geometry Cylinder {
              height 0.2
              radius 0.4
            }
          }
        ]
        name "wheelFR"
        boundingObject USE wheel
        physics DEF physics_wheel Physics {
          density 10
        }
      }
    }
    DEF car_body Shape {
      appearance PBRAppearance {
        baseColor 0 0.1 0.5
      }
      geometry Box {
        size 1.5 0.6 3
      }
    }
  ]
  boundingObject USE car_body
  physics Physics {
    density 10
  }
  recognitionColors [
    0 0 0
  ]
  controller "webots_controller"
}
DEF environment Solid {
  children [
    Solid {
      translation 50 0 -30
    }
    Solid {
      translation 0.69 0.4 -14.85
      rotation 0 1 0 3.1416
      children [
        CrashBarrier {
          translation -0.75 -0.3 0
          name "crash barrier(1)"
          path [
            0 0 0
            1.5 0 0
          ]
        }
      ]
      name "solid(1)"
      boundingObject Box {
        size 1.5 0.7 0.1
      }
      physics Physics {
        density -1
        mass 5
      }
    }
    Pole {
      translation 32.11 0 -135.17
    }
    RectangularPanel {
      translation 32.0631 1.79 -135.19
      rotation 0 1 0 1.309
    }
    BusStop {
      translation 55.0094 0 -137.66
      rotation 0 1 0 -3.1415853071795863
      name "bus stop(3)"
    }
    BusStop {
      translation 56.01 0 63.8801
      rotation 0 -1 0 -5.307179586466759e-06
      name "bus stop(2)"
    }
    BusStop {
      translation 102.35 0 -33.86
      rotation 0 1 0 1.5708
      name "bus stop(1)"
    }
    BusStop {
      translation 7.68 0 -33.86
      rotation 0 1 0 -1.5707953071795862
    }
    CrashBarrier {
      translation 54.2 0 -97.6
      rotation 0 1 0 3.1416
      path [
        0 0 0
        4 0 0
      ]
    }
    LaneSeparation {
      translation 110 0 -70
      name "road(14)"
      width 8
      length 15
      newLaneLeft FALSE
      lines [
        RoadLine {
          type "continuous"
          width 0.3
        }
        RoadLine {
          type "continuous"
          width 0.3
        }
      ]
      rightBarrier TRUE
      leftBarrier TRUE
      appearance Asphalt {
        colorOverride 0 0 0
      }
      pavementAppearance StonePavement {
        colorOverride 0 0 0
      }
    }
    LaneSeparation {
      translation 80 0 -140
      rotation 0 1 0 -1.5708
      name "road(16)"
      width 8
      length 8
      lines [
        RoadLine {
          type "continuous"
          width 0.3
        }
        RoadLine {
          type "continuous"
          width 0.3
        }
      ]
      rightBarrier TRUE
      leftBarrier TRUE
      appearance Asphalt {
        colorOverride 0 0 0
      }
      pavementAppearance StonePavement {
        colorOverride 0 0 0
      }
    }
    LaneSeparation {
      translation 30 0 -140
      rotation 0 1 0 1.5708
      name "road(18)"
      width 8
      length 8
      newLaneLeft FALSE
      lines [
        RoadLine {
          type "continuous"
          width 0.3
        }
        RoadLine {
          type "continuous"
          width 0.3
        }
      ]
      rightBarrier TRUE
      leftBarrier TRUE
      appearance Asphalt {
        colorOverride 0 0 0
      }
      pavementAppearance StonePavement {
        colorOverride 0 0 0
      }
    }
    LaneSeparation {
      translation 0 0 -70
      name "road(6)"
      width 8
      length 15
      lines [
        RoadLine {
          type "continuous"
          width 0.3
        }
        RoadLine {
          type "continuous"
          width 0.3
        }
      ]
      rightBarrier TRUE
      leftBarrier TRUE
      appearance Asphalt {
        colorOverride 0 0 0
      }
      pavementAppearance StonePavement {
        colorOverride 0 0 0
      }
    }
    LaneSeparation {
      translation 110 0 0
      rotation 0 1 0 -3.1416
      name "road(11)"
      width 8
      length 15
      lines [
        RoadLine {
          type "continuous"
          width 0.3
        }
        RoadLine {
          type "continuous"
          width 0.3
        }
      ]
      rightBarrier TRUE
      leftBarrier TRUE
      appearance Asphalt {
        colorOverride 0 0 0
      }
      pavementAppearance StonePavement {
        colorOverride 0 0 0
      }
    }
    LaneSeparation {
      rotation 0 1 0 -3.1416
      name "road(3)"
      width 8
      length 15
      newLaneLeft FALSE
      lines [
        RoadLine {
          type "continuous"
          width 0.3
        }
        RoadLine {
          type "continuous"
          width 0.3
        }
      ]
      rightBarrier TRUE
      leftBarrier TRUE
      bottom TRUE
      appearance Asphalt {
        colorOverride 0 0 0
      }
      pavementAppearance StonePavement {
        colorOverride 0 0 0
      }
    }
    CurvedRoadSegment {
      translation 30 0 -110
      rotation 0 1 0 3.1416
      name "road(8)"
      width 8
      numberOfForwardLanes 2
      lines [
        RoadLine {
          type "continuous"
          width 0.3
        }
      ]
      rightBarrier TRUE
      leftBarrier TRUE
      curvatureRadius 30
      appearance Asphalt {
        colorOverride 0 0 0
      }
      pavementAppearance StonePavement {
        colorOverride 0 0 0
      }
    }
    CurvedRoadSegment {
      translation 38 0 -122.2
      rotation 0 1 0 1.5708
      name "road(19)"
      width 4
      numberOfForwardLanes 2
      lines [
        RoadLine {
          type "continuous"
          width 0.3
        }
      ]
      rightBarrier TRUE
      leftBarrier TRUE
      curvatureRadius 14.2
      appearance Asphalt {
        colorOverride 0 0 0
      }
      pavementAppearance StonePavement {
        colorOverride 0 0 0
      }
    }
    CurvedRoadSegment {
      translation 80 0 -110
      rotation 0 1 0 1.5708
      name "road(17)"
      width 8
      numberOfForwardLanes 2
      lines [
        RoadLine {
          type "continuous"
          width 0.3
        }
      ]
      rightBarrier TRUE
      leftBarrier TRUE
      curvatureRadius 30
      appearance Asphalt {
        colorOverride 0 0 0
      }
      pavementAppearance StonePavement {
        colorOverride 0 0 0
      }
    }
    CurvedRoadSegment {
      translation 80 0 40
      name "road(9)"
      width 8
      numberOfForwardLanes 2
      lines [
        RoadLine {
          type "continuous"
          width 0.3
        }
      ]
      rightBarrier TRUE
      leftBarrier TRUE
      curvatureRadius 30
      appearance Asphalt {
        colorOverride 0 0 0
      }
      pavementAppearance StonePavement {
        colorOverride 0 0 0
      }
    }
    CurvedRoadSegment {
      translation 30 0 40
      rotation 0 1 0 -1.570796
      name "road(1)"
      width 8
      numberOfForwardLanes 2
      lines [
        RoadLine {
          type "continuous"
          width 0.3
        }
      ]
      rightBarrier TRUE
      leftBarrier TRUE
      curvatureRadius 30
      appearance Asphalt {
        colorOverride 0 0 0
      }
      pavementAppearance StonePavement {
        colorOverride 0 0 0
      }
    }
    StraightRoadSegment {
      translation 80 0 70
      rotation 0 1 0 -1.5708
      name "road(2)"
      width 8
      numberOfForwardLanes 2
      lines [
        RoadLine {
          type "continuous"
          width 0.3
        }
      ]
      rightBarrier TRUE
      leftBarrier TRUE
      length 50
      appearance Asphalt {
        colorOverride 0 0 0
      }
      pavementAppearance StonePavement {
        colorOverride 0 0 0
      }
    }
    StraightRoadSegment {
      translation 38 0 -142
      rotation 0 1 0 1.5708
      name "road(23)"
      width 4
      numberOfForwardLanes 2
      lines [
        RoadLine {
          type "continuous"
          width 0.3
        }
      ]
      rightBarrier TRUE
      leftBarrier TRUE
      length 34
      appearance Asphalt {
        colorOverride 0 0 0
      }
      pavementAppearance StonePavement {
        colorOverride 0 0 0
      }
    }
    StraightRoadSegment {
      translation 112 0 -55
      name "road(13)"
      width 4
      numberOfForwardLanes 2
      lines [
        RoadLine {
          type "continuous"
          width 0.3
        }
      ]
      rightBarrier TRUE
      leftBarrier TRUE
      length 40
      appearance Asphalt {
        colorOverride 0 0 0
      }
      pavementAppearance StonePavement {
        colorOverride 0 0 0
      }
    }
    StraightRoadSegment {
      translation 106.4 0 -55
      name "road(12)"
      width 4
      numberOfForwardLanes 2
      lines [
        RoadLine {
          type "continuous"
          width 0.3
        }
      ]
      rightBarrier TRUE
      leftBarrier TRUE
      length 40
      appearance Asphalt {
        colorOverride 0 0 0
      }
      pavementAppearance StonePavement {
        colorOverride 0 0 0
      }
    }
    StraightRoadSegment {
      translation 3.6 0 -55
      name "road(5)"
      width 4
      numberOfForwardLanes 2
      lines [
        RoadLine {
          type "continuous"
          width 0.3
        }
      ]
      rightBarrier TRUE
      leftBarrier TRUE
      length 40
      appearance Asphalt {
        colorOverride 0 0 0
      }
      pavementAppearance StonePavement {
        colorOverride 0 0 0
      }
    }
    StraightRoadSegment {
      translation -2 0 -55
      name "road(4)"
      width 4
      numberOfForwardLanes 2
      lines [
        RoadLine {
          type "continuous"
          width 0.3
        }
      ]
      rightBarrier TRUE
      leftBarrier TRUE
      length 40
      appearance Asphalt {
        colorOverride 0 0 0
      }
      pavementAppearance StonePavement {
        colorOverride 0 0 0
      }
    }
    StraightRoadSegment {
      translation 110 0 -110
      name "road(15)"
      width 8
      numberOfForwardLanes 2
      lines [
        RoadLine {
          type "continuous"
          width 0.3
        }
      ]
      rightBarrier TRUE
      leftBarrier TRUE
      length 40
      appearance Asphalt {
        colorOverride 0 0 0
      }
      pavementAppearance StonePavement {
        colorOverride 0 0 0
      }
    }
    StraightRoadSegment {
      translation 52.2 0 -122.2
      name "road(22)"
      width 4
      numberOfForwardLanes 2
      lines [
        RoadLine {
          type "continuous"
          width 0.3
        }
      ]
      rightBarrier TRUE
      leftBarrier TRUE
      length 25
      appearance Asphalt {
        colorOverride 0 0 0
      }
      pavementAppearance StonePavement {
        colorOverride 0 0 0
      }
    }
    StraightRoadSegment {
      translation 0 0 -110
      name "road(7)"
      width 8
      numberOfForwardLanes 2
      lines [
        RoadLine {
          type "continuous"
          width 0.3
        }
      ]
      rightBarrier TRUE
      leftBarrier TRUE
      length 40
      appearance Asphalt {
        colorOverride 0 0 0
      }
      pavementAppearance StonePavement {
        colorOverride 0 0 0
      }
    }
    StraightRoadSegment {
      translation 110 0 0
      name "road(10)"
      width 8
      numberOfForwardLanes 2
      lines [
        RoadLine {
          type "continuous"
          width 0.3
        }
      ]
      rightBarrier TRUE
      leftBarrier TRUE
      length 40
      appearance Asphalt {
        colorOverride 0 0 0
      }
      pavementAppearance StonePavement {
        colorOverride 0 0 0
      }
    }
    StraightRoadSegment {
      width 8
      numberOfForwardLanes 2
      lines [
        RoadLine {
          type "continuous"
          width 0.3
        }
      ]
      rightBarrier TRUE
      leftBarrier TRUE
      bottom TRUE
      length 40
      appearance Asphalt {
        colorOverride 0 0 0
      }
      pavementAppearance StonePavement {
        colorOverride 0 0 0
      }
    }
  ]
  name "environment"
}
Floor {
  translation 55 -0.01 -35
  size 120 220
  tileSize 0.1 0.1
  appearance PBRAppearance {
    baseColor 0.5 0.5 0.5
    transparency 1
    metalness 0
  }
}
