#VRML_SIM R2020a utf8
WorldInfo {
  basicTimeStep 16
}
Viewpoint {
  orientation -0.13604872643324314 0.9613566108335687 0.2393412017235796 1.799494164456511
  position -5.156028645438592 7.717062723152812 -29.836713621291167
}
TexturedBackground {
  luminosity 2
  reflections FALSE
}
DEF Cab1 Robot {
  translation -20.31969999357564 0.3986696792065586 -29.441900006248225
  rotation -0.00011349079067931864 0.9999999864427885 -0.00011930743241959921 -1.5723841962935208
  children [
    DEF cam_f Camera {
      translation 0 0.1 1
      rotation 0.0002061049634456112 -0.9659258286852112 -0.25881895409635697 -3.140055307179586
      children [
        Shape {
          appearance PBRAppearance {
            baseColor 0.4 0 0
          }
          geometry Cylinder {
            height 0.1
            radius 0.05
          }
        }
      ]
      boundingObject Cylinder {
        height 0.1
        radius 0.05
      }
      physics Physics {
        density 1
      }
      fieldOfView 0.75
      width 100
      height 100
      far 10
    }
    DEF ls_f LightSensor {
      translation 0 0 1
      rotation 0 1 0 -1.57
      children [
        Shape {
          appearance PBRAppearance {
            baseColor 0 0 0
            metalness 0
          }
          geometry Box {
            size 0.1 0.1 0.1
          }
        }
      ]
      name "ls_front"
      boundingObject Shape {
        appearance PBRAppearance {
        }
        geometry Cylinder {
          height 0.1
          radius 0.05
        }
      }
      physics Physics {
        density 1
      }
      lookupTable [
        0 0 0
        5 1000 0
      ]
    }
    DEF ds_fl DistanceSensor {
      translation 0.45 0.2 1
      rotation 0 1 0 -1.047
      children [
        Shape {
          appearance PBRAppearance {
          }
          geometry Box {
            size 0.1 0.1 0.1
          }
        }
      ]
      name "ds_fl"
      boundingObject Shape {
        appearance PBRAppearance {
        }
        geometry Box {
          size 0.1 0.1 0.1
        }
      }
      physics Physics {
        density 1
      }
      lookupTable [
        0 0 0
        5 1000 0
      ]
    }
    DEF ds_lf DistanceSensor {
      translation 0.5 0.2 0.95
      children [
        Shape {
          appearance PBRAppearance {
          }
          geometry Box {
            size 0.1 0.1 0.1
          }
        }
      ]
      name "ds_lf"
      boundingObject Shape {
        appearance PBRAppearance {
        }
        geometry Box {
          size 0.1 0.1 0.1
        }
      }
      physics Physics {
        density 1
      }
      lookupTable [
        0 0 0
        5 1000 0
      ]
    }
    DEF ds_lc DistanceSensor {
      translation 0.5 0.2 0
      children [
        Shape {
          appearance PBRAppearance {
          }
          geometry Box {
            size 0.1 0.1 0.1
          }
        }
      ]
      name "ds_lc"
      boundingObject Shape {
        appearance PBRAppearance {
        }
        geometry Box {
          size 0.1 0.1 0.1
        }
      }
      physics Physics {
        density 1
      }
      lookupTable [
        0 0 0
        5 1000 0
      ]
    }
    DEF ds_fr DistanceSensor {
      translation -0.45 0.2 1
      rotation 0 1 0 -2.09
      children [
        Shape {
          appearance PBRAppearance {
          }
          geometry Box {
            size 0.1 0.1 0.1
          }
        }
      ]
      name "ds_fr"
      boundingObject Shape {
        appearance PBRAppearance {
        }
        geometry Box {
          size 0.1 0.1 0.1
        }
      }
      physics Physics {
        density 1
      }
      lookupTable [
        0 0 0
        5 1000 0
      ]
    }
    DEF ds_rf DistanceSensor {
      translation -0.5 0.2 0.95
      rotation 0 1 0 -3.14
      children [
        Shape {
          appearance PBRAppearance {
          }
          geometry Box {
            size 0.1 0.1 0.1
          }
        }
      ]
      name "ds_rf"
      boundingObject Shape {
        appearance PBRAppearance {
        }
        geometry Box {
          size 0.1 0.1 0.1
        }
      }
      physics Physics {
        density 1
      }
      lookupTable [
        0 0 0
        5 1000 0
      ]
    }
    DEF ds_rc DistanceSensor {
      translation -0.5 0.2 0
      rotation 0 1 0 -3.14
      children [
        Shape {
          appearance PBRAppearance {
          }
          geometry Box {
            size 0.1 0.1 0.1
          }
        }
      ]
      name "ds_rc"
      boundingObject Shape {
        appearance PBRAppearance {
        }
        geometry Box {
          size 0.1 0.1 0.1
        }
      }
      physics Physics {
        density 1
      }
      lookupTable [
        0 0 0
        5 1000 0
      ]
    }
    DEF ds_fc DistanceSensor {
      translation 0 0.2 1
      rotation 0 1 0 -1.57
      children [
        Shape {
          appearance PBRAppearance {
          }
          geometry Box {
            size 0.1 0.1 0.1
          }
        }
      ]
      name "ds_fc"
      boundingObject Shape {
        appearance PBRAppearance {
        }
        geometry Box {
          size 0.1 0.1 0.1
        }
      }
      physics Physics {
        density 1
      }
      lookupTable [
        0 0 0
        5 1000 0
      ]
    }
    DEF ds_fcr DistanceSensor {
      translation -0.225 0.2 1
      rotation 0 1 0 -1.833
      children [
        Shape {
          appearance PBRAppearance {
          }
          geometry Box {
            size 0.1 0.1 0.1
          }
        }
      ]
      name "ds_fcr"
      boundingObject Shape {
        appearance PBRAppearance {
        }
        geometry Box {
          size 0.1 0.1 0.1
        }
      }
      physics Physics {
        density 1
      }
      lookupTable [
        0 0 0
        5 1000 0
      ]
    }
    DEF ds_fcl DistanceSensor {
      translation 0.225 0.2 1
      rotation 0 1 0 -1.309
      children [
        Shape {
          appearance PBRAppearance {
          }
          geometry Box {
            size 0.1 0.1 0.1
          }
        }
      ]
      name "ds_fcl"
      boundingObject Shape {
        appearance PBRAppearance {
        }
        geometry Box {
          size 0.1 0.1 0.1
        }
      }
      physics Physics {
        density 1
      }
      lookupTable [
        0 0 0
        5 1000 0
      ]
    }
    Transform {
      translation 0 0.5 -0.3
      rotation 1 0 0 0
      children [
        Shape {
          appearance PBRAppearance {
            baseColor 0.5 0.5 0.5
            transparency 0.3
          }
          geometry Box {
            size 0.9 0.5 1.2
          }
        }
      ]
    }
    Transform {
      translation 0 0.8 -0.3
      rotation 1 0 0 0
      children [
        Shape {
          appearance PBRAppearance {
            baseColor 0 0 0
          }
          geometry Box {
            size 1 0.1 1.3
          }
        }
      ]
    }
    DEF wheelFL HingeJoint {
      jointParameters HingeJointParameters {
        position 3.255420353235132e-08
        anchor 0.55 -0.1 0.55
      }
      device [
        DEF wheelFL RotationalMotor {
          name "wheelFL"
          maxTorque 30
        }
      ]
      endPoint DEF wheelFL Solid {
        translation 0.55 -0.1 0.55
        rotation 1.6380393876798686e-08 -1.6367354921189455e-08 0.9999999999999998 1.5699999999999963
        children [
          DEF wheel Shape {
            appearance PBRAppearance {
              baseColor 0 0 0
              metalness 0
            }
            geometry Cylinder {
              height 0.1
              radius 0.3
            }
          }
        ]
        name "wheelFL"
        boundingObject USE wheel
        physics DEF physics_wheel Physics {
          density 10
        }
        linearVelocity -9.08872626710977e-08 5.185811873801778e-09 -6.172838487666651e-09
        angularVelocity -4.089862855533659e-09 -4.0130697180605864e-08 3.2651298095484895e-07
      }
    }
    DEF wheelRL HingeJoint {
      jointParameters HingeJointParameters {
        position 3.1555929756539695e-08
        anchor 0.55 -0.1 -0.7
      }
      device [
        DEF wheelRL RotationalMotor {
          name "wheelRL"
          maxTorque 30
        }
      ]
      endPoint DEF wheelRL Solid {
        translation 0.55 -0.1 -0.7
        rotation 1.5790534299819272e-08 -1.5777964878269887e-08 0.9999999999999999 1.5699999999999958
        children [
          DEF wheel Shape {
            appearance PBRAppearance {
              baseColor 0 0 0
              metalness 0
            }
            geometry Cylinder {
              height 0.1
              radius 0.3
            }
          }
        ]
        name "wheelRL"
        boundingObject USE wheel
        physics DEF physics_wheel Physics {
          density 10
        }
        linearVelocity -9.167303440069915e-08 -6.392667200422517e-09 1.1441981288429505e-08
        angularVelocity 5.7405304854201e-09 -4.013030681178788e-08 3.3976793464240255e-07
      }
    }
    DEF wheelRR HingeJoint {
      jointParameters HingeJointParameters {
        position 3.384330152892231e-08
        anchor -0.55 -0.1 -0.7
      }
      device [
        DEF wheelRR RotationalMotor {
          name "wheelRR"
          maxTorque 30
        }
      ]
      endPoint DEF wheelRR Solid {
        translation -0.55 -0.1 -0.7
        rotation 1.6935131296545627e-08 -1.6921650764461157e-08 0.9999999999999998 1.569999999999997
        children [
          DEF wheel Shape {
            appearance PBRAppearance {
              baseColor 0 0 0
              metalness 0
            }
            geometry Cylinder {
              height 0.1
              radius 0.3
            }
          }
        ]
        name "wheelRR"
        boundingObject USE wheel
        physics DEF physics_wheel Physics {
          density 10
        }
        linearVelocity -7.269832560375284e-08 -4.240858491092943e-09 7.130212406388721e-09
        angularVelocity 7.089475301795839e-09 -4.0124179963881735e-08 3.162852932050377e-07
      }
    }
    DEF wheelFR HingeJoint {
      jointParameters HingeJointParameters {
        position -3.191104048204144e-08
        anchor -0.55 -0.1 0.55
      }
      device [
        DEF wheelFR RotationalMotor {
          name "wheelFR"
          maxTorque 30
        }
      ]
      endPoint DEF wheelFR Solid {
        translation -0.55 -0.1 0.55
        rotation -2.1938788545569875e-08 2.192132505280415e-08 0.9999999999999996 1.5699999999999963
        children [
          DEF wheel Shape {
            appearance PBRAppearance {
              baseColor 0 0 0
              metalness 0
            }
            geometry Cylinder {
              height 0.1
              radius 0.3
            }
          }
        ]
        name "wheelFR"
        boundingObject USE wheel
        physics DEF physics_wheel Physics {
          density 10
        }
        linearVelocity 5.589296585789625e-08 7.337622090052178e-09 -1.0281880401406598e-08
        angularVelocity -1.7566202215096822e-09 -4.015557373647951e-08 -3.168214485309896e-07
      }
    }
    DEF car_body Shape {
      appearance PBRAppearance {
        baseColor 1 1 0
      }
      geometry Box {
        size 1 0.6 2
      }
    }
  ]
  name "Cab1"
  boundingObject USE car_body
  physics Physics {
    density 10
  }
  recognitionColors [
    0 0 0
  ]
  controller "controller"
  linearVelocity -4.86958650758447e-08 9.492132686387566e-10 -2.319754074815131e-09
  angularVelocity 2.0102423796492425e-09 -4.037751136555338e-08 -9.401480299496947e-09
}
DEF Cab2 Robot {
  translation 9.999906847999789 0.3986696792225526 -29.100002401250403
  rotation -0.0001134907480381508 0.9999999864427954 -0.00011930741416175973 -1.5723853225705533
  children [
    DEF cam_f Camera {
      translation 0 0.1 1
      rotation 0 1 0 3.14
      children [
        Shape {
          appearance PBRAppearance {
            baseColor 0.4 0 0
          }
          geometry Cylinder {
            height 0.1
            radius 0.05
          }
        }
      ]
      boundingObject Cylinder {
        height 0.1
        radius 0.05
      }
      physics Physics {
        density 1
      }
      fieldOfView 0.75
      width 100
      height 100
      far 10
    }
    DEF ls_f LightSensor {
      translation 0 0 1
      rotation 0 1 0 -1.57
      children [
        Shape {
          appearance PBRAppearance {
            baseColor 0 0 0
            metalness 0
          }
          geometry Box {
            size 0.1 0.1 0.1
          }
        }
      ]
      name "ls_front"
      boundingObject Shape {
        appearance PBRAppearance {
        }
        geometry Cylinder {
          height 0.1
          radius 0.05
        }
      }
      physics Physics {
        density 1
      }
      lookupTable [
        0 0 0
        5 1000 0
      ]
    }
    DEF ds_fl DistanceSensor {
      translation 0.45 0.2 1
      rotation 0 1 0 -1.047
      children [
        Shape {
          appearance PBRAppearance {
          }
          geometry Box {
            size 0.1 0.1 0.1
          }
        }
      ]
      name "ds_fl"
      boundingObject Shape {
        appearance PBRAppearance {
        }
        geometry Box {
          size 0.1 0.1 0.1
        }
      }
      physics Physics {
        density 1
      }
      lookupTable [
        0 0 0
        5 1000 0
      ]
    }
    DEF ds_lf DistanceSensor {
      translation 0.5 0.2 0.95
      children [
        Shape {
          appearance PBRAppearance {
          }
          geometry Box {
            size 0.1 0.1 0.1
          }
        }
      ]
      name "ds_lf"
      boundingObject Shape {
        appearance PBRAppearance {
        }
        geometry Box {
          size 0.1 0.1 0.1
        }
      }
      physics Physics {
        density 1
      }
      lookupTable [
        0 0 0
        5 1000 0
      ]
    }
    DEF ds_lc DistanceSensor {
      translation 0.5 0.2 0
      children [
        Shape {
          appearance PBRAppearance {
          }
          geometry Box {
            size 0.1 0.1 0.1
          }
        }
      ]
      name "ds_lc"
      boundingObject Shape {
        appearance PBRAppearance {
        }
        geometry Box {
          size 0.1 0.1 0.1
        }
      }
      physics Physics {
        density 1
      }
      lookupTable [
        0 0 0
        5 1000 0
      ]
    }
    DEF ds_fr DistanceSensor {
      translation -0.45 0.2 1
      rotation 0 1 0 -2.09
      children [
        Shape {
          appearance PBRAppearance {
          }
          geometry Box {
            size 0.1 0.1 0.1
          }
        }
      ]
      name "ds_fr"
      boundingObject Shape {
        appearance PBRAppearance {
        }
        geometry Box {
          size 0.1 0.1 0.1
        }
      }
      physics Physics {
        density 1
      }
      lookupTable [
        0 0 0
        5 1000 0
      ]
    }
    DEF ds_rf DistanceSensor {
      translation -0.5 0.2 0.95
      rotation 0 1 0 -3.14
      children [
        Shape {
          appearance PBRAppearance {
          }
          geometry Box {
            size 0.1 0.1 0.1
          }
        }
      ]
      name "ds_rf"
      boundingObject Shape {
        appearance PBRAppearance {
        }
        geometry Box {
          size 0.1 0.1 0.1
        }
      }
      physics Physics {
        density 1
      }
      lookupTable [
        0 0 0
        5 1000 0
      ]
    }
    DEF ds_rc DistanceSensor {
      translation -0.5 0.2 0
      rotation 0 1 0 -3.14
      children [
        Shape {
          appearance PBRAppearance {
          }
          geometry Box {
            size 0.1 0.1 0.1
          }
        }
      ]
      name "ds_rc"
      boundingObject Shape {
        appearance PBRAppearance {
        }
        geometry Box {
          size 0.1 0.1 0.1
        }
      }
      physics Physics {
        density 1
      }
      lookupTable [
        0 0 0
        5 1000 0
      ]
    }
    DEF ds_fc DistanceSensor {
      translation 0 0.2 1
      rotation 0 1 0 -1.57
      children [
        Shape {
          appearance PBRAppearance {
          }
          geometry Box {
            size 0.1 0.1 0.1
          }
        }
      ]
      name "ds_fc"
      boundingObject Shape {
        appearance PBRAppearance {
        }
        geometry Box {
          size 0.1 0.1 0.1
        }
      }
      physics Physics {
        density 1
      }
      lookupTable [
        0 0 0
        5 1000 0
      ]
    }
    DEF ds_fcr DistanceSensor {
      translation -0.225 0.2 1
      rotation 0 1 0 -1.833
      children [
        Shape {
          appearance PBRAppearance {
          }
          geometry Box {
            size 0.1 0.1 0.1
          }
        }
      ]
      name "ds_fcr"
      boundingObject Shape {
        appearance PBRAppearance {
        }
        geometry Box {
          size 0.1 0.1 0.1
        }
      }
      physics Physics {
        density 1
      }
      lookupTable [
        0 0 0
        5 1000 0
      ]
    }
    DEF ds_fcl DistanceSensor {
      translation 0.225 0.2 1
      rotation 0 1 0 -1.309
      children [
        Shape {
          appearance PBRAppearance {
          }
          geometry Box {
            size 0.1 0.1 0.1
          }
        }
      ]
      name "ds_fcl"
      boundingObject Shape {
        appearance PBRAppearance {
        }
        geometry Box {
          size 0.1 0.1 0.1
        }
      }
      physics Physics {
        density 1
      }
      lookupTable [
        0 0 0
        5 1000 0
      ]
    }
    Transform {
      translation 0 0.5 -0.3
      rotation 1 0 0 0
      children [
        Shape {
          appearance PBRAppearance {
            baseColor 0.5 0.5 0.5
            transparency 0.3
          }
          geometry Box {
            size 0.9 0.5 1.2
          }
        }
      ]
    }
    Transform {
      translation 0 0.8 -0.3
      rotation 1 0 0 0
      children [
        Shape {
          appearance PBRAppearance {
            baseColor 0 0 0
          }
          geometry Box {
            size 1 0.1 1.3
          }
        }
      ]
    }
    DEF wheelFL HingeJoint {
      jointParameters HingeJointParameters {
        position 6.57208458131402e-08
        anchor 0.55 -0.1 0.55
      }
      device [
        DEF wheelFL RotationalMotor {
          name "wheelFL"
          maxTorque 30
        }
      ]
      endPoint DEF wheelFL Solid {
        translation 0.55 -0.1 0.55
        rotation 3.288660096635093e-08 -3.286042290657008e-08 0.999999999999999 1.5699999999999972
        children [
          DEF wheel Shape {
            appearance PBRAppearance {
              baseColor 0 0 0
              metalness 0
            }
            geometry Cylinder {
              height 0.1
              radius 0.3
            }
          }
        ]
        name "wheelFL"
        boundingObject USE wheel
        physics DEF physics_wheel Physics {
          density 10
        }
        linearVelocity -7.945865987573187e-08 -4.0847230804388183e-10 -1.7177205867461696e-08
        angularVelocity -9.368357116989985e-09 -7.836506693445432e-08 3.1892910132715274e-07
      }
    }
    DEF wheelRL HingeJoint {
      jointParameters HingeJointParameters {
        position 6.838643698777039e-08
        anchor 0.55 -0.1 -0.7
      }
      device [
        DEF wheelRL RotationalMotor {
          name "wheelRL"
          maxTorque 30
        }
      ]
      endPoint DEF wheelRL Solid {
        translation 0.55 -0.1 -0.7
        rotation 3.422045831731586e-08 -3.4193218493885176e-08 0.999999999999999 1.5699999999999974
        children [
          DEF wheel Shape {
            appearance PBRAppearance {
              baseColor 0 0 0
              metalness 0
            }
            geometry Cylinder {
              height 0.1
              radius 0.3
            }
          }
        ]
        name "wheelRL"
        boundingObject USE wheel
        physics DEF physics_wheel Physics {
          density 10
        }
        linearVelocity -8.214681176057753e-08 -3.6900706830001907e-10 1.737874727654083e-08
        angularVelocity 9.791452822846811e-09 -7.836442315150608e-08 3.3200085724565284e-07
      }
    }
    DEF wheelRR HingeJoint {
      jointParameters HingeJointParameters {
        position -4.4173138680273235e-12
        anchor -0.55 -0.1 -0.7
      }
      device [
        DEF wheelRR RotationalMotor {
          name "wheelRR"
          maxTorque 30
        }
      ]
      endPoint DEF wheelRR Solid {
        translation -0.55 -0.1 -0.7
        rotation -2.2104164473777593e-12 2.2086569340160024e-12 1 1.5699999999999963
        children [
          DEF wheel Shape {
            appearance PBRAppearance {
              baseColor 0 0 0
              metalness 0
            }
            geometry Cylinder {
              height 0.1
              radius 0.3
            }
          }
        ]
        name "wheelRR"
        boundingObject USE wheel
        physics DEF physics_wheel Physics {
          density 10
        }
        linearVelocity 8.194461718207664e-08 4.0901723365544055e-10 1.7639465489313456e-08
        angularVelocity 1.084578591206789e-08 -7.838364999380448e-08 -3.3153389620077773e-07
      }
    }
    DEF wheelFR HingeJoint {
      jointParameters HingeJointParameters {
        position -1.8442457744012106e-11
        anchor -0.55 -0.1 0.55
      }
      device [
        DEF wheelFR RotationalMotor {
          name "wheelFR"
          maxTorque 30
        }
      ]
      endPoint DEF wheelFR Solid {
        translation -0.55 -0.1 0.55
        rotation -9.228574908952312e-12 9.221228872006053e-12 1 1.5699999999999956
        children [
          DEF wheel Shape {
            appearance PBRAppearance {
              baseColor 0 0 0
              metalness 0
            }
            geometry Cylinder {
              height 0.1
              radius 0.3
            }
          }
        ]
        name "wheelFR"
        boundingObject USE wheel
        physics DEF physics_wheel Physics {
          density 10
        }
        linearVelocity 7.935893804580901e-08 3.6955038557182726e-10 -1.692485383897782e-08
        angularVelocity -8.355269970358596e-09 -7.838300509551924e-08 -3.1863582847063084e-07
      }
    }
    DEF car_body Shape {
      appearance PBRAppearance {
        baseColor 1 1 0
      }
      geometry Box {
        size 1 0.6 2
      }
    }
  ]
  name "Cab2"
  boundingObject USE car_body
  physics Physics {
    density 10
  }
  recognitionColors [
    0 0 0
  ]
  controller "controller"
  linearVelocity -6.903911628671852e-11 -2.164490732593009e-12 -5.643333598146624e-09
  angularVelocity 7.21665277883019e-10 -7.881003553530751e-08 3.3437156608850945e-11
}
DEF environment Solid {
  scale 1.09819 1.09819 1.09819
  children [
    DEF PickUp1 BusStop {
      translation 0 0 -45
      rotation 0 1 0 3.14159
      name "PickUp1"
      bench FALSE
      appearance PBRAppearance {
        baseColor 0 0 0
        roughness 0.5
        metalness 0
      }
      internalAdvertisingTexture []
      externalAdvertisingTexture []
    }
    DEF PickUp2 BusStop {
      translation 45 0 0
      rotation 0 -1 0 -1.5707953071795862
      name "PickUp2"
      bench FALSE
      appearance PBRAppearance {
        baseColor 1 0 0
        roughness 0.5
        metalness 0
      }
      internalAdvertisingTexture []
      externalAdvertisingTexture []
      advertisingLightOn FALSE
    }
    DEF PickUp3 BusStop {
      translation 0 0 45
      rotation 0 1 0 -5.307179586466759e-06
      name "PickUp3"
      bench FALSE
      appearance PBRAppearance {
        baseColor 0 1 0
        roughness 0.5
        metalness 0
      }
      internalAdvertisingTexture []
      externalAdvertisingTexture []
      advertisingLightOn FALSE
    }
    DEF PickUp4 BusStop {
      translation -45 0 0
      rotation 0 1 0 -1.5707953071795862
      name "PickUp4"
      bench FALSE
      appearance PBRAppearance {
        baseColor 0 0 1
        roughness 0.5
        metalness 0
      }
      internalAdvertisingTexture []
      externalAdvertisingTexture []
      advertisingLightOn FALSE
    }
    DEF PickUp5 BusStop {
      translation 0 0 -71
      rotation 0 1 0 3.14159
      name "PickUp5"
      bench FALSE
      appearance PBRAppearance {
        baseColor 1 1 0
        roughness 0.5
        metalness 0
      }
      internalAdvertisingTexture []
      externalAdvertisingTexture []
      advertisingLightOn FALSE
    }
    DEF PickUp6 BusStop {
      translation 71 0 0
      rotation 0 -1 0 -1.5707953071795862
      name "PickUp6"
      bench FALSE
      appearance PBRAppearance {
        baseColor 1 0 1
        roughness 0.5
        metalness 0
      }
      internalAdvertisingTexture []
      externalAdvertisingTexture []
      advertisingLightOn FALSE
    }
    DEF PickUp7 BusStop {
      translation 0 0 71
      rotation 0 1 0 -5.307179586466759e-06
      name "PickUp7"
      bench FALSE
      appearance PBRAppearance {
        baseColor 0 1 1
        roughness 0.5
        metalness 0
      }
      internalAdvertisingTexture []
      externalAdvertisingTexture []
      advertisingLightOn FALSE
    }
    DEF PickUp8 BusStop {
      translation -71 0 0
      rotation 0 1 0 -1.5707953071795862
      name "PickUp8"
      bench FALSE
      appearance PBRAppearance {
        roughness 0.5
        metalness 0
      }
      internalAdvertisingTexture []
      externalAdvertisingTexture []
      advertisingLightOn FALSE
    }
    CurvedRoadSegment {
      translation -56 0 33
      rotation 0 1 0 -1.570796
      name "road(1)"
      width 6
      numberOfForwardLanes 2
      lines [
        RoadLine {
          type "continuous"
          width 0.3
        }
      ]
      rightBarrier TRUE
      leftBarrier TRUE
      bottom TRUE
      curvatureRadius 20
      appearance Asphalt {
        colorOverride 0 0 0
        IBLStrength 0
      }
      pavementAppearance StonePavement {
        colorOverride 0 0 0
      }
    }
    CurvedRoadSegment {
      translation -56 0 -33
      rotation 0 1 0 3.14
      name "road(7)"
      width 6
      numberOfForwardLanes 2
      lines [
        RoadLine {
          type "continuous"
          width 0.3
        }
      ]
      rightBarrier TRUE
      leftBarrier TRUE
      bottom TRUE
      curvatureRadius 20
      appearance Asphalt {
        colorOverride 0 0 0
        IBLStrength 0
      }
      pavementAppearance StonePavement {
        colorOverride 0 0 0
      }
    }
    CurvedRoadSegment {
      translation -33 0 -56
      rotation 0 1 0 3.14
      name "road(8)"
      width 6
      numberOfForwardLanes 2
      lines [
        RoadLine {
          type "continuous"
          width 0.3
        }
      ]
      rightBarrier TRUE
      leftBarrier TRUE
      bottom TRUE
      curvatureRadius 20
      appearance Asphalt {
        colorOverride 0 0 0
        IBLStrength 0
      }
      pavementAppearance StonePavement {
        colorOverride 0 0 0
      }
    }
    CurvedRoadSegment {
      translation 33 0 -56
      rotation 0 1 0 1.57
      name "road(9)"
      width 6
      numberOfForwardLanes 2
      lines [
        RoadLine {
          type "continuous"
          width 0.3
        }
      ]
      rightBarrier TRUE
      leftBarrier TRUE
      bottom TRUE
      curvatureRadius 20
      appearance Asphalt {
        colorOverride 0 0 0
        IBLStrength 0
      }
      pavementAppearance StonePavement {
        colorOverride 0 0 0
      }
    }
    CurvedRoadSegment {
      translation 56 0 -33
      rotation 0 1 0 1.57
      name "road(10)"
      width 6
      numberOfForwardLanes 2
      lines [
        RoadLine {
          type "continuous"
          width 0.3
        }
      ]
      rightBarrier TRUE
      leftBarrier TRUE
      bottom TRUE
      curvatureRadius 20
      appearance Asphalt {
        colorOverride 0 0 0
        IBLStrength 0
      }
      pavementAppearance StonePavement {
        colorOverride 0 0 0
      }
    }
    CurvedRoadSegment {
      translation 56 0 33
      name "road(11)"
      width 6
      numberOfForwardLanes 2
      lines [
        RoadLine {
          type "continuous"
          width 0.3
        }
      ]
      rightBarrier TRUE
      leftBarrier TRUE
      bottom TRUE
      curvatureRadius 20
      appearance Asphalt {
        colorOverride 0 0 0
        IBLStrength 0
      }
      pavementAppearance StonePavement {
        colorOverride 0 0 0
      }
    }
    CurvedRoadSegment {
      translation 33 0 56
      name "road(12)"
      width 6
      numberOfForwardLanes 2
      lines [
        RoadLine {
          type "continuous"
          width 0.3
        }
      ]
      rightBarrier TRUE
      leftBarrier TRUE
      bottom TRUE
      curvatureRadius 20
      appearance Asphalt {
        colorOverride 0 0 0
        IBLStrength 0
      }
      pavementAppearance StonePavement {
        colorOverride 0 0 0
      }
    }
    CurvedRoadSegment {
      translation -33 0 56
      rotation 0 1 0 -1.57
      name "road(13)"
      width 6
      numberOfForwardLanes 2
      lines [
        RoadLine {
          type "continuous"
          width 0.3
        }
      ]
      rightBarrier TRUE
      leftBarrier TRUE
      bottom TRUE
      curvatureRadius 20
      appearance Asphalt {
        colorOverride 0 0 0
        IBLStrength 0
      }
      pavementAppearance StonePavement {
        colorOverride 0 0 0
      }
    }
    RoadIntersection {
      translation -53 0 53
      rotation 0 1 0 0.785
      roadsWidth 6
      startRoadsLength [
        -0.1
      ]
      startRoadsStartLine [
        ""
        ""
      ]
      startRoadsLine [
        RoadLine {
          type "continuous"
          width 0.3
        }
      ]
      startRoadBorderWidth 0.5
      bottom TRUE
      appearance Asphalt {
        colorOverride 0.5 0.5 0
      }
    }
    RoadIntersection {
      translation 53 0 53
      rotation 0 1 0 0.785
      name "road intersection(1)"
      roadsWidth 6
      startRoadsLength [
        -0.1
      ]
      startRoadsStartLine [
        ""
        ""
      ]
      startRoadsLine [
        RoadLine {
          type "continuous"
          width 0.3
        }
      ]
      startRoadBorderWidth 0.5
      bottom TRUE
      appearance Asphalt {
        colorOverride 0.5 0.5 0
      }
    }
    RoadIntersection {
      translation 53 0 -53
      rotation 0 1 0 0.785
      name "road intersection(2)"
      roadsWidth 6
      startRoadsLength [
        -0.1
      ]
      startRoadsStartLine [
        ""
        ""
      ]
      startRoadsLine [
        RoadLine {
          type "continuous"
          width 0.3
        }
      ]
      startRoadBorderWidth 0.5
      bottom TRUE
      appearance Asphalt {
        colorOverride 0.5 0.5 0
      }
    }
    RoadIntersection {
      translation -53 0 -53
      rotation 0 1 0 0.785
      name "road intersection(3)"
      roadsWidth 6
      startRoadsLength [
        -0.1
      ]
      startRoadsStartLine [
        ""
        ""
      ]
      startRoadsLine [
        RoadLine {
          type "continuous"
          width 0.3
        }
      ]
      startRoadBorderWidth 0.5
      bottom TRUE
      appearance Asphalt {
        colorOverride 0.5 0.5 0
      }
    }
    StraightRoadSegment {
      translation -53 0 20
      name "road(20)"
      width 6
      numberOfForwardLanes 2
      lines [
        RoadLine {
          type "continuous"
          width 0.3
        }
      ]
      rightBarrier TRUE
      leftBarrier TRUE
      bottom TRUE
      length 30
      appearance Asphalt {
        colorOverride 0 0 0
        IBLStrength 0
      }
      pavementAppearance StonePavement {
        colorOverride 0 0 0
      }
    }
    AddLanesRoadSegment {
      translation -53 0 20
      rotation 0 1 0 3.14
      width 6
      length 10
      numberOfNewLanes 1
      newLaneLeft FALSE
      lines [
        RoadLine {
          type "continuous"
          width 0.3
        }
      ]
      rightBarrier TRUE
      leftBarrier TRUE
      bottom TRUE
      appearance Asphalt {
        colorOverride 0 0 0
        IBLStrength 0
      }
      pavementAppearance StonePavement {
        colorOverride 0 0 0
      }
    }
    Solid {
      translation -51.48 0 15.5
      rotation 0 1 0 -0.2617996938995747
      children [
        Shape {
          appearance PBRAppearance {
            roughness 1
            metalness 0
          }
          geometry Box {
            size 0.2 0.01 11.6
          }
        }
      ]
      name "solid(1)"
    }
    StraightRoadSegment {
      translation -51.5 0 -10
      name "road(17)"
      width 9
      numberOfLanes 3
      numberOfForwardLanes 2
      lines [
        RoadLine {
          type "continuous"
          width 0.3
        }
        RoadLine {
          type "continuous"
          width 0.3
        }
      ]
      rightBarrier TRUE
      leftBarrier TRUE
      bottom TRUE
      length 20
      appearance Asphalt {
        colorOverride 0 0 0
        IBLStrength 0
      }
      pavementAppearance StonePavement {
        colorOverride 0 0 0
      }
    }
    AddLanesRoadSegment {
      translation -53 0 -20
      name "road(3)"
      width 6
      length 10
      numberOfNewLanes 1
      lines [
        RoadLine {
          type "continuous"
          width 0.3
        }
      ]
      rightBarrier TRUE
      leftBarrier TRUE
      bottom TRUE
      appearance Asphalt {
        colorOverride 0 0 0
        IBLStrength 0
      }
      pavementAppearance StonePavement {
        colorOverride 0 0 0
      }
    }
    Solid {
      translation -51.48 0 -15.5
      rotation 0 1 0 0.2618
      children [
        Shape {
          appearance PBRAppearance {
            roughness 1
            metalness 0
          }
          geometry Box {
            size 0.2 0.01 11.6
          }
        }
      ]
      name "solid(2)"
    }
    StraightRoadSegment {
      translation -53 0 -50
      name "road(5)"
      width 6
      numberOfForwardLanes 2
      lines [
        RoadLine {
          type "continuous"
          width 0.3
        }
      ]
      rightBarrier TRUE
      leftBarrier TRUE
      bottom TRUE
      length 30
      appearance Asphalt {
        colorOverride 0 0 0
        IBLStrength 0
      }
      pavementAppearance StonePavement {
        colorOverride 0 0 0
      }
    }
    StraightRoadSegment {
      translation -50 0 -53
      rotation 0 1 0 1.57
      name "road(4)"
      width 6
      numberOfForwardLanes 2
      lines [
        RoadLine {
          type "continuous"
          width 0.3
        }
      ]
      rightBarrier TRUE
      leftBarrier TRUE
      bottom TRUE
      length 30
      appearance Asphalt {
        colorOverride 0 0 0
        IBLStrength 0
      }
      pavementAppearance StonePavement {
        colorOverride 0 0 0
      }
    }
    AddLanesRoadSegment {
      translation -10 0 -51.5
      rotation 0 1 0 -1.57
      name "road(2)"
      width 9
      length 10
      numberOfLanes 3
      numberOfNewLanes 1
      lines [
        RoadLine {
          type "continuous"
          width 0.3
        }
        RoadLine {
          type "continuous"
          width -1.73472e-18
        }
      ]
      rightBarrier TRUE
      leftBarrier TRUE
      bottom TRUE
      appearance Asphalt {
        colorOverride 0 0 0
        IBLStrength 0
      }
      pavementAppearance StonePavement {
        colorOverride 0 0 0
      }
    }
    Solid {
      translation 15.5 0 -51.48
      rotation 0 1 0 1.8326
      children [
        Shape {
          appearance PBRAppearance {
            roughness 1
            metalness 0
          }
          geometry Box {
            size 0.2 0.01 11.6
          }
        }
      ]
      name "solid(3)"
    }
    StraightRoadSegment {
      translation -10 0 -51.5
      rotation 0 1 0 1.571
      name "road(18)"
      width 9
      numberOfLanes 3
      numberOfForwardLanes 2
      lines [
        RoadLine {
          type "continuous"
          width 0.3
        }
        RoadLine {
          type "continuous"
          width 0.3
        }
      ]
      rightBarrier TRUE
      leftBarrier TRUE
      bottom TRUE
      length 20
      appearance Asphalt {
        colorOverride 0 0 0
        IBLStrength 0
      }
      pavementAppearance StonePavement {
        colorOverride 0 0 0
      }
    }
    AddLanesRoadSegment {
      translation 10 0 -51.5
      rotation 0 1 0 1.57
      name "road(19)"
      width 9
      length 10
      numberOfLanes 3
      numberOfNewLanes 1
      newLaneLeft FALSE
      lines [
        RoadLine {
          type "continuous"
          width 0.3
        }
        RoadLine {
          type "continuous"
          width -1.73472e-18
        }
      ]
      rightBarrier TRUE
      leftBarrier TRUE
      bottom TRUE
      appearance Asphalt {
        colorOverride 0 0 0
        IBLStrength 0
      }
      pavementAppearance StonePavement {
        colorOverride 0 0 0
      }
    }
    Solid {
      translation -15.5 0 -51.48
      rotation 0 1 0 -1.8326
      children [
        Shape {
          appearance PBRAppearance {
            roughness 1
            metalness 0
          }
          geometry Box {
            size 0.2 0.01 11.6
          }
        }
      ]
      name "solid(4)"
    }
    CurvedRoadSegment {
      translation 20 0 -36.8
      rotation 0 1 0 1.571
      name "road(33)"
      width 5.8
      numberOfForwardLanes 2
      lines [
        RoadLine {
          type "continuous"
          width 0.3
        }
      ]
      roadBorderWidth [
        0
      ]
      rightBarrier TRUE
      leftBarrier TRUE
      bottom TRUE
      totalAngle 3.14
      subdivision 21
      appearance Asphalt {
        colorOverride 0 0 0
        IBLStrength 0
      }
      pavementAppearance StonePavement {
        colorOverride 0 0 0
      }
    }
    StraightRoadSegment {
      translation -20 0 -26.8
      rotation 0 1 0 1.571
      name "road(35)"
      width 5.8
      numberOfForwardLanes 2
      lines [
        RoadLine {
          type "continuous"
          width 0.3
        }
      ]
      rightBarrier TRUE
      leftBarrier TRUE
      bottom TRUE
      length 40
      appearance Asphalt {
        colorOverride 0 0 0
        IBLStrength 0
      }
      pavementAppearance StonePavement {
        colorOverride 0 0 0
      }
    }
    CurvedRoadSegment {
      translation -20 0 -36.8
      rotation 0 1 0 -1.571
      name "road(34)"
      width 5.8
      numberOfForwardLanes 2
      lines [
        RoadLine {
          type "continuous"
          width 0.3
        }
      ]
      roadBorderWidth [
        0
      ]
      rightBarrier TRUE
      leftBarrier TRUE
      bottom TRUE
      totalAngle 3.14
      subdivision 21
      appearance Asphalt {
        colorOverride 0 0 0
        IBLStrength 0
      }
      pavementAppearance StonePavement {
        colorOverride 0 0 0
      }
    }
    StraightRoadSegment {
      translation 20 0 -53
      rotation 0 1 0 1.57
      name "road(21)"
      width 6
      numberOfForwardLanes 2
      lines [
        RoadLine {
          type "continuous"
          width 0.3
        }
      ]
      rightBarrier TRUE
      leftBarrier TRUE
      bottom TRUE
      length 30
      appearance Asphalt {
        colorOverride 0 0 0
        IBLStrength 0
      }
      pavementAppearance StonePavement {
        colorOverride 0 0 0
      }
    }
    StraightRoadSegment {
      translation 53 0 -50
      name "road(22)"
      width 6
      numberOfForwardLanes 2
      lines [
        RoadLine {
          type "continuous"
          width 0.3
        }
      ]
      rightBarrier TRUE
      leftBarrier TRUE
      bottom TRUE
      length 30
      appearance Asphalt {
        colorOverride 0 0 0
        IBLStrength 0
      }
      pavementAppearance StonePavement {
        colorOverride 0 0 0
      }
    }
    AddLanesRoadSegment {
      translation 53 0 -20
      name "road(23)"
      width 6
      length 10
      numberOfNewLanes 1
      newLaneLeft FALSE
      lines [
        RoadLine {
          type "continuous"
          width 0.3
        }
      ]
      rightBarrier TRUE
      leftBarrier TRUE
      bottom TRUE
      appearance Asphalt {
        colorOverride 0 0 0
        IBLStrength 0
      }
      pavementAppearance StonePavement {
        colorOverride 0 0 0
      }
    }
    Solid {
      translation 51.48 0 -15.5
      rotation 0 1 0 -0.2617996938995747
      children [
        Shape {
          appearance PBRAppearance {
            roughness 1
            metalness 0
          }
          geometry Box {
            size 0.2 0.01 11.6
          }
        }
      ]
      name "solid(5)"
    }
    StraightRoadSegment {
      translation 51.5 0 -10
      name "road(24)"
      width 9
      numberOfLanes 3
      numberOfForwardLanes 2
      lines [
        RoadLine {
          type "continuous"
          width 0.3
        }
        RoadLine {
          type "continuous"
          width 0.3
        }
      ]
      rightBarrier TRUE
      leftBarrier TRUE
      bottom TRUE
      length 20
      appearance Asphalt {
        colorOverride 0 0 0
        IBLStrength 0
      }
      pavementAppearance StonePavement {
        colorOverride 0 0 0
      }
    }
    AddLanesRoadSegment {
      translation 53 0 20
      rotation 0 1 0 3.14
      name "road(25)"
      width 6
      length 10
      numberOfNewLanes 1
      lines [
        RoadLine {
          type "continuous"
          width 0.3
        }
      ]
      rightBarrier TRUE
      leftBarrier TRUE
      bottom TRUE
      appearance Asphalt {
        colorOverride 0 0 0
        IBLStrength 0
      }
      pavementAppearance StonePavement {
        colorOverride 0 0 0
      }
    }
    Solid {
      translation 51.48 0 15.5
      rotation 0 1 0 0.2618
      children [
        Shape {
          appearance PBRAppearance {
            roughness 1
            metalness 0
          }
          geometry Box {
            size 0.2 0.01 11.6
          }
        }
      ]
      name "solid(6)"
    }
    StraightRoadSegment {
      translation 53 0 20
      name "road(26)"
      width 6
      numberOfForwardLanes 2
      lines [
        RoadLine {
          type "continuous"
          width 0.3
        }
      ]
      rightBarrier TRUE
      leftBarrier TRUE
      bottom TRUE
      length 30
      appearance Asphalt {
        colorOverride 0 0 0
        IBLStrength 0
      }
      pavementAppearance StonePavement {
        colorOverride 0 0 0
      }
    }
    StraightRoadSegment {
      translation 20 0 53
      rotation 0 1 0 1.57
      name "road(27)"
      width 6
      numberOfForwardLanes 2
      lines [
        RoadLine {
          type "continuous"
          width 0.3
        }
      ]
      rightBarrier TRUE
      leftBarrier TRUE
      bottom TRUE
      length 30
      appearance Asphalt {
        colorOverride 0 0 0
        IBLStrength 0
      }
      pavementAppearance StonePavement {
        colorOverride 0 0 0
      }
    }
    AddLanesRoadSegment {
      translation 20 0 53
      rotation 0 1 0 -1.57
      name "road(28)"
      width 6
      length 10
      numberOfNewLanes 1
      newLaneLeft FALSE
      lines [
        RoadLine {
          type "continuous"
          width 0.3
        }
      ]
      rightBarrier TRUE
      leftBarrier TRUE
      bottom TRUE
      appearance Asphalt {
        colorOverride 0 0 0
        IBLStrength 0
      }
      pavementAppearance StonePavement {
        colorOverride 0 0 0
      }
    }
    Solid {
      translation 15.5 0 51.48
      rotation 0 1 0 -1.8326
      children [
        Shape {
          appearance PBRAppearance {
            roughness 1
            metalness 0
          }
          geometry Box {
            size 0.2 0.01 11.6
          }
        }
      ]
      name "solid(7)"
    }
    StraightRoadSegment {
      translation -10 0 51.5
      rotation 0 1 0 1.57
      name "road(29)"
      width 9
      numberOfLanes 3
      numberOfForwardLanes 2
      lines [
        RoadLine {
          type "continuous"
          width 0.3
        }
        RoadLine {
          type "continuous"
          width 0.3
        }
      ]
      rightBarrier TRUE
      leftBarrier TRUE
      bottom TRUE
      length 20
      appearance Asphalt {
        colorOverride 0 0 0
        IBLStrength 0
      }
      pavementAppearance StonePavement {
        colorOverride 0 0 0
      }
    }
    AddLanesRoadSegment {
      translation -20 0 53
      rotation 0 1 0 1.57
      name "road(30)"
      width 6
      length 10
      numberOfNewLanes 1
      lines [
        RoadLine {
          type "continuous"
          width 0.3
        }
      ]
      rightBarrier TRUE
      leftBarrier TRUE
      bottom TRUE
      appearance Asphalt {
        colorOverride 0 0 0
        IBLStrength 0
      }
      pavementAppearance StonePavement {
        colorOverride 0 0 0
      }
    }
    Solid {
      translation -15.5 0 51.48
      rotation 0 1 0 1.8326
      children [
        Shape {
          appearance PBRAppearance {
            roughness 1
            metalness 0
          }
          geometry Box {
            size 0.2 0.01 11.6
          }
        }
      ]
      name "solid(8)"
    }
    StraightRoadSegment {
      translation -50 0 53
      rotation 0 1 0 1.57
      name "road(32)"
      width 6
      numberOfForwardLanes 2
      lines [
        RoadLine {
          type "continuous"
          width 0.3
        }
      ]
      rightBarrier TRUE
      leftBarrier TRUE
      bottom TRUE
      length 30
      appearance Asphalt {
        colorOverride 0 0 0
        IBLStrength 0
      }
      pavementAppearance StonePavement {
        colorOverride 0 0 0
      }
    }
    StraightRoadSegment {
      translation 53 0 20
      name "road(31)"
      width 6
      numberOfForwardLanes 2
      lines [
        RoadLine {
          type "continuous"
          width 0.3
        }
      ]
      rightBarrier TRUE
      leftBarrier TRUE
      bottom TRUE
      length 30
      appearance Asphalt {
        colorOverride 0 0 0
        IBLStrength 0
      }
      pavementAppearance StonePavement {
        colorOverride 0 0 0
      }
    }
    StraightRoadSegment {
      translation -76 0 -33
      name "road(6)"
      width 6
      numberOfForwardLanes 2
      lines [
        RoadLine {
          type "continuous"
          width 0.3
        }
      ]
      rightBarrier TRUE
      leftBarrier TRUE
      bottom TRUE
      length 66
      appearance Asphalt {
        colorOverride 0 0 0
        IBLStrength 0
      }
      pavementAppearance StonePavement {
        colorOverride 0 0 0
      }
    }
    StraightRoadSegment {
      translation -33 0 -76
      rotation 0 1 0 1.57
      name "road(14)"
      width 6
      numberOfForwardLanes 2
      lines [
        RoadLine {
          type "continuous"
          width 0.3
        }
      ]
      rightBarrier TRUE
      leftBarrier TRUE
      bottom TRUE
      length 66
      appearance Asphalt {
        colorOverride 0 0 0
        IBLStrength 0
      }
      pavementAppearance StonePavement {
        colorOverride 0 0 0
      }
    }
    StraightRoadSegment {
      translation 76 0 -33
      name "road(15)"
      width 6
      numberOfForwardLanes 2
      lines [
        RoadLine {
          type "continuous"
          width 0.3
        }
      ]
      rightBarrier TRUE
      leftBarrier TRUE
      bottom TRUE
      length 66
      appearance Asphalt {
        colorOverride 0 0 0
        IBLStrength 0
      }
      pavementAppearance StonePavement {
        colorOverride 0 0 0
      }
    }
    StraightRoadSegment {
      translation -33 0 76
      rotation 0 1 0 1.57
      name "road(16)"
      width 6
      numberOfForwardLanes 2
      lines [
        RoadLine {
          type "continuous"
          width 0.3
        }
      ]
      rightBarrier TRUE
      leftBarrier TRUE
      bottom TRUE
      length 66
      appearance Asphalt {
        colorOverride 0 0 0
        IBLStrength 0
      }
      pavementAppearance StonePavement {
        colorOverride 0 0 0
      }
    }
    Solid {
      translation -15 0 -48.41
      rotation 0 1 0 -1.26
      children [
        Shape {
          appearance PBRAppearance {
            roughness 1
            metalness 0
          }
          geometry Box {
            size 0.2 0.01 10.67
          }
        }
      ]
      name "solid(9)"
    }
    Solid {
      translation 15 0 -48.39
      rotation 0 1 0 -1.88
      children [
        Shape {
          appearance PBRAppearance {
            roughness 1
            metalness 0
          }
          geometry Box {
            size 0.2 0.01 10.67
          }
        }
      ]
      name "solid(10)"
    }
  ]
  name "environment"
}
Floor {
  size 176 176
  tileSize 0.1 0.1
  appearance PBRAppearance {
    baseColor 0.5 0.5 0.5
    transparency 0.9
    metalness 0
  }
}
