#VRML_SIM R2020a utf8
WorldInfo {
  basicTimeStep 16
}
Viewpoint {
<<<<<<< HEAD
  orientation 0.03808682417150016 0.7714041274115354 0.635204743399305 3.119688131672871
  position 6.409620980680648 139.501828724283 -82.55227138078858
=======
  orientation -0.3561820611274205 0.8929354878619198 0.2753190037898181 1.1006983234984413
  position 6.798450751790384 15.370336924761107 -20.682202171309395
>>>>>>> 646ec37621c7860671f5e36e707d995a69f27d43
}
TexturedBackground {
  luminosity 2
  reflections FALSE
}
DEF Cab1 Robot {
  translation -21.579580903099952 0.3986696791302122 -29.474300131682092
  rotation -0.00011349042279701871 0.9999999864428721 -0.00011930708025550741 -1.5723852175075563
  children [
    DEF cam_f Camera {
      translation 0 0.1 1
      rotation 0.00020599496346978955 -0.9659258287071042 -0.2588189541022232 -3.140055307179586
      children [
        Shape {
          appearance PBRAppearance {
            baseColor 0.4 0 0
          }
          geometry Cylinder {
            height 0.1
            radius 0.05
          }
        }
      ]
      boundingObject Cylinder {
        height 0.1
        radius 0.05
      }
      physics Physics {
        density 1
      }
      recognitionColors [
        0 0 0
      ]
      fieldOfView 0.75
      width 18
      height 10
      far 10
    }
    DEF ls_f LightSensor {
      translation 0 0 1
      rotation 0 1 0 -1.57
      children [
        Shape {
          appearance PBRAppearance {
            baseColor 0 0 0
            metalness 0
          }
          geometry Box {
            size 0.1 0.1 0.1
          }
        }
      ]
      name "ls_front"
      boundingObject Shape {
        appearance PBRAppearance {
        }
        geometry Cylinder {
          height 0.1
          radius 0.05
        }
      }
      physics Physics {
        density 1
      }
      lookupTable [
        0 0 0
        5 1000 0
      ]
    }
    DEF ds_fl DistanceSensor {
      translation 0.45 0.2 1
      rotation 0 1 0 -1.047
      children [
        Shape {
          appearance PBRAppearance {
          }
          geometry Box {
            size 0.1 0.1 0.1
          }
        }
      ]
      name "ds_fl"
      boundingObject Shape {
        appearance PBRAppearance {
        }
        geometry Box {
          size 0.1 0.1 0.1
        }
      }
      physics Physics {
        density 1
      }
      lookupTable [
        0 0 0
        5 1000 0
      ]
    }
    DEF ds_lf DistanceSensor {
      translation 0.5 0.2 0.95
      children [
        Shape {
          appearance PBRAppearance {
          }
          geometry Box {
            size 0.1 0.1 0.1
          }
        }
      ]
      name "ds_lf"
      boundingObject Shape {
        appearance PBRAppearance {
        }
        geometry Box {
          size 0.1 0.1 0.1
        }
      }
      physics Physics {
        density 1
      }
      lookupTable [
        0 0 0
        5 1000 0
      ]
    }
    DEF ds_lc DistanceSensor {
      translation 0.5 0.2 0
      children [
        Shape {
          appearance PBRAppearance {
          }
          geometry Box {
            size 0.1 0.1 0.1
          }
        }
      ]
      name "ds_lc"
      boundingObject Shape {
        appearance PBRAppearance {
        }
        geometry Box {
          size 0.1 0.1 0.1
        }
      }
      physics Physics {
        density 1
      }
      lookupTable [
        0 0 0
        5 1000 0
      ]
    }
    DEF ds_fr DistanceSensor {
      translation -0.45 0.2 1
      rotation 0 1 0 -2.09
      children [
        Shape {
          appearance PBRAppearance {
          }
          geometry Box {
            size 0.1 0.1 0.1
          }
        }
      ]
      name "ds_fr"
      boundingObject Shape {
        appearance PBRAppearance {
        }
        geometry Box {
          size 0.1 0.1 0.1
        }
      }
      physics Physics {
        density 1
      }
      lookupTable [
        0 0 0
        5 1000 0
      ]
    }
    DEF ds_rf DistanceSensor {
      translation -0.5 0.2 0.95
      rotation 0 1 0 -3.14
      children [
        Shape {
          appearance PBRAppearance {
          }
          geometry Box {
            size 0.1 0.1 0.1
          }
        }
      ]
      name "ds_rf"
      boundingObject Shape {
        appearance PBRAppearance {
        }
        geometry Box {
          size 0.1 0.1 0.1
        }
      }
      physics Physics {
        density 1
      }
      lookupTable [
        0 0 0
        5 1000 0
      ]
    }
    DEF ds_rc DistanceSensor {
      translation -0.5 0.2 0
      rotation 0 1 0 -3.14
      children [
        Shape {
          appearance PBRAppearance {
          }
          geometry Box {
            size 0.1 0.1 0.1
          }
        }
      ]
      name "ds_rc"
      boundingObject Shape {
        appearance PBRAppearance {
        }
        geometry Box {
          size 0.1 0.1 0.1
        }
      }
      physics Physics {
        density 1
      }
      lookupTable [
        0 0 0
        5 1000 0
      ]
    }
    DEF ds_fc DistanceSensor {
      translation 0 0.2 1
      rotation 0 1 0 -1.57
      children [
        Shape {
          appearance PBRAppearance {
          }
          geometry Box {
            size 0.1 0.1 0.1
          }
        }
      ]
      name "ds_fc"
      boundingObject Shape {
        appearance PBRAppearance {
        }
        geometry Box {
          size 0.1 0.1 0.1
        }
      }
      physics Physics {
        density 1
      }
      lookupTable [
        0 0 0
        5 1000 0
      ]
    }
    DEF ds_fcr DistanceSensor {
      translation -0.225 0.2 1
      rotation 0 1 0 -1.833
      children [
        Shape {
          appearance PBRAppearance {
          }
          geometry Box {
            size 0.1 0.1 0.1
          }
        }
      ]
      name "ds_fcr"
      boundingObject Shape {
        appearance PBRAppearance {
        }
        geometry Box {
          size 0.1 0.1 0.1
        }
      }
      physics Physics {
        density 1
      }
      lookupTable [
        0 0 0
        5 1000 0
      ]
    }
    DEF ds_fcl DistanceSensor {
      translation 0.225 0.2 1
      rotation 0 1 0 -1.309
      children [
        Shape {
          appearance PBRAppearance {
          }
          geometry Box {
            size 0.1 0.1 0.1
          }
        }
      ]
      name "ds_fcl"
      boundingObject Shape {
        appearance PBRAppearance {
        }
        geometry Box {
          size 0.1 0.1 0.1
        }
      }
      physics Physics {
        density 1
      }
      lookupTable [
        0 0 0
        5 1000 0
      ]
    }
    Transform {
      translation 0 0.5 -0.3
      rotation 1 0 0 0
      children [
        Shape {
          appearance PBRAppearance {
            baseColor 0.5 0.5 0.5
            transparency 0.3
          }
          geometry Box {
            size 0.9 0.5 1.2
          }
        }
      ]
    }
    Transform {
      translation 0 0.8 -0.3
      rotation 1 0 0 0
      children [
        Shape {
          appearance PBRAppearance {
            baseColor 0 0 0
          }
          geometry Box {
            size 1 0.1 1.3
          }
        }
      ]
    }
    DEF wheelFL HingeJoint {
      jointParameters HingeJointParameters {
        position -3.327365227964424e-08
        anchor 0.55 -0.1 0.55
      }
      device [
        DEF wheelFL RotationalMotor {
          name "wheelFL"
          maxTorque 30
        }
      ]
      endPoint DEF wheelFL Solid {
        translation 0.55 -0.1 0.55
        rotation -2.1893889123405995e-08 2.1876461371024583e-08 0.9999999999999996 1.569999999999997
        children [
          DEF wheel Shape {
            appearance PBRAppearance {
              baseColor 0 0 0
              metalness 0
            }
            geometry Cylinder {
              height 0.1
              radius 0.3
            }
          }
        ]
        name "wheelFL"
        boundingObject USE wheel
        physics DEF physics_wheel Physics {
          density 10
        }
        linearVelocity 1.950715502247343e-07 -5.085093994868393e-09 7.536136614471023e-09
        angularVelocity 5.1203480173674426e-09 3.578277130030934e-08 -3.65775532953339e-07
      }
    }
    DEF wheelRL HingeJoint {
      jointParameters HingeJointParameters {
        position -3.474033146525983e-08
        anchor 0.55 -0.1 -0.7
      }
      device [
        DEF wheelRL RotationalMotor {
          name "wheelRL"
          maxTorque 30
        }
      ]
      endPoint DEF wheelRL Solid {
        translation 0.55 -0.1 -0.7
        rotation -2.6947320193211024e-08 2.692586985969454e-08 0.9999999999999992 1.569999999999997
        children [
          DEF wheel Shape {
            appearance PBRAppearance {
              baseColor 0 0 0
              metalness 0
            }
            geometry Cylinder {
              height 0.1
              radius 0.3
            }
          }
        ]
        name "wheelRL"
        boundingObject USE wheel
        physics DEF physics_wheel Physics {
          density 10
        }
        linearVelocity -2.3779717544403902e-08 9.32502056065934e-09 -7.293088919314803e-09
        angularVelocity -4.222516151479196e-09 3.5835003068142094e-08 -2.5126010575823605e-07
      }
    }
    DEF wheelRR HingeJoint {
      jointParameters HingeJointParameters {
        position -3.6704670336654414e-08
        anchor -0.55 -0.1 -0.7
      }
      device [
        DEF wheelRR RotationalMotor {
          name "wheelRR"
          maxTorque 30
        }
      ]
      endPoint DEF wheelRR Solid {
        translation -0.55 -0.1 -0.7
        rotation -1.836695544660301e-08 1.8352335168327204e-08 0.9999999999999998 1.5699999999999965
        children [
          DEF wheel Shape {
            appearance PBRAppearance {
              baseColor 0 0 0
              metalness 0
            }
            geometry Cylinder {
              height 0.1
              radius 0.3
            }
          }
        ]
        name "wheelRR"
        boundingObject USE wheel
        physics DEF physics_wheel Physics {
          density 10
        }
        linearVelocity -3.0642451014027804e-08 9.281734602491383e-09 -7.3050330966560336e-09
        angularVelocity -4.196054100447201e-09 3.5827189683326676e-08 -2.6772109614015735e-07
      }
    }
    DEF wheelFR HingeJoint {
      jointParameters HingeJointParameters {
<<<<<<< HEAD
=======
        position -3.4845702781946854e-08
>>>>>>> 646ec37621c7860671f5e36e707d995a69f27d43
        anchor -0.55 -0.1 0.55
      }
      device [
        DEF wheelFR RotationalMotor {
          name "wheelFR"
          maxTorque 30
        }
      ]
      endPoint DEF wheelFR Solid {
        translation -0.55 -0.1 0.55
<<<<<<< HEAD
        rotation 0 0 1 1.5699999999999956
=======
        rotation -1.743673120154564e-08 1.7422851390973424e-08 0.9999999999999998 1.5699999999999958
>>>>>>> 646ec37621c7860671f5e36e707d995a69f27d43
        children [
          DEF wheel Shape {
            appearance PBRAppearance {
              baseColor 0 0 0
              metalness 0
            }
            geometry Cylinder {
              height 0.1
              radius 0.3
            }
          }
        ]
        name "wheelFR"
        boundingObject USE wheel
        physics DEF physics_wheel Physics {
          density 10
        }
        linearVelocity 5.152535216647514e-08 -5.128352101827773e-09 7.3093455148862074e-09
        angularVelocity 4.151865149778144e-09 3.58081341069666e-08 2.4352595949035485e-07
      }
    }
    DEF car_body Shape {
      appearance PBRAppearance {
        baseColor 1 1 0
      }
      geometry Box {
        size 1 0.6 2
      }
    }
  ]
  name "Cab1"
  boundingObject USE car_body
  physics Physics {
    density 10
  }
  recognitionColors [
    0 0 0
  ]
  controller "controller"
  linearVelocity 4.67899702463465e-08 1.2081959338530822e-09 2.77736723402194e-09
  angularVelocity -5.804882712806141e-11 3.601954847277697e-08 1.1616814428901493e-08
}
DEF Cab2 Robot {
  translation 9.99990683573974 0.3986696792225525 -29.100002401195102
  rotation -0.00011349074803640289 0.9999999864427955 -0.00011930741416728066 -1.5723853225464746
  children [
    DEF cam_f Camera {
      translation 0 0.1 1
      rotation 0 1 0 3.14
      children [
        Shape {
          appearance PBRAppearance {
            baseColor 0.4 0 0
          }
          geometry Cylinder {
            height 0.1
            radius 0.05
          }
        }
      ]
      boundingObject Cylinder {
        height 0.1
        radius 0.05
      }
      physics Physics {
        density 1
      }
      fieldOfView 0.75
      width 18
      height 10
      far 10
    }
    DEF ls_f LightSensor {
      translation 0 0 1
      rotation 0 1 0 -1.57
      children [
        Shape {
          appearance PBRAppearance {
            baseColor 0 0 0
            metalness 0
          }
          geometry Box {
            size 0.1 0.1 0.1
          }
        }
      ]
      name "ls_front"
      boundingObject Shape {
        appearance PBRAppearance {
        }
        geometry Cylinder {
          height 0.1
          radius 0.05
        }
      }
      physics Physics {
        density 1
      }
      lookupTable [
        0 0 0
        5 1000 0
      ]
    }
    DEF ds_fl DistanceSensor {
      translation 0.45 0.2 1
      rotation 0 1 0 -1.047
      children [
        Shape {
          appearance PBRAppearance {
          }
          geometry Box {
            size 0.1 0.1 0.1
          }
        }
      ]
      name "ds_fl"
      boundingObject Shape {
        appearance PBRAppearance {
        }
        geometry Box {
          size 0.1 0.1 0.1
        }
      }
      physics Physics {
        density 1
      }
      lookupTable [
        0 0 0
        5 1000 0
      ]
    }
    DEF ds_lf DistanceSensor {
      translation 0.5 0.2 0.95
      children [
        Shape {
          appearance PBRAppearance {
          }
          geometry Box {
            size 0.1 0.1 0.1
          }
        }
      ]
      name "ds_lf"
      boundingObject Shape {
        appearance PBRAppearance {
        }
        geometry Box {
          size 0.1 0.1 0.1
        }
      }
      physics Physics {
        density 1
      }
      lookupTable [
        0 0 0
        5 1000 0
      ]
    }
    DEF ds_lc DistanceSensor {
      translation 0.5 0.2 0
      children [
        Shape {
          appearance PBRAppearance {
          }
          geometry Box {
            size 0.1 0.1 0.1
          }
        }
      ]
      name "ds_lc"
      boundingObject Shape {
        appearance PBRAppearance {
        }
        geometry Box {
          size 0.1 0.1 0.1
        }
      }
      physics Physics {
        density 1
      }
      lookupTable [
        0 0 0
        5 1000 0
      ]
    }
    DEF ds_fr DistanceSensor {
      translation -0.45 0.2 1
      rotation 0 1 0 -2.09
      children [
        Shape {
          appearance PBRAppearance {
          }
          geometry Box {
            size 0.1 0.1 0.1
          }
        }
      ]
      name "ds_fr"
      boundingObject Shape {
        appearance PBRAppearance {
        }
        geometry Box {
          size 0.1 0.1 0.1
        }
      }
      physics Physics {
        density 1
      }
      lookupTable [
        0 0 0
        5 1000 0
      ]
    }
    DEF ds_rf DistanceSensor {
      translation -0.5 0.2 0.95
      rotation 0 1 0 -3.14
      children [
        Shape {
          appearance PBRAppearance {
          }
          geometry Box {
            size 0.1 0.1 0.1
          }
        }
      ]
      name "ds_rf"
      boundingObject Shape {
        appearance PBRAppearance {
        }
        geometry Box {
          size 0.1 0.1 0.1
        }
      }
      physics Physics {
        density 1
      }
      lookupTable [
        0 0 0
        5 1000 0
      ]
    }
    DEF ds_rc DistanceSensor {
      translation -0.5 0.2 0
      rotation 0 1 0 -3.14
      children [
        Shape {
          appearance PBRAppearance {
          }
          geometry Box {
            size 0.1 0.1 0.1
          }
        }
      ]
      name "ds_rc"
      boundingObject Shape {
        appearance PBRAppearance {
        }
        geometry Box {
          size 0.1 0.1 0.1
        }
      }
      physics Physics {
        density 1
      }
      lookupTable [
        0 0 0
        5 1000 0
      ]
    }
    DEF ds_fc DistanceSensor {
      translation 0 0.2 1
      rotation 0 1 0 -1.57
      children [
        Shape {
          appearance PBRAppearance {
          }
          geometry Box {
            size 0.1 0.1 0.1
          }
        }
      ]
      name "ds_fc"
      boundingObject Shape {
        appearance PBRAppearance {
        }
        geometry Box {
          size 0.1 0.1 0.1
        }
      }
      physics Physics {
        density 1
      }
      lookupTable [
        0 0 0
        5 1000 0
      ]
    }
    DEF ds_fcr DistanceSensor {
      translation -0.225 0.2 1
      rotation 0 1 0 -1.833
      children [
        Shape {
          appearance PBRAppearance {
          }
          geometry Box {
            size 0.1 0.1 0.1
          }
        }
      ]
      name "ds_fcr"
      boundingObject Shape {
        appearance PBRAppearance {
        }
        geometry Box {
          size 0.1 0.1 0.1
        }
      }
      physics Physics {
        density 1
      }
      lookupTable [
        0 0 0
        5 1000 0
      ]
    }
    DEF ds_fcl DistanceSensor {
      translation 0.225 0.2 1
      rotation 0 1 0 -1.309
      children [
        Shape {
          appearance PBRAppearance {
          }
          geometry Box {
            size 0.1 0.1 0.1
          }
        }
      ]
      name "ds_fcl"
      boundingObject Shape {
        appearance PBRAppearance {
        }
        geometry Box {
          size 0.1 0.1 0.1
        }
      }
      physics Physics {
        density 1
      }
      lookupTable [
        0 0 0
        5 1000 0
      ]
    }
    Transform {
      translation 0 0.5 -0.3
      rotation 1 0 0 0
      children [
        Shape {
          appearance PBRAppearance {
            baseColor 0.5 0.5 0.5
            transparency 0.3
          }
          geometry Box {
            size 0.9 0.5 1.2
          }
        }
      ]
    }
    Transform {
      translation 0 0.8 -0.3
      rotation 1 0 0 0
      children [
        Shape {
          appearance PBRAppearance {
            baseColor 0 0 0
          }
          geometry Box {
            size 1 0.1 1.3
          }
        }
      ]
    }
    DEF wheelFL HingeJoint {
      jointParameters HingeJointParameters {
        position 6.565185862718732e-08
        anchor 0.55 -0.1 0.55
      }
      device [
        DEF wheelFL RotationalMotor {
          name "wheelFL"
          maxTorque 30
        }
      ]
      endPoint DEF wheelFL Solid {
        translation 0.55 -0.1 0.55
        rotation 3.2852079894259525e-08 -3.2825929313593646e-08 0.999999999999999 1.5699999999999972
        children [
          DEF wheel Shape {
            appearance PBRAppearance {
              baseColor 0 0 0
              metalness 0
            }
            geometry Cylinder {
              height 0.1
              radius 0.3
            }
          }
        ]
        name "wheelFL"
        boundingObject USE wheel
        physics DEF physics_wheel Physics {
          density 10
        }
        linearVelocity -7.946797302174478e-08 -4.085704167686341e-10 -1.7181532812081785e-08
        angularVelocity -9.369390193175526e-09 -7.837683866645338e-08 3.1907111840294945e-07
      }
    }
    DEF wheelRL HingeJoint {
      jointParameters HingeJointParameters {
        position 6.851179007440314e-08
        anchor 0.55 -0.1 -0.7
      }
      device [
        DEF wheelRL RotationalMotor {
          name "wheelRL"
          maxTorque 30
        }
      ]
      endPoint DEF wheelRL Solid {
        translation 0.55 -0.1 -0.7
        rotation 3.4283184791526384e-08 -3.425589503720155e-08 0.999999999999999 1.5699999999999974
        children [
          DEF wheel Shape {
            appearance PBRAppearance {
              baseColor 0 0 0
              metalness 0
            }
            geometry Cylinder {
              height 0.1
              radius 0.3
            }
          }
        ]
        name "wheelRL"
        boundingObject USE wheel
        physics DEF physics_wheel Physics {
          density 10
        }
        linearVelocity -8.21565715835917e-08 -3.6899430210325365e-10 1.7383121592283507e-08
        angularVelocity 9.792510782153218e-09 -7.837619747718739e-08 3.3195381076805603e-07
      }
    }
    DEF wheelRR HingeJoint {
      jointParameters HingeJointParameters {
        position 9.313885876194207e-11
        anchor -0.55 -0.1 -0.7
      }
      device [
        DEF wheelRR RotationalMotor {
          name "wheelRR"
          maxTorque 30
        }
      ]
      endPoint DEF wheelRR Solid {
        translation -0.55 -0.1 -0.7
        rotation 4.6606528638939754e-11 -4.656942938097104e-11 1 1.5699999999999963
        children [
          DEF wheel Shape {
            appearance PBRAppearance {
              baseColor 0 0 0
              metalness 0
            }
            geometry Cylinder {
              height 0.1
              radius 0.3
            }
          }
        ]
        name "wheelRR"
        boundingObject USE wheel
        physics DEF physics_wheel Physics {
          density 10
        }
        linearVelocity 8.195561574380904e-08 4.091174533261147e-10 1.7643864792902372e-08
        angularVelocity 1.0846711951098836e-08 -7.839542498855203e-08 -3.314916979496033e-07
      }
    }
    DEF wheelFR HingeJoint {
      jointParameters HingeJointParameters {
<<<<<<< HEAD
=======
        position -3.1917189916962774e-11
>>>>>>> 646ec37621c7860671f5e36e707d995a69f27d43
        anchor -0.55 -0.1 0.55
      }
      device [
        DEF wheelFR RotationalMotor {
          name "wheelFR"
          maxTorque 30
        }
      ]
      endPoint DEF wheelFR Solid {
        translation -0.55 -0.1 0.55
<<<<<<< HEAD
        rotation 0 0 1 1.5699999999999956
=======
        rotation -1.5971308277908426e-11 1.595859495848373e-11 1 1.5699999999999956
>>>>>>> 646ec37621c7860671f5e36e707d995a69f27d43
        children [
          DEF wheel Shape {
            appearance PBRAppearance {
              baseColor 0 0 0
              metalness 0
            }
            geometry Cylinder {
              height 0.1
              radius 0.3
            }
          }
        ]
        name "wheelFR"
        boundingObject USE wheel
        physics DEF physics_wheel Physics {
          density 10
        }
        linearVelocity 7.93689259558847e-08 3.695397303209838e-10 -1.6929191925294487e-08
        angularVelocity -8.355872753030928e-09 -7.839477930810898e-08 -3.187794251587571e-07
      }
    }
    DEF car_body Shape {
      appearance PBRAppearance {
        baseColor 1 1 0
      }
      geometry Box {
        size 1 0.6 2
      }
    }
  ]
  name "Cab2"
  boundingObject USE car_body
  physics Physics {
    density 10
  }
  recognitionColors [
    0 0 0
  ]
  controller "controller"
  linearVelocity -6.857000340122541e-11 -2.169374964096955e-12 -5.644168655114029e-09
  angularVelocity 7.217472018958654e-10 -7.88218511706991e-08 3.352718668339066e-11
}
DEF environment Solid {
  scale 1.09819 1.09819 1.09819
  children [
    DEF PickUp1 BusStop {
      translation 0 0 -45
      rotation 0 1 0 3.14159
      name "PickUp1"
      bench FALSE
      appearance PBRAppearance {
        baseColor 0 0 0
        roughness 0.5
        metalness 0
      }
      internalAdvertisingTexture []
      externalAdvertisingTexture []
    }
    DEF PickUp2 BusStop {
      translation 45 0 0
      rotation 0 -1 0 -1.5707953071795862
      name "PickUp2"
      bench FALSE
      appearance PBRAppearance {
        baseColor 1 0 0
        roughness 0.5
        metalness 0
      }
      internalAdvertisingTexture []
      externalAdvertisingTexture []
      advertisingLightOn FALSE
    }
    DEF PickUp3 BusStop {
      translation 0 0 45
      rotation 0 1 0 -5.307179586466759e-06
      name "PickUp3"
      bench FALSE
      appearance PBRAppearance {
        baseColor 0 1 0
        roughness 0.5
        metalness 0
      }
      internalAdvertisingTexture []
      externalAdvertisingTexture []
      advertisingLightOn FALSE
    }
    DEF PickUp4 BusStop {
      translation -45 0 0
      rotation 0 1 0 -1.5707953071795862
      name "PickUp4"
      bench FALSE
      appearance PBRAppearance {
        baseColor 0 0 1
        roughness 0.5
        metalness 0
      }
      internalAdvertisingTexture []
      externalAdvertisingTexture []
      advertisingLightOn FALSE
    }
    DEF PickUp5 BusStop {
      translation 0 0 -71
      rotation 0 1 0 3.14159
      name "PickUp5"
      bench FALSE
      appearance PBRAppearance {
        baseColor 1 1 0
        roughness 0.5
        metalness 0
      }
      internalAdvertisingTexture []
      externalAdvertisingTexture []
      advertisingLightOn FALSE
    }
    DEF PickUp6 BusStop {
      translation 71 0 0
      rotation 0 -1 0 -1.5707953071795862
      name "PickUp6"
      bench FALSE
      appearance PBRAppearance {
        baseColor 1 0 1
        roughness 0.5
        metalness 0
      }
      internalAdvertisingTexture []
      externalAdvertisingTexture []
      advertisingLightOn FALSE
    }
    DEF PickUp7 BusStop {
      translation 0 0 71
      rotation 0 1 0 -5.307179586466759e-06
      name "PickUp7"
      bench FALSE
      appearance PBRAppearance {
        baseColor 0 1 1
        roughness 0.5
        metalness 0
      }
      internalAdvertisingTexture []
      externalAdvertisingTexture []
      advertisingLightOn FALSE
    }
    DEF PickUp8 BusStop {
      translation -71 0 0
      rotation 0 1 0 -1.5707953071795862
      name "PickUp8"
      bench FALSE
      appearance PBRAppearance {
        roughness 0.5
        metalness 0
      }
      internalAdvertisingTexture []
      externalAdvertisingTexture []
      advertisingLightOn FALSE
    }
    CurvedRoadSegment {
      translation -56 0 33
      rotation 0 1 0 -1.570796
      name "road(1)"
      width 6
      numberOfForwardLanes 2
      lines [
        RoadLine {
          type "continuous"
          width 0.3
        }
      ]
      rightBarrier TRUE
      leftBarrier TRUE
      bottom TRUE
      curvatureRadius 20
      appearance Asphalt {
        colorOverride 0 0 0
        IBLStrength 0
      }
      pavementAppearance StonePavement {
        colorOverride 0 0 0
      }
    }
    CurvedRoadSegment {
      translation -56 0 -33
      rotation 0 1 0 3.14
      name "road(7)"
      width 6
      numberOfForwardLanes 2
      lines [
        RoadLine {
          type "continuous"
          width 0.3
        }
      ]
      rightBarrier TRUE
      leftBarrier TRUE
      bottom TRUE
      curvatureRadius 20
      appearance Asphalt {
        colorOverride 0 0 0
        IBLStrength 0
      }
      pavementAppearance StonePavement {
        colorOverride 0 0 0
      }
    }
    CurvedRoadSegment {
      translation -33 0 -56
      rotation 0 1 0 3.14
      name "road(8)"
      width 6
      numberOfForwardLanes 2
      lines [
        RoadLine {
          type "continuous"
          width 0.3
        }
      ]
      rightBarrier TRUE
      leftBarrier TRUE
      bottom TRUE
      curvatureRadius 20
      appearance Asphalt {
        colorOverride 0 0 0
        IBLStrength 0
      }
      pavementAppearance StonePavement {
        colorOverride 0 0 0
      }
    }
    CurvedRoadSegment {
      translation 33 0 -56
      rotation 0 1 0 1.57
      name "road(9)"
      width 6
      numberOfForwardLanes 2
      lines [
        RoadLine {
          type "continuous"
          width 0.3
        }
      ]
      rightBarrier TRUE
      leftBarrier TRUE
      bottom TRUE
      curvatureRadius 20
      appearance Asphalt {
        colorOverride 0 0 0
        IBLStrength 0
      }
      pavementAppearance StonePavement {
        colorOverride 0 0 0
      }
    }
    CurvedRoadSegment {
      translation 56 0 -33
      rotation 0 1 0 1.57
      name "road(10)"
      width 6
      numberOfForwardLanes 2
      lines [
        RoadLine {
          type "continuous"
          width 0.3
        }
      ]
      rightBarrier TRUE
      leftBarrier TRUE
      bottom TRUE
      curvatureRadius 20
      appearance Asphalt {
        colorOverride 0 0 0
        IBLStrength 0
      }
      pavementAppearance StonePavement {
        colorOverride 0 0 0
      }
    }
    CurvedRoadSegment {
      translation 56 0 33
      name "road(11)"
      width 6
      numberOfForwardLanes 2
      lines [
        RoadLine {
          type "continuous"
          width 0.3
        }
      ]
      rightBarrier TRUE
      leftBarrier TRUE
      bottom TRUE
      curvatureRadius 20
      appearance Asphalt {
        colorOverride 0 0 0
        IBLStrength 0
      }
      pavementAppearance StonePavement {
        colorOverride 0 0 0
      }
    }
    CurvedRoadSegment {
      translation 33 0 56
      name "road(12)"
      width 6
      numberOfForwardLanes 2
      lines [
        RoadLine {
          type "continuous"
          width 0.3
        }
      ]
      rightBarrier TRUE
      leftBarrier TRUE
      bottom TRUE
      curvatureRadius 20
      appearance Asphalt {
        colorOverride 0 0 0
        IBLStrength 0
      }
      pavementAppearance StonePavement {
        colorOverride 0 0 0
      }
    }
    CurvedRoadSegment {
      translation -33 0 56
      rotation 0 1 0 -1.57
      name "road(13)"
      width 6
      numberOfForwardLanes 2
      lines [
        RoadLine {
          type "continuous"
          width 0.3
        }
      ]
      rightBarrier TRUE
      leftBarrier TRUE
      bottom TRUE
      curvatureRadius 20
      appearance Asphalt {
        colorOverride 0 0 0
        IBLStrength 0
      }
      pavementAppearance StonePavement {
        colorOverride 0 0 0
      }
    }
    RoadIntersection {
      translation -53 0 53
      rotation 0 1 0 0.785
      roadsWidth 6
      startRoadsLength [
        -0.1
      ]
      startRoadsStartLine [
        ""
        ""
      ]
      startRoadsLine [
        RoadLine {
          type "continuous"
          width 0.3
        }
      ]
      startRoadBorderWidth 0.5
      bottom TRUE
      appearance Asphalt {
        colorOverride 0.5 0.5 0
      }
    }
    RoadIntersection {
      translation 53 0 53
      rotation 0 1 0 0.785
      name "road intersection(1)"
      roadsWidth 6
      startRoadsLength [
        -0.1
      ]
      startRoadsStartLine [
        ""
        ""
      ]
      startRoadsLine [
        RoadLine {
          type "continuous"
          width 0.3
        }
      ]
      startRoadBorderWidth 0.5
      bottom TRUE
      appearance Asphalt {
        colorOverride 0.5 0.5 0
      }
    }
    RoadIntersection {
      translation 53 0 -53
      rotation 0 1 0 0.785
      name "road intersection(2)"
      roadsWidth 6
      startRoadsLength [
        -0.1
      ]
      startRoadsStartLine [
        ""
        ""
      ]
      startRoadsLine [
        RoadLine {
          type "continuous"
          width 0.3
        }
      ]
      startRoadBorderWidth 0.5
      bottom TRUE
      appearance Asphalt {
        colorOverride 0.5 0.5 0
      }
    }
    RoadIntersection {
      translation -53 0 -53
      rotation 0 1 0 0.785
      name "road intersection(3)"
      roadsWidth 6
      startRoadsLength [
        -0.1
      ]
      startRoadsStartLine [
        ""
        ""
      ]
      startRoadsLine [
        RoadLine {
          type "continuous"
          width 0.3
        }
      ]
      startRoadBorderWidth 0.5
      bottom TRUE
      appearance Asphalt {
        colorOverride 0.5 0.5 0
      }
    }
    StraightRoadSegment {
      translation -53 0 20
      name "road(20)"
      width 6
      numberOfForwardLanes 2
      lines [
        RoadLine {
          type "continuous"
          width 0.3
        }
      ]
      rightBarrier TRUE
      leftBarrier TRUE
      bottom TRUE
      length 30
      appearance Asphalt {
        colorOverride 0 0 0
        IBLStrength 0
      }
      pavementAppearance StonePavement {
        colorOverride 0 0 0
      }
    }
    AddLanesRoadSegment {
      translation -53 0 20
      rotation 0 1 0 3.14
      width 6
      length 10
      numberOfNewLanes 1
      newLaneLeft FALSE
      lines [
        RoadLine {
          type "continuous"
          width 0.3
        }
      ]
      rightBarrier TRUE
      leftBarrier TRUE
      bottom TRUE
      appearance Asphalt {
        colorOverride 0 0 0
        IBLStrength 0
      }
      pavementAppearance StonePavement {
        colorOverride 0 0 0
      }
    }
    Solid {
      translation -51.48 0 15.5
      rotation 0 1 0 -0.2617996938995747
      children [
        Shape {
          appearance PBRAppearance {
            roughness 1
            metalness 0
          }
          geometry Box {
            size 0.2 0.01 11.6
          }
        }
      ]
      name "solid(1)"
    }
    StraightRoadSegment {
      translation -51.5 0 -10
      name "road(17)"
      width 9
      numberOfLanes 3
      numberOfForwardLanes 2
      lines [
        RoadLine {
          type "continuous"
          width 0.3
        }
        RoadLine {
          type "continuous"
          width 0.3
        }
      ]
      rightBarrier TRUE
      leftBarrier TRUE
      bottom TRUE
      length 20
      appearance Asphalt {
        colorOverride 0 0 0
        IBLStrength 0
      }
      pavementAppearance StonePavement {
        colorOverride 0 0 0
      }
    }
    AddLanesRoadSegment {
      translation -53 0 -20
      name "road(3)"
      width 6
      length 10
      numberOfNewLanes 1
      lines [
        RoadLine {
          type "continuous"
          width 0.3
        }
      ]
      rightBarrier TRUE
      leftBarrier TRUE
      bottom TRUE
      appearance Asphalt {
        colorOverride 0 0 0
        IBLStrength 0
      }
      pavementAppearance StonePavement {
        colorOverride 0 0 0
      }
    }
    Solid {
      translation -51.48 0 -15.5
      rotation 0 1 0 0.2618
      children [
        Shape {
          appearance PBRAppearance {
            roughness 1
            metalness 0
          }
          geometry Box {
            size 0.2 0.01 11.6
          }
        }
      ]
      name "solid(2)"
    }
    StraightRoadSegment {
      translation -53 0 -50
      name "road(5)"
      width 6
      numberOfForwardLanes 2
      lines [
        RoadLine {
          type "continuous"
          width 0.3
        }
      ]
      rightBarrier TRUE
      leftBarrier TRUE
      bottom TRUE
      length 30
      appearance Asphalt {
        colorOverride 0 0 0
        IBLStrength 0
      }
      pavementAppearance StonePavement {
        colorOverride 0 0 0
      }
    }
    StraightRoadSegment {
      translation -50 0 -53
      rotation 0 1 0 1.57
      name "road(4)"
      width 6
      numberOfForwardLanes 2
      lines [
        RoadLine {
          type "continuous"
          width 0.3
        }
      ]
      rightBarrier TRUE
      leftBarrier TRUE
      bottom TRUE
      length 30
      appearance Asphalt {
        colorOverride 0 0 0
        IBLStrength 0
      }
      pavementAppearance StonePavement {
        colorOverride 0 0 0
      }
    }
    AddLanesRoadSegment {
      translation -10 0 -51.5
      rotation 0 1 0 -1.57
      name "road(2)"
      width 9
      length 10
      numberOfLanes 3
      numberOfNewLanes 1
      lines [
        RoadLine {
          type "continuous"
          width 0.3
        }
        RoadLine {
          type "continuous"
          width -1.73472e-18
        }
      ]
      rightBarrier TRUE
      leftBarrier TRUE
      bottom TRUE
      appearance Asphalt {
        colorOverride 0 0 0
        IBLStrength 0
      }
      pavementAppearance StonePavement {
        colorOverride 0 0 0
      }
    }
    Solid {
      translation 15.5 0 -51.48
      rotation 0 1 0 1.8326
      children [
        Shape {
          appearance PBRAppearance {
            roughness 1
            metalness 0
          }
          geometry Box {
            size 0.2 0.01 11.6
          }
        }
      ]
      name "solid(3)"
    }
    StraightRoadSegment {
      translation -10 0 -51.5
      rotation 0 1 0 1.571
      name "road(18)"
      width 9
      numberOfLanes 3
      numberOfForwardLanes 2
      lines [
        RoadLine {
          type "continuous"
          width 0.3
        }
        RoadLine {
          type "continuous"
          width 0.3
        }
      ]
      rightBarrier TRUE
      leftBarrier TRUE
      bottom TRUE
      length 20
      appearance Asphalt {
        colorOverride 0 0 0
        IBLStrength 0
      }
      pavementAppearance StonePavement {
        colorOverride 0 0 0
      }
    }
    AddLanesRoadSegment {
      translation 10 0 -51.5
      rotation 0 1 0 1.57
      name "road(19)"
      width 9
      length 10
      numberOfLanes 3
      numberOfNewLanes 1
      newLaneLeft FALSE
      lines [
        RoadLine {
          type "continuous"
          width 0.3
        }
        RoadLine {
          type "continuous"
          width -1.73472e-18
        }
      ]
      rightBarrier TRUE
      leftBarrier TRUE
      bottom TRUE
      appearance Asphalt {
        colorOverride 0 0 0
        IBLStrength 0
      }
      pavementAppearance StonePavement {
        colorOverride 0 0 0
      }
    }
    Solid {
      translation -15.5 0 -51.48
      rotation 0 1 0 -1.8326
      children [
        Shape {
          appearance PBRAppearance {
            roughness 1
            metalness 0
          }
          geometry Box {
            size 0.2 0.01 11.6
          }
        }
      ]
      name "solid(4)"
    }
    CurvedRoadSegment {
      translation 20 0 -36.8
      rotation 0 1 0 1.571
      name "road(33)"
      width 5.8
      numberOfForwardLanes 2
      lines [
        RoadLine {
          type "continuous"
          width 0.3
        }
      ]
      roadBorderWidth [
        0
      ]
      rightBarrier TRUE
      leftBarrier TRUE
      bottom TRUE
      totalAngle 3.14
      subdivision 21
      appearance Asphalt {
        colorOverride 0 0 0
        IBLStrength 0
      }
      pavementAppearance StonePavement {
        colorOverride 0 0 0
      }
    }
    StraightRoadSegment {
      translation -20 0 -26.8
      rotation 0 1 0 1.571
      name "road(35)"
      width 5.8
      numberOfForwardLanes 2
      lines [
        RoadLine {
          type "continuous"
          width 0.3
        }
      ]
      rightBarrier TRUE
      leftBarrier TRUE
      bottom TRUE
      length 40
      appearance Asphalt {
        colorOverride 0 0 0
        IBLStrength 0
      }
      pavementAppearance StonePavement {
        colorOverride 0 0 0
      }
    }
    CurvedRoadSegment {
      translation -20 0 -36.8
      rotation 0 1 0 -1.571
      name "road(34)"
      width 5.8
      numberOfForwardLanes 2
      lines [
        RoadLine {
          type "continuous"
          width 0.3
        }
      ]
      roadBorderWidth [
        0
      ]
      rightBarrier TRUE
      leftBarrier TRUE
      bottom TRUE
      totalAngle 3.14
      subdivision 21
      appearance Asphalt {
        colorOverride 0 0 0
        IBLStrength 0
      }
      pavementAppearance StonePavement {
        colorOverride 0 0 0
      }
    }
    StraightRoadSegment {
      translation 20 0 -53
      rotation 0 1 0 1.57
      name "road(21)"
      width 6
      numberOfForwardLanes 2
      lines [
        RoadLine {
          type "continuous"
          width 0.3
        }
      ]
      rightBarrier TRUE
      leftBarrier TRUE
      bottom TRUE
      length 30
      appearance Asphalt {
        colorOverride 0 0 0
        IBLStrength 0
      }
      pavementAppearance StonePavement {
        colorOverride 0 0 0
      }
    }
    StraightRoadSegment {
      translation 53 0 -50
      name "road(22)"
      width 6
      numberOfForwardLanes 2
      lines [
        RoadLine {
          type "continuous"
          width 0.3
        }
      ]
      rightBarrier TRUE
      leftBarrier TRUE
      bottom TRUE
      length 30
      appearance Asphalt {
        colorOverride 0 0 0
        IBLStrength 0
      }
      pavementAppearance StonePavement {
        colorOverride 0 0 0
      }
    }
    AddLanesRoadSegment {
      translation 53 0 -20
      name "road(23)"
      width 6
      length 10
      numberOfNewLanes 1
      newLaneLeft FALSE
      lines [
        RoadLine {
          type "continuous"
          width 0.3
        }
      ]
      rightBarrier TRUE
      leftBarrier TRUE
      bottom TRUE
      appearance Asphalt {
        colorOverride 0 0 0
        IBLStrength 0
      }
      pavementAppearance StonePavement {
        colorOverride 0 0 0
      }
    }
    Solid {
      translation 51.48 0 -15.5
      rotation 0 1 0 -0.2617996938995747
      children [
        Shape {
          appearance PBRAppearance {
            roughness 1
            metalness 0
          }
          geometry Box {
            size 0.2 0.01 11.6
          }
        }
      ]
      name "solid(5)"
    }
    StraightRoadSegment {
      translation 51.5 0 -10
      name "road(24)"
      width 9
      numberOfLanes 3
      numberOfForwardLanes 2
      lines [
        RoadLine {
          type "continuous"
          width 0.3
        }
        RoadLine {
          type "continuous"
          width 0.3
        }
      ]
      rightBarrier TRUE
      leftBarrier TRUE
      bottom TRUE
      length 20
      appearance Asphalt {
        colorOverride 0 0 0
        IBLStrength 0
      }
      pavementAppearance StonePavement {
        colorOverride 0 0 0
      }
    }
    AddLanesRoadSegment {
      translation 53 0 20
      rotation 0 1 0 3.14
      name "road(25)"
      width 6
      length 10
      numberOfNewLanes 1
      lines [
        RoadLine {
          type "continuous"
          width 0.3
        }
      ]
      rightBarrier TRUE
      leftBarrier TRUE
      bottom TRUE
      appearance Asphalt {
        colorOverride 0 0 0
        IBLStrength 0
      }
      pavementAppearance StonePavement {
        colorOverride 0 0 0
      }
    }
    Solid {
      translation 51.48 0 15.5
      rotation 0 1 0 0.2618
      children [
        Shape {
          appearance PBRAppearance {
            roughness 1
            metalness 0
          }
          geometry Box {
            size 0.2 0.01 11.6
          }
        }
      ]
      name "solid(6)"
    }
    StraightRoadSegment {
      translation 53 0 20
      name "road(26)"
      width 6
      numberOfForwardLanes 2
      lines [
        RoadLine {
          type "continuous"
          width 0.3
        }
      ]
      rightBarrier TRUE
      leftBarrier TRUE
      bottom TRUE
      length 30
      appearance Asphalt {
        colorOverride 0 0 0
        IBLStrength 0
      }
      pavementAppearance StonePavement {
        colorOverride 0 0 0
      }
    }
    StraightRoadSegment {
      translation 20 0 53
      rotation 0 1 0 1.57
      name "road(27)"
      width 6
      numberOfForwardLanes 2
      lines [
        RoadLine {
          type "continuous"
          width 0.3
        }
      ]
      rightBarrier TRUE
      leftBarrier TRUE
      bottom TRUE
      length 30
      appearance Asphalt {
        colorOverride 0 0 0
        IBLStrength 0
      }
      pavementAppearance StonePavement {
        colorOverride 0 0 0
      }
    }
    AddLanesRoadSegment {
      translation 20 0 53
      rotation 0 1 0 -1.57
      name "road(28)"
      width 6
      length 10
      numberOfNewLanes 1
      newLaneLeft FALSE
      lines [
        RoadLine {
          type "continuous"
          width 0.3
        }
      ]
      rightBarrier TRUE
      leftBarrier TRUE
      bottom TRUE
      appearance Asphalt {
        colorOverride 0 0 0
        IBLStrength 0
      }
      pavementAppearance StonePavement {
        colorOverride 0 0 0
      }
    }
    Solid {
      translation 15.5 0 51.48
      rotation 0 1 0 -1.8326
      children [
        Shape {
          appearance PBRAppearance {
            roughness 1
            metalness 0
          }
          geometry Box {
            size 0.2 0.01 11.6
          }
        }
      ]
      name "solid(7)"
    }
    StraightRoadSegment {
      translation -10 0 51.5
      rotation 0 1 0 1.57
      name "road(29)"
      width 9
      numberOfLanes 3
      numberOfForwardLanes 2
      lines [
        RoadLine {
          type "continuous"
          width 0.3
        }
        RoadLine {
          type "continuous"
          width 0.3
        }
      ]
      rightBarrier TRUE
      leftBarrier TRUE
      bottom TRUE
      length 20
      appearance Asphalt {
        colorOverride 0 0 0
        IBLStrength 0
      }
      pavementAppearance StonePavement {
        colorOverride 0 0 0
      }
    }
    AddLanesRoadSegment {
      translation -20 0 53
      rotation 0 1 0 1.57
      name "road(30)"
      width 6
      length 10
      numberOfNewLanes 1
      lines [
        RoadLine {
          type "continuous"
          width 0.3
        }
      ]
      rightBarrier TRUE
      leftBarrier TRUE
      bottom TRUE
      appearance Asphalt {
        colorOverride 0 0 0
        IBLStrength 0
      }
      pavementAppearance StonePavement {
        colorOverride 0 0 0
      }
    }
    Solid {
      translation -15.5 0 51.48
      rotation 0 1 0 1.8326
      children [
        Shape {
          appearance PBRAppearance {
            roughness 1
            metalness 0
          }
          geometry Box {
            size 0.2 0.01 11.6
          }
        }
      ]
      name "solid(8)"
    }
    StraightRoadSegment {
      translation -50 0 53
      rotation 0 1 0 1.57
      name "road(32)"
      width 6
      numberOfForwardLanes 2
      lines [
        RoadLine {
          type "continuous"
          width 0.3
        }
      ]
      rightBarrier TRUE
      leftBarrier TRUE
      bottom TRUE
      length 30
      appearance Asphalt {
        colorOverride 0 0 0
        IBLStrength 0
      }
      pavementAppearance StonePavement {
        colorOverride 0 0 0
      }
    }
    StraightRoadSegment {
      translation 53 0 20
      name "road(31)"
      width 6
      numberOfForwardLanes 2
      lines [
        RoadLine {
          type "continuous"
          width 0.3
        }
      ]
      rightBarrier TRUE
      leftBarrier TRUE
      bottom TRUE
      length 30
      appearance Asphalt {
        colorOverride 0 0 0
        IBLStrength 0
      }
      pavementAppearance StonePavement {
        colorOverride 0 0 0
      }
    }
    StraightRoadSegment {
      translation -76 0 -33
      name "road(6)"
      width 6
      numberOfForwardLanes 2
      lines [
        RoadLine {
          type "continuous"
          width 0.3
        }
      ]
      rightBarrier TRUE
      leftBarrier TRUE
      bottom TRUE
      length 66
      appearance Asphalt {
        colorOverride 0 0 0
        IBLStrength 0
      }
      pavementAppearance StonePavement {
        colorOverride 0 0 0
      }
    }
    StraightRoadSegment {
      translation -33 0 -76
      rotation 0 1 0 1.57
      name "road(14)"
      width 6
      numberOfForwardLanes 2
      lines [
        RoadLine {
          type "continuous"
          width 0.3
        }
      ]
      rightBarrier TRUE
      leftBarrier TRUE
      bottom TRUE
      length 66
      appearance Asphalt {
        colorOverride 0 0 0
        IBLStrength 0
      }
      pavementAppearance StonePavement {
        colorOverride 0 0 0
      }
    }
    StraightRoadSegment {
      translation 76 0 -33
      name "road(15)"
      width 6
      numberOfForwardLanes 2
      lines [
        RoadLine {
          type "continuous"
          width 0.3
        }
      ]
      rightBarrier TRUE
      leftBarrier TRUE
      bottom TRUE
      length 66
      appearance Asphalt {
        colorOverride 0 0 0
        IBLStrength 0
      }
      pavementAppearance StonePavement {
        colorOverride 0 0 0
      }
    }
    StraightRoadSegment {
      translation -33 0 76
      rotation 0 1 0 1.57
      name "road(16)"
      width 6
      numberOfForwardLanes 2
      lines [
        RoadLine {
          type "continuous"
          width 0.3
        }
      ]
      rightBarrier TRUE
      leftBarrier TRUE
      bottom TRUE
      length 66
      appearance Asphalt {
        colorOverride 0 0 0
        IBLStrength 0
      }
      pavementAppearance StonePavement {
        colorOverride 0 0 0
      }
    }
    Solid {
      translation -15 0 -48.41
      rotation 0 1 0 -1.26
      children [
        Shape {
          appearance PBRAppearance {
            roughness 1
            metalness 0
          }
          geometry Box {
            size 0.2 0.01 10.67
          }
        }
      ]
      name "solid(9)"
    }
    Solid {
      translation 15 0 -48.39
      rotation 0 1 0 -1.88
      children [
        Shape {
          appearance PBRAppearance {
            roughness 1
            metalness 0
          }
          geometry Box {
            size 0.2 0.01 10.67
          }
        }
      ]
      name "solid(10)"
    }
  ]
  name "environment"
}
Floor {
  size 176 176
  tileSize 0.1 0.1
  appearance PBRAppearance {
    baseColor 0.5 0.5 0.5
    transparency 0.9
    metalness 0
  }
}
