#VRML_SIM R2020a utf8
WorldInfo {
  basicTimeStep 16
}
Viewpoint {
  orientation -0.25522375675898396 -0.945628158279386 -0.2016140378420294 1.7005914001226077
  position -77.68362742832142 41.555410315775234 -56.47243834069372
}
TexturedBackground {
  luminosity 2
  reflections FALSE
}
DEF Cab1 Robot {
  translation -0.00011293395806233656 0.3986624227930272 -29.20000497279791
  rotation -0.00013508642821858245 0.9999999800245127 -0.00014731812974774455 -1.5723853289573195
  children [
    DEF cam_f Camera {
      translation 0 0.1 1
      rotation 0 1 0 3.14
      children [
        Shape {
          appearance PBRAppearance {
            baseColor 0.4 0 0
          }
          geometry Cylinder {
            height 0.1
            radius 0.05
          }
        }
      ]
      boundingObject Cylinder {
        height 0.1
        radius 0.05
      }
      physics Physics {
        density 1
      }
      fieldOfView 0.75
      width 18
      height 10
      far 10
    }
    DEF ls_f LightSensor {
      translation 0 0 1
      rotation 0 1 0 -1.57
      children [
        Shape {
          appearance PBRAppearance {
            baseColor 0 0 0
            metalness 0
          }
          geometry Box {
            size 0.1 0.1 0.1
          }
        }
      ]
      name "ls_front"
      boundingObject Shape {
        appearance PBRAppearance {
        }
        geometry Cylinder {
          height 0.1
          radius 0.05
        }
      }
      physics Physics {
        density 1
      }
      lookupTable [
        0 0 0
        5 1000 0
      ]
    }
    DEF ds_fl DistanceSensor {
      translation 0.45 0.2 1
      rotation 0 1 0 -1.047
      children [
        Shape {
          appearance PBRAppearance {
          }
          geometry Box {
            size 0.1 0.1 0.1
          }
        }
      ]
      name "ds_fl"
      boundingObject Shape {
        appearance PBRAppearance {
        }
        geometry Box {
          size 0.1 0.1 0.1
        }
      }
      physics Physics {
        density 1
      }
      lookupTable [
        0 0 0
        5 1000 0
      ]
    }
    DEF ds_lf DistanceSensor {
      translation 0.5 0.2 0.95
      children [
        Shape {
          appearance PBRAppearance {
          }
          geometry Box {
            size 0.1 0.1 0.1
          }
        }
      ]
      name "ds_lf"
      boundingObject Shape {
        appearance PBRAppearance {
        }
        geometry Box {
          size 0.1 0.1 0.1
        }
      }
      physics Physics {
        density 1
      }
      lookupTable [
        0 0 0
        5 1000 0
      ]
    }
    DEF ds_lc DistanceSensor {
      translation 0.5 0.2 0
      children [
        Shape {
          appearance PBRAppearance {
          }
          geometry Box {
            size 0.1 0.1 0.1
          }
        }
      ]
      name "ds_lc"
      boundingObject Shape {
        appearance PBRAppearance {
        }
        geometry Box {
          size 0.1 0.1 0.1
        }
      }
      physics Physics {
        density 1
      }
      lookupTable [
        0 0 0
        5 1000 0
      ]
    }
    DEF ds_fr DistanceSensor {
      translation -0.45 0.2 1
      rotation 0 1 0 -2.09
      children [
        Shape {
          appearance PBRAppearance {
          }
          geometry Box {
            size 0.1 0.1 0.1
          }
        }
      ]
      name "ds_fr"
      boundingObject Shape {
        appearance PBRAppearance {
        }
        geometry Box {
          size 0.1 0.1 0.1
        }
      }
      physics Physics {
        density 1
      }
      lookupTable [
        0 0 0
        5 1000 0
      ]
    }
    DEF ds_rf DistanceSensor {
      translation -0.5 0.2 0.95
      rotation 0 1 0 -3.14
      children [
        Shape {
          appearance PBRAppearance {
          }
          geometry Box {
            size 0.1 0.1 0.1
          }
        }
      ]
      name "ds_rf"
      boundingObject Shape {
        appearance PBRAppearance {
        }
        geometry Box {
          size 0.1 0.1 0.1
        }
      }
      physics Physics {
        density 1
      }
      lookupTable [
        0 0 0
        5 1000 0
      ]
    }
    DEF ds_rc DistanceSensor {
      translation -0.5 0.2 0
      rotation 0 1 0 -3.14
      children [
        Shape {
          appearance PBRAppearance {
          }
          geometry Box {
            size 0.1 0.1 0.1
          }
        }
      ]
      name "ds_rc"
      boundingObject Shape {
        appearance PBRAppearance {
        }
        geometry Box {
          size 0.1 0.1 0.1
        }
      }
      physics Physics {
        density 1
      }
      lookupTable [
        0 0 0
        5 1000 0
      ]
    }
    DEF ds_fc DistanceSensor {
      translation 0 0.2 1
      rotation 0 1 0 -1.57
      children [
        Shape {
          appearance PBRAppearance {
          }
          geometry Box {
            size 0.1 0.1 0.1
          }
        }
      ]
      name "ds_fc"
      boundingObject Shape {
        appearance PBRAppearance {
        }
        geometry Box {
          size 0.1 0.1 0.1
        }
      }
      physics Physics {
        density 1
      }
      lookupTable [
        0 0 0
        5 1000 0
      ]
    }
    DEF ds_fcr DistanceSensor {
      translation -0.225 0.2 1
      rotation 0 1 0 -1.833
      children [
        Shape {
          appearance PBRAppearance {
          }
          geometry Box {
            size 0.1 0.1 0.1
          }
        }
      ]
      name "ds_fcr"
      boundingObject Shape {
        appearance PBRAppearance {
        }
        geometry Box {
          size 0.1 0.1 0.1
        }
      }
      physics Physics {
        density 1
      }
      lookupTable [
        0 0 0
        5 1000 0
      ]
    }
    DEF ds_fcl DistanceSensor {
      translation 0.225 0.2 1
      rotation 0 1 0 -1.309
      children [
        Shape {
          appearance PBRAppearance {
          }
          geometry Box {
            size 0.1 0.1 0.1
          }
        }
      ]
      name "ds_fcl"
      boundingObject Shape {
        appearance PBRAppearance {
        }
        geometry Box {
          size 0.1 0.1 0.1
        }
      }
      physics Physics {
        density 1
      }
      lookupTable [
        0 0 0
        5 1000 0
      ]
    }
    Transform {
      translation 0 0.5 -0.3
      rotation 1 0 0 0
      children [
        Shape {
          appearance PBRAppearance {
            baseColor 0.5 0.5 0.5
            transparency 0.3
          }
          geometry Box {
            size 0.9 0.5 1.2
          }
        }
      ]
    }
    Transform {
      translation 0 0.8 -0.3
      rotation 1 0 0 0
      children [
        Shape {
          appearance PBRAppearance {
            baseColor 0 0 0
          }
          geometry Box {
            size 1 0.1 1.3
          }
        }
      ]
    }
    DEF wheelFL HingeJoint {
      jointParameters HingeJointParameters {
        position -3.240091306366821e-08
        anchor 0.55 -0.1 0.55
      }
      device [
        DEF wheelFL RotationalMotor {
          name "wheelFL"
          maxTorque 30
        }
      ]
      endPoint DEF wheelFL Solid {
        translation 0.55 -0.1 0.55
        rotation -1.621336252883765e-08 1.6200456531834106e-08 0.9999999999999998 1.5699999999999965
        children [
          DEF wheel Shape {
            appearance PBRAppearance {
              baseColor 0 0 0
              metalness 0
            }
            geometry Cylinder {
              height 0.1
              radius 0.3
            }
          }
        ]
        name "wheelFL"
        boundingObject USE wheel
        physics DEF physics_wheel Physics {
          density 10
        }
        linearVelocity 8.592462848472011e-08 -7.724011592131225e-09 8.698458707694555e-09
        angularVelocity 4.7428182032237774e-09 3.881234661919527e-08 -3.1115480325224793e-07
      }
    }
    DEF wheelRL HingeJoint {
      jointParameters HingeJointParameters {
        position -3.408176559029863e-08
        anchor 0.55 -0.1 -0.7
      }
      device [
        DEF wheelRL RotationalMotor {
          name "wheelRL"
          maxTorque 30
        }
      ]
      endPoint DEF wheelRL Solid {
        translation 0.55 -0.1 -0.7
        rotation -1.705445831271944e-08 1.7040882795149316e-08 0.9999999999999998 1.5699999999999965
        children [
          DEF wheel Shape {
            appearance PBRAppearance {
              baseColor 0 0 0
              metalness 0
            }
            geometry Cylinder {
              height 0.1
              radius 0.3
            }
          }
        ]
        name "wheelRL"
        boundingObject USE wheel
        physics DEF physics_wheel Physics {
          density 10
        }
        linearVelocity 8.903901833614285e-08 3.693310682671784e-09 -8.444782191763376e-09
        angularVelocity -4.724113636150919e-09 3.881149937051543e-08 -3.2632188951679677e-07
      }
    }
    DEF wheelRR HingeJoint {
      jointParameters HingeJointParameters {
        position -3.401022451468173e-08
        anchor -0.55 -0.1 -0.7
      }
      device [
        DEF wheelRR RotationalMotor {
          name "wheelRR"
          maxTorque 30
        }
      ]
      endPoint DEF wheelRR Solid {
        translation -0.55 -0.1 -0.7
        rotation -1.701865927852554e-08 1.7005112257340867e-08 0.9999999999999998 1.5699999999999965
        children [
          DEF wheel Shape {
            appearance PBRAppearance {
              baseColor 0 0 0
              metalness 0
            }
            geometry Cylinder {
              height 0.1
              radius 0.3
            }
          }
        ]
        name "wheelRR"
        boundingObject USE wheel
        physics DEF physics_wheel Physics {
          density 10
        }
        linearVelocity 7.399475548510099e-08 3.0581166011862224e-09 -8.468511490588709e-09
        angularVelocity -4.737069123971858e-09 3.880493688540923e-08 -3.1819678145635674e-07
      }
    }
    DEF wheelFR HingeJoint {
      jointParameters HingeJointParameters {
        position 3.240188809500961e-08
        anchor -0.55 -0.1 0.5
      }
      device [
        DEF wheelFR RotationalMotor {
          name "wheelFR"
          maxTorque 30
        }
      ]
      endPoint DEF wheelFR Solid {
        translation -0.55 -0.1 0.5
        rotation 1.621385043288481e-08 -1.6200944047504807e-08 0.9999999999999998 1.5699999999999958
        children [
          DEF wheel Shape {
            appearance PBRAppearance {
              baseColor 0 0 0
              metalness 0
            }
            geometry Cylinder {
              height 0.1
              radius 0.3
            }
          }
        ]
        name "wheelFR"
        boundingObject USE wheel
        physics DEF physics_wheel Physics {
          density 10
        }
        linearVelocity -5.6102033245032545e-08 -7.902510766244482e-09 7.787032451916354e-09
        angularVelocity 3.3735072828583852e-09 3.8840650956154506e-08 3.1164578413963716e-07
      }
    }
    DEF car_body Shape {
      appearance PBRAppearance {
        baseColor 1 1 0
      }
      geometry Box {
        size 1 0.6 2
      }
    }
  ]
  name "Cab1"
  boundingObject USE car_body
  physics Physics {
    density 10
  }
  recognitionColors [
    0 0 0
  ]
  controller "controller"
  linearVelocity 4.7081418295365554e-08 -3.0208661943260346e-09 3.263193147046892e-09
  angularVelocity -6.030967720986736e-10 3.903448981619071e-08 9.30454896430067e-09
}
DEF Cab2 Robot {
  translation -24.656400010483402 0.3986624226176735 -50.65609999283062
  rotation 0.00011652811149498896 0.9999999838780597 -0.00013662020233923334 1.8141852899199162
  children [
    DEF cam_f Camera {
      translation 0 0.1 1
      rotation 0 1 0 3.14
      children [
        Shape {
          appearance PBRAppearance {
            baseColor 0.4 0 0
          }
          geometry Cylinder {
            height 0.1
            radius 0.05
          }
        }
      ]
      boundingObject Cylinder {
        height 0.1
        radius 0.05
      }
      physics Physics {
        density 1
      }
      fieldOfView 0.75
      width 18
      height 10
      far 10
    }
    DEF ls_f LightSensor {
      translation 0 0 1
      rotation 0 1 0 -1.57
      children [
        Shape {
          appearance PBRAppearance {
            baseColor 0 0 0
            metalness 0
          }
          geometry Box {
            size 0.1 0.1 0.1
          }
        }
      ]
      name "ls_front"
      boundingObject Shape {
        appearance PBRAppearance {
        }
        geometry Cylinder {
          height 0.1
          radius 0.05
        }
      }
      physics Physics {
        density 1
      }
      lookupTable [
        0 0 0
        5 1000 0
      ]
    }
    DEF ds_fl DistanceSensor {
      translation 0.45 0.2 1
      rotation 0 1 0 -1.047
      children [
        Shape {
          appearance PBRAppearance {
          }
          geometry Box {
            size 0.1 0.1 0.1
          }
        }
      ]
      name "ds_fl"
      boundingObject Shape {
        appearance PBRAppearance {
        }
        geometry Box {
          size 0.1 0.1 0.1
        }
      }
      physics Physics {
        density 1
      }
      lookupTable [
        0 0 0
        5 1000 0
      ]
    }
    DEF ds_lf DistanceSensor {
      translation 0.5 0.2 0.95
      children [
        Shape {
          appearance PBRAppearance {
          }
          geometry Box {
            size 0.1 0.1 0.1
          }
        }
      ]
      name "ds_lf"
      boundingObject Shape {
        appearance PBRAppearance {
        }
        geometry Box {
          size 0.1 0.1 0.1
        }
      }
      physics Physics {
        density 1
      }
      lookupTable [
        0 0 0
        5 1000 0
      ]
    }
    DEF ds_lc DistanceSensor {
      translation 0.5 0.2 0
      children [
        Shape {
          appearance PBRAppearance {
          }
          geometry Box {
            size 0.1 0.1 0.1
          }
        }
      ]
      name "ds_lc"
      boundingObject Shape {
        appearance PBRAppearance {
        }
        geometry Box {
          size 0.1 0.1 0.1
        }
      }
      physics Physics {
        density 1
      }
      lookupTable [
        0 0 0
        5 1000 0
      ]
    }
    DEF ds_fr DistanceSensor {
      translation -0.45 0.2 1
      rotation 0 1 0 -2.09
      children [
        Shape {
          appearance PBRAppearance {
          }
          geometry Box {
            size 0.1 0.1 0.1
          }
        }
      ]
      name "ds_fr"
      boundingObject Shape {
        appearance PBRAppearance {
        }
        geometry Box {
          size 0.1 0.1 0.1
        }
      }
      physics Physics {
        density 1
      }
      lookupTable [
        0 0 0
        5 1000 0
      ]
    }
    DEF ds_rf DistanceSensor {
      translation -0.5 0.2 0.95
      rotation 0 1 0 -3.14
      children [
        Shape {
          appearance PBRAppearance {
          }
          geometry Box {
            size 0.1 0.1 0.1
          }
        }
      ]
      name "ds_rf"
      boundingObject Shape {
        appearance PBRAppearance {
        }
        geometry Box {
          size 0.1 0.1 0.1
        }
      }
      physics Physics {
        density 1
      }
      lookupTable [
        0 0 0
        5 1000 0
      ]
    }
    DEF ds_rc DistanceSensor {
      translation -0.5 0.2 0
      rotation 0 1 0 -3.14
      children [
        Shape {
          appearance PBRAppearance {
          }
          geometry Box {
            size 0.1 0.1 0.1
          }
        }
      ]
      name "ds_rc"
      boundingObject Shape {
        appearance PBRAppearance {
        }
        geometry Box {
          size 0.1 0.1 0.1
        }
      }
      physics Physics {
        density 1
      }
      lookupTable [
        0 0 0
        5 1000 0
      ]
    }
    DEF ds_fc DistanceSensor {
      translation 0 0.2 1
      rotation 0 1 0 -1.57
      children [
        Shape {
          appearance PBRAppearance {
          }
          geometry Box {
            size 0.1 0.1 0.1
          }
        }
      ]
      name "ds_fc"
      boundingObject Shape {
        appearance PBRAppearance {
        }
        geometry Box {
          size 0.1 0.1 0.1
        }
      }
      physics Physics {
        density 1
      }
      lookupTable [
        0 0 0
        5 1000 0
      ]
    }
    DEF ds_fcr DistanceSensor {
      translation -0.225 0.2 1
      rotation 0 1 0 -1.833
      children [
        Shape {
          appearance PBRAppearance {
          }
          geometry Box {
            size 0.1 0.1 0.1
          }
        }
      ]
      name "ds_fcr"
      boundingObject Shape {
        appearance PBRAppearance {
        }
        geometry Box {
          size 0.1 0.1 0.1
        }
      }
      physics Physics {
        density 1
      }
      lookupTable [
        0 0 0
        5 1000 0
      ]
    }
    DEF ds_fcl DistanceSensor {
      translation 0.225 0.2 1
      rotation 0 1 0 -1.309
      children [
        Shape {
          appearance PBRAppearance {
          }
          geometry Box {
            size 0.1 0.1 0.1
          }
        }
      ]
      name "ds_fcl"
      boundingObject Shape {
        appearance PBRAppearance {
        }
        geometry Box {
          size 0.1 0.1 0.1
        }
      }
      physics Physics {
        density 1
      }
      lookupTable [
        0 0 0
        5 1000 0
      ]
    }
    Transform {
      translation 0 0.5 -0.3
      rotation 1 0 0 0
      children [
        Shape {
          appearance PBRAppearance {
            baseColor 0.5 0.5 0.5
            transparency 0.3
          }
          geometry Box {
            size 0.9 0.5 1.2
          }
        }
      ]
    }
    Transform {
      translation 0 0.8 -0.3
      rotation 1 0 0 0
      children [
        Shape {
          appearance PBRAppearance {
            baseColor 0 0 0
          }
          geometry Box {
            size 1 0.1 1.3
          }
        }
      ]
    }
    DEF wheelFL HingeJoint {
      jointParameters HingeJointParameters {
        position -2.3869472655871804e-10
        anchor 0.55 -0.1 0.55
      }
      device [
        DEF wheelFL RotationalMotor {
          name "wheelFL"
          maxTorque 30
        }
      ]
      endPoint DEF wheelFL Solid {
        translation 0.55 -0.1 0.55
        rotation 3.933069916676079e-09 -3.9299391534917915e-09 1 1.5699999999999947
        children [
          DEF wheel Shape {
            appearance PBRAppearance {
              baseColor 0 0 0
              metalness 0
            }
            geometry Cylinder {
              height 0.1
              radius 0.3
            }
          }
        ]
        name "wheelFL"
        boundingObject USE wheel
        physics DEF physics_wheel Physics {
          density 10
        }
        linearVelocity 2.5249747250539058e-09 2.6942892416420922e-09 -9.672649106287369e-09
        angularVelocity -3.7264789021948545e-09 2.0595871018132232e-08 2.6717264714844584e-10
      }
    }
    DEF wheelRL HingeJoint {
      jointParameters HingeJointParameters {
        position -1.0478255103639638e-09
        anchor 0.55 -0.1 -0.7
      }
      device [
        DEF wheelRL RotationalMotor {
          name "wheelRL"
          maxTorque 30
        }
      ]
      endPoint DEF wheelRL Solid {
        translation 0.55 -0.1 -0.7
        rotation -3.096866753994822e-09 3.09440161741357e-09 1 1.5699999999999972
        children [
          DEF wheel Shape {
            appearance PBRAppearance {
              baseColor 0 0 0
              metalness 0
            }
            geometry Cylinder {
              height 0.1
              radius 0.3
            }
          }
        ]
        name "wheelRL"
        boundingObject USE wheel
        physics DEF physics_wheel Physics {
          density 10
        }
        linearVelocity 4.2850525864516495e-09 -3.364260002212386e-09 -2.0026942599760744e-09
        angularVelocity 2.915866561144496e-11 2.0595916174199817e-08 -7.067040933785123e-09
      }
    }
    DEF wheelRR HingeJoint {
      jointParameters HingeJointParameters {
        position -4.4590168737499336e-10
        anchor -0.55 -0.1 -0.7
      }
      device [
        DEF wheelRR RotationalMotor {
          name "wheelRR"
          maxTorque 30
        }
      ]
      endPoint DEF wheelRR Solid {
        translation -0.55 -0.1 -0.7
        rotation -2.2312845614645093e-10 2.2295084384088244e-10 1 1.5699999999999952
        children [
          DEF wheel Shape {
            appearance PBRAppearance {
              baseColor 0 0 0
              metalness 0
            }
            geometry Cylinder {
              height 0.1
              radius 0.3
            }
          }
        ]
        name "wheelRR"
        boundingObject USE wheel
        physics DEF physics_wheel Physics {
          density 10
        }
        linearVelocity 1.1788186247465264e-08 -1.0427823560070269e-09 4.623564603228756e-09
        angularVelocity -2.246224771883109e-09 2.0591974901286448e-08 -5.90246104086579e-09
      }
    }
    DEF wheelFR HingeJoint {
      jointParameters HingeJointParameters {
        position 3.0668328734164383e-08
        anchor -0.55 -0.1 0.5
      }
      device [
        DEF wheelFR RotationalMotor {
          name "wheelFR"
          maxTorque 30
        }
      ]
      endPoint DEF wheelFR Solid {
        translation -0.55 -0.1 0.5
        rotation 1.2307679727050327e-08 -1.2297882692204156e-08 0.9999999999999999 1.5699999999999952
        children [
          DEF wheel Shape {
            appearance PBRAppearance {
              baseColor 0 0 0
              metalness 0
            }
            geometry Cylinder {
              height 0.1
              radius 0.3
            }
          }
        ]
        name "wheelFR"
        boundingObject USE wheel
        physics DEF physics_wheel Physics {
          density 10
        }
        linearVelocity 8.226077137675795e-08 4.773422704555048e-09 -2.0657801463387623e-08
        angularVelocity -8.662416840191546e-08 2.061210823523114e-08 -3.24148183646526e-07
      }
    }
    DEF car_body Shape {
      appearance PBRAppearance {
        baseColor 1 1 0
      }
      geometry Box {
        size 1 0.6 2
      }
    }
  ]
  name "Cab2"
  boundingObject USE car_body
  physics Physics {
    density 10
  }
  recognitionColors [
    0 0 0
  ]
  controller "controller"
  linearVelocity 2.4160442202669307e-08 9.595387618321042e-10 -8.757433317864561e-09
  angularVelocity -9.097421385972988e-10 2.0717957704895548e-08 5.264398601433912e-09
}
DEF environment Solid {
  scale 1.09819 1.09819 1.09819
  children [
    DEF PickUp1 BusStop {
      translation 0 0 -45
      rotation 0 1 0 3.14159
      name "PickUp1"
      bench FALSE
      appearance PBRAppearance {
        baseColor 0 0 0
        roughness 0.5
        metalness 0
      }
      internalAdvertisingTexture []
      externalAdvertisingTexture []
    }
    DEF PickUp2 BusStop {
      translation 45 0 0
      rotation 0 -1 0 -1.5707953071795862
      name "PickUp2"
      bench FALSE
      appearance PBRAppearance {
        baseColor 1 0 0
        roughness 0.5
        metalness 0
      }
      internalAdvertisingTexture []
      externalAdvertisingTexture []
      advertisingLightOn FALSE
    }
    DEF PickUp3 BusStop {
      translation 0 0 45
      rotation 0 1 0 -5.307179586466759e-06
      name "PickUp3"
      bench FALSE
      appearance PBRAppearance {
        baseColor 0 1 0
        roughness 0.5
        metalness 0
      }
      internalAdvertisingTexture []
      externalAdvertisingTexture []
      advertisingLightOn FALSE
    }
    DEF PickUp4 BusStop {
      translation -45 0 0
      rotation 0 1 0 -1.5707953071795862
      name "PickUp4"
      bench FALSE
      appearance PBRAppearance {
        baseColor 0 0 1
        roughness 0.5
        metalness 0
      }
      internalAdvertisingTexture []
      externalAdvertisingTexture []
      advertisingLightOn FALSE
    }
    DEF PickUp5 BusStop {
      translation 0 0 -71
      rotation 0 1 0 3.14159
      name "PickUp5"
      bench FALSE
      appearance PBRAppearance {
        baseColor 1 1 0
        roughness 0.5
        metalness 0
      }
      internalAdvertisingTexture []
      externalAdvertisingTexture []
      advertisingLightOn FALSE
    }
    DEF PickUp6 BusStop {
      translation 71 0 0
      rotation 0 -1 0 -1.5707953071795862
      name "PickUp6"
      bench FALSE
      appearance PBRAppearance {
        baseColor 1 0 1
        roughness 0.5
        metalness 0
      }
      internalAdvertisingTexture []
      externalAdvertisingTexture []
      advertisingLightOn FALSE
    }
    DEF PickUp7 BusStop {
      translation 0 0 71
      rotation 0 1 0 -5.307179586466759e-06
      name "PickUp7"
      bench FALSE
      appearance PBRAppearance {
        baseColor 0 1 1
        roughness 0.5
        metalness 0
      }
      internalAdvertisingTexture []
      externalAdvertisingTexture []
      advertisingLightOn FALSE
    }
    DEF PickUp8 BusStop {
      translation -71 0 0
      rotation 0 1 0 -1.5707953071795862
      name "PickUp8"
      bench FALSE
      appearance PBRAppearance {
        roughness 0.5
        metalness 0
      }
      internalAdvertisingTexture []
      externalAdvertisingTexture []
      advertisingLightOn FALSE
    }
    CurvedRoadSegment {
      translation -56 0 33
      rotation 0 1 0 -1.570796
      name "road(1)"
      width 6
      numberOfForwardLanes 2
      lines [
        RoadLine {
          type "continuous"
          width 0.3
        }
      ]
      rightBarrier TRUE
      leftBarrier TRUE
      bottom TRUE
      curvatureRadius 20
      appearance Asphalt {
        colorOverride 0 0 0
        IBLStrength 0
      }
      pavementAppearance StonePavement {
        colorOverride 0 0 0
      }
    }
    CurvedRoadSegment {
      translation -56 0 -33
      rotation 0 1 0 3.14
      name "road(7)"
      width 6
      numberOfForwardLanes 2
      lines [
        RoadLine {
          type "continuous"
          width 0.3
        }
      ]
      rightBarrier TRUE
      leftBarrier TRUE
      bottom TRUE
      curvatureRadius 20
      appearance Asphalt {
        colorOverride 0 0 0
        IBLStrength 0
      }
      pavementAppearance StonePavement {
        colorOverride 0 0 0
      }
    }
    CurvedRoadSegment {
      translation -33 0 -56
      rotation 0 1 0 3.14
      name "road(8)"
      width 6
      numberOfForwardLanes 2
      lines [
        RoadLine {
          type "continuous"
          width 0.3
        }
      ]
      rightBarrier TRUE
      leftBarrier TRUE
      bottom TRUE
      curvatureRadius 20
      appearance Asphalt {
        colorOverride 0 0 0
        IBLStrength 0
      }
      pavementAppearance StonePavement {
        colorOverride 0 0 0
      }
    }
    CurvedRoadSegment {
      translation 33 0 -56
      rotation 0 1 0 1.57
      name "road(9)"
      width 6
      numberOfForwardLanes 2
      lines [
        RoadLine {
          type "continuous"
          width 0.3
        }
      ]
      rightBarrier TRUE
      leftBarrier TRUE
      bottom TRUE
      curvatureRadius 20
      appearance Asphalt {
        colorOverride 0 0 0
        IBLStrength 0
      }
      pavementAppearance StonePavement {
        colorOverride 0 0 0
      }
    }
    CurvedRoadSegment {
      translation 56 0 -33
      rotation 0 1 0 1.57
      name "road(10)"
      width 6
      numberOfForwardLanes 2
      lines [
        RoadLine {
          type "continuous"
          width 0.3
        }
      ]
      rightBarrier TRUE
      leftBarrier TRUE
      bottom TRUE
      curvatureRadius 20
      appearance Asphalt {
        colorOverride 0 0 0
        IBLStrength 0
      }
      pavementAppearance StonePavement {
        colorOverride 0 0 0
      }
    }
    CurvedRoadSegment {
      translation 56 0 33
      name "road(11)"
      width 6
      numberOfForwardLanes 2
      lines [
        RoadLine {
          type "continuous"
          width 0.3
        }
      ]
      rightBarrier TRUE
      leftBarrier TRUE
      bottom TRUE
      curvatureRadius 20
      appearance Asphalt {
        colorOverride 0 0 0
        IBLStrength 0
      }
      pavementAppearance StonePavement {
        colorOverride 0 0 0
      }
    }
    CurvedRoadSegment {
      translation 33 0 56
      name "road(12)"
      width 6
      numberOfForwardLanes 2
      lines [
        RoadLine {
          type "continuous"
          width 0.3
        }
      ]
      rightBarrier TRUE
      leftBarrier TRUE
      bottom TRUE
      curvatureRadius 20
      appearance Asphalt {
        colorOverride 0 0 0
        IBLStrength 0
      }
      pavementAppearance StonePavement {
        colorOverride 0 0 0
      }
    }
    CurvedRoadSegment {
      translation -33 0 56
      rotation 0 1 0 -1.57
      name "road(13)"
      width 6
      numberOfForwardLanes 2
      lines [
        RoadLine {
          type "continuous"
          width 0.3
        }
      ]
      rightBarrier TRUE
      leftBarrier TRUE
      bottom TRUE
      curvatureRadius 20
      appearance Asphalt {
        colorOverride 0 0 0
        IBLStrength 0
      }
      pavementAppearance StonePavement {
        colorOverride 0 0 0
      }
    }
    RoadIntersection {
      translation -53 0 53
      rotation 0 1 0 0.785
      roadsWidth 6
      startRoadsLength [
        -0.1
      ]
      startRoadsStartLine [
        ""
        ""
      ]
      startRoadsLine [
        RoadLine {
          type "continuous"
          width 0.3
        }
      ]
      startRoadBorderWidth 0.5
      bottom TRUE
      appearance Asphalt {
        colorOverride 0 1 0.5
      }
    }
    RoadIntersection {
      translation 53 0 53
      rotation 0 1 0 0.785
      name "road intersection(1)"
      roadsWidth 6
      startRoadsLength [
        -0.1
      ]
      startRoadsStartLine [
        ""
        ""
      ]
      startRoadsLine [
        RoadLine {
          type "continuous"
          width 0.3
        }
      ]
      startRoadBorderWidth 0.5
      bottom TRUE
      appearance Asphalt {
        colorOverride 1 0 0.5
      }
    }
    RoadIntersection {
      translation 53 0 -53
      rotation 0 1 0 0.785
      name "road intersection(2)"
      roadsWidth 6
      startRoadsLength [
        -0.1
      ]
      startRoadsStartLine [
        ""
        ""
      ]
      startRoadsLine [
        RoadLine {
          type "continuous"
          width 0.3
        }
      ]
      startRoadBorderWidth 0.5
      bottom TRUE
      appearance Asphalt {
        colorOverride 0.5 0.5 0
      }
    }
    RoadIntersection {
      translation -53 0 -53
      rotation 0 1 0 0.785
      name "road intersection(3)"
      roadsWidth 6
      startRoadsLength [
        -0.1
      ]
      startRoadsStartLine [
        ""
        ""
      ]
      startRoadsLine [
        RoadLine {
          type "continuous"
          width 0.3
        }
      ]
      startRoadBorderWidth 0.5
      bottom TRUE
      appearance Asphalt {
        colorOverride 0.5 0.5 1
      }
    }
    StraightRoadSegment {
      translation -53 0 20
      name "road(20)"
      width 6
      numberOfForwardLanes 2
      lines [
        RoadLine {
          type "continuous"
          width 0.3
        }
      ]
      rightBarrier TRUE
      leftBarrier TRUE
      bottom TRUE
      length 30
      appearance Asphalt {
        colorOverride 0 0 0
        IBLStrength 0
      }
      pavementAppearance StonePavement {
        colorOverride 0 0 0
      }
    }
    AddLanesRoadSegment {
      translation -53 0 20
      rotation 0 1 0 3.14
      width 6
      length 10
      numberOfNewLanes 1
      newLaneLeft FALSE
      lines [
        RoadLine {
          type "continuous"
          width 0.3
        }
      ]
      rightBarrier TRUE
      leftBarrier TRUE
      bottom TRUE
      appearance Asphalt {
        colorOverride 0 0 0
        IBLStrength 0
      }
      pavementAppearance StonePavement {
        colorOverride 0 0 0
      }
    }
    StraightRoadSegment {
      translation -51.5 0 -10
      name "road(17)"
      width 9
      numberOfLanes 3
      numberOfForwardLanes 2
      lines [
        RoadLine {
          type "continuous"
          width 0.3
        }
        RoadLine {
          type "continuous"
          width 0.3
        }
      ]
      rightBarrier TRUE
      leftBarrier TRUE
      bottom TRUE
      length 20
      appearance Asphalt {
        colorOverride 0 0 0
        IBLStrength 0
      }
      pavementAppearance StonePavement {
        colorOverride 0 0 0
      }
    }
    AddLanesRoadSegment {
      translation -53 0 -20
      name "road(3)"
      width 6
      length 10
      numberOfNewLanes 1
      lines [
        RoadLine {
          type "continuous"
          width 0.3
        }
      ]
      rightBarrier TRUE
      leftBarrier TRUE
      bottom TRUE
      appearance Asphalt {
        colorOverride 0 0 0
        IBLStrength 0
      }
      pavementAppearance StonePavement {
        colorOverride 0 0 0
      }
    }
    StraightRoadSegment {
      translation -53 0 -50
      name "road(5)"
      width 6
      numberOfForwardLanes 2
      lines [
        RoadLine {
          type "continuous"
          width 0.3
        }
      ]
      rightBarrier TRUE
      leftBarrier TRUE
      bottom TRUE
      length 30
      appearance Asphalt {
        colorOverride 0 0 0
        IBLStrength 0
      }
      pavementAppearance StonePavement {
        colorOverride 0 0 0
      }
    }
    StraightRoadSegment {
      translation -50 0 -53
      rotation 0 1 0 1.57
      name "road(4)"
      width 6
      numberOfForwardLanes 2
      lines [
        RoadLine {
          type "continuous"
          width 0.3
        }
      ]
      rightBarrier TRUE
      leftBarrier TRUE
      bottom TRUE
      length 30
      appearance Asphalt {
        colorOverride 0 0 0
        IBLStrength 0
      }
      pavementAppearance StonePavement {
        colorOverride 0 0 0
      }
    }
    AddLanesRoadSegment {
      translation -10 0 -51.5
      rotation 0 1 0 -1.57
      name "road(2)"
      width 9
      length 10
      numberOfLanes 3
      numberOfNewLanes 1
      lines [
        RoadLine {
          type "continuous"
          width 0.3
        }
        RoadLine {
        }
      ]
      rightBarrier TRUE
      leftBarrier TRUE
      bottom TRUE
      appearance Asphalt {
        colorOverride 0 0 0
        IBLStrength 0
      }
      pavementAppearance StonePavement {
        colorOverride 0 0 0
      }
    }
    StraightRoadSegment {
      translation -10 0 -51.5
      rotation 0 1 0 1.571
      name "road(18)"
      width 9
      numberOfLanes 3
      numberOfForwardLanes 2
      lines [
        RoadLine {
          type "continuous"
          width 0.3
        }
        RoadLine {
          type "continuous"
          width 0.3
        }
      ]
      rightBarrier TRUE
      leftBarrier TRUE
      bottom TRUE
      length 20
      appearance Asphalt {
        colorOverride 0 0 0
        IBLStrength 0
      }
      pavementAppearance StonePavement {
        colorOverride 0 0 0
      }
    }
    AddLanesRoadSegment {
      translation 10 0 -51.5
      rotation 0 1 0 1.57
      name "road(19)"
      width 9
      length 10
      numberOfLanes 3
      numberOfNewLanes 1
      newLaneLeft FALSE
      lines [
        RoadLine {
          type "continuous"
          width 0.3
        }
        RoadLine {
        }
      ]
      rightBarrier TRUE
      leftBarrier TRUE
      bottom TRUE
      appearance Asphalt {
        colorOverride 0 0 0
        IBLStrength 0
      }
      pavementAppearance StonePavement {
        colorOverride 0 0 0
      }
    }
    CurvedRoadSegment {
      translation 20 0 -36.6
      rotation 0 1 0 1.571
      name "road(33)"
      width 6
      numberOfForwardLanes 2
      lines [
        RoadLine {
          type "continuous"
          width 0.3
        }
      ]
      roadBorderWidth [
        0
      ]
      rightBarrier TRUE
      leftBarrier TRUE
      bottom TRUE
      totalAngle 3.14
      subdivision 21
      appearance Asphalt {
        colorOverride 0 0 0
        IBLStrength 0
      }
      pavementAppearance StonePavement {
        colorOverride 0 0 0
      }
    }
    StraightRoadSegment {
      translation -20 0 -26.6
      rotation 0 1 0 1.571
      name "road(35)"
      width 6
      numberOfForwardLanes 2
      lines [
        RoadLine {
          type "continuous"
          width 0.3
        }
      ]
      rightBarrier TRUE
      leftBarrier TRUE
      bottom TRUE
      length 40
      appearance Asphalt {
        colorOverride 0 0 0
        IBLStrength 0
      }
      pavementAppearance StonePavement {
        colorOverride 0 0 0
      }
    }
    CurvedRoadSegment {
      translation -20 0 -36.6
      rotation 0 1 0 -1.571
      name "road(34)"
      width 6
      numberOfForwardLanes 2
      lines [
        RoadLine {
          type "continuous"
          width 0.3
        }
      ]
      roadBorderWidth [
        0
      ]
      rightBarrier TRUE
      leftBarrier TRUE
      bottom TRUE
      totalAngle 3.14
      subdivision 21
      appearance Asphalt {
        colorOverride 0 0 0
        IBLStrength 0
      }
      pavementAppearance StonePavement {
        colorOverride 0 0 0
      }
    }
    StraightRoadSegment {
      translation 20 0 -53
      rotation 0 1 0 1.57
      name "road(21)"
      width 6
      numberOfForwardLanes 2
      lines [
        RoadLine {
          type "continuous"
          width 0.3
        }
      ]
      rightBarrier TRUE
      leftBarrier TRUE
      bottom TRUE
      length 30
      appearance Asphalt {
        colorOverride 0 0 0
        IBLStrength 0
      }
      pavementAppearance StonePavement {
        colorOverride 0 0 0
      }
    }
    StraightRoadSegment {
      translation 53 0 -50
      name "road(22)"
      width 6
      numberOfForwardLanes 2
      lines [
        RoadLine {
          type "continuous"
          width 0.3
        }
      ]
      rightBarrier TRUE
      leftBarrier TRUE
      bottom TRUE
      length 30
      appearance Asphalt {
        colorOverride 0 0 0
        IBLStrength 0
      }
      pavementAppearance StonePavement {
        colorOverride 0 0 0
      }
    }
    AddLanesRoadSegment {
      translation 53 0 -20
      name "road(23)"
      width 6
      length 10
      numberOfNewLanes 1
      newLaneLeft FALSE
      lines [
        RoadLine {
          type "continuous"
          width 0.3
        }
      ]
      rightBarrier TRUE
      leftBarrier TRUE
      bottom TRUE
      appearance Asphalt {
        colorOverride 0 0 0
        IBLStrength 0
      }
      pavementAppearance StonePavement {
        colorOverride 0 0 0
      }
    }
    StraightRoadSegment {
      translation 51.5 0 -10
      name "road(24)"
      width 9
      numberOfLanes 3
      numberOfForwardLanes 2
      lines [
        RoadLine {
          type "continuous"
          width 0.3
        }
        RoadLine {
          type "continuous"
          width 0.3
        }
      ]
      rightBarrier TRUE
      leftBarrier TRUE
      bottom TRUE
      length 20
      appearance Asphalt {
        colorOverride 0 0 0
        IBLStrength 0
      }
      pavementAppearance StonePavement {
        colorOverride 0 0 0
      }
    }
    AddLanesRoadSegment {
      translation 53 0 20
      rotation 0 1 0 3.14
      name "road(25)"
      width 6
      length 10
      numberOfNewLanes 1
      lines [
        RoadLine {
          type "continuous"
          width 0.3
        }
      ]
      rightBarrier TRUE
      leftBarrier TRUE
      bottom TRUE
      appearance Asphalt {
        colorOverride 0 0 0
        IBLStrength 0
      }
      pavementAppearance StonePavement {
        colorOverride 0 0 0
      }
    }
    StraightRoadSegment {
      translation 53 0 20
      name "road(26)"
      width 6
      numberOfForwardLanes 2
      lines [
        RoadLine {
          type "continuous"
          width 0.3
        }
      ]
      rightBarrier TRUE
      leftBarrier TRUE
      bottom TRUE
      length 30
      appearance Asphalt {
        colorOverride 0 0 0
        IBLStrength 0
      }
      pavementAppearance StonePavement {
        colorOverride 0 0 0
      }
    }
    StraightRoadSegment {
      translation 20 0 53
      rotation 0 1 0 1.57
      name "road(27)"
      width 6
      numberOfForwardLanes 2
      lines [
        RoadLine {
          type "continuous"
          width 0.3
        }
      ]
      rightBarrier TRUE
      leftBarrier TRUE
      bottom TRUE
      length 30
      appearance Asphalt {
        colorOverride 0 0 0
        IBLStrength 0
      }
      pavementAppearance StonePavement {
        colorOverride 0 0 0
      }
    }
    AddLanesRoadSegment {
      translation 20 0 53
      rotation 0 1 0 -1.57
      name "road(28)"
      width 6
      length 10
      numberOfNewLanes 1
      newLaneLeft FALSE
      lines [
        RoadLine {
          type "continuous"
          width 0.3
        }
      ]
      rightBarrier TRUE
      leftBarrier TRUE
      bottom TRUE
      appearance Asphalt {
        colorOverride 0 0 0
        IBLStrength 0
      }
      pavementAppearance StonePavement {
        colorOverride 0 0 0
      }
    }
    StraightRoadSegment {
      translation -10 0 51.5
      rotation 0 1 0 1.57
      name "road(29)"
      width 9
      numberOfLanes 3
      numberOfForwardLanes 2
      lines [
        RoadLine {
          type "continuous"
          width 0.3
        }
        RoadLine {
          type "continuous"
          width 0.3
        }
      ]
      rightBarrier TRUE
      leftBarrier TRUE
      bottom TRUE
      length 20
      appearance Asphalt {
        colorOverride 0 0 0
        IBLStrength 0
      }
      pavementAppearance StonePavement {
        colorOverride 0 0 0
      }
    }
    AddLanesRoadSegment {
      translation -20 0 53
      rotation 0 1 0 1.57
      name "road(30)"
      width 6
      length 10
      numberOfNewLanes 1
      lines [
        RoadLine {
          type "continuous"
          width 0.3
        }
      ]
      rightBarrier TRUE
      leftBarrier TRUE
      bottom TRUE
      appearance Asphalt {
        colorOverride 0 0 0
        IBLStrength 0
      }
      pavementAppearance StonePavement {
        colorOverride 0 0 0
      }
    }
    StraightRoadSegment {
      translation -50 0 53
      rotation 0 1 0 1.57
      name "road(32)"
      width 6
      numberOfForwardLanes 2
      lines [
        RoadLine {
          type "continuous"
          width 0.3
        }
      ]
      rightBarrier TRUE
      leftBarrier TRUE
      bottom TRUE
      length 30
      appearance Asphalt {
        colorOverride 0 0 0
        IBLStrength 0
      }
      pavementAppearance StonePavement {
        colorOverride 0 0 0
      }
    }
    StraightRoadSegment {
      translation 53 0 20
      name "road(31)"
      width 6
      numberOfForwardLanes 2
      lines [
        RoadLine {
          type "continuous"
          width 0.3
        }
      ]
      rightBarrier TRUE
      leftBarrier TRUE
      bottom TRUE
      length 30
      appearance Asphalt {
        colorOverride 0 0 0
        IBLStrength 0
      }
      pavementAppearance StonePavement {
        colorOverride 0 0 0
      }
    }
    StraightRoadSegment {
      translation -76 0 -33
      name "road(6)"
      width 6
      numberOfForwardLanes 2
      lines [
        RoadLine {
          type "continuous"
          width 0.3
        }
      ]
      rightBarrier TRUE
      leftBarrier TRUE
      bottom TRUE
      length 66
      appearance Asphalt {
        colorOverride 0 0 0
        IBLStrength 0
      }
      pavementAppearance StonePavement {
        colorOverride 0 0 0
      }
    }
    StraightRoadSegment {
      translation -33 0 -76
      rotation 0 1 0 1.57
      name "road(14)"
      width 6
      numberOfForwardLanes 2
      lines [
        RoadLine {
          type "continuous"
          width 0.3
        }
      ]
      rightBarrier TRUE
      leftBarrier TRUE
      bottom TRUE
      length 66
      appearance Asphalt {
        colorOverride 0 0 0
        IBLStrength 0
      }
      pavementAppearance StonePavement {
        colorOverride 0 0 0
      }
    }
    StraightRoadSegment {
      translation 76 0 -33
      name "road(15)"
      width 6
      numberOfForwardLanes 2
      lines [
        RoadLine {
          type "continuous"
          width 0.3
        }
      ]
      rightBarrier TRUE
      leftBarrier TRUE
      bottom TRUE
      length 66
      appearance Asphalt {
        colorOverride 0 0 0
        IBLStrength 0
      }
      pavementAppearance StonePavement {
        colorOverride 0 0 0
      }
    }
    StraightRoadSegment {
      translation -33 0 76
      rotation 0 1 0 1.57
      name "road(16)"
      width 6
      numberOfForwardLanes 2
      lines [
        RoadLine {
          type "continuous"
          width 0.3
        }
      ]
      rightBarrier TRUE
      leftBarrier TRUE
      bottom TRUE
      length 66
      appearance Asphalt {
        colorOverride 0 0 0
        IBLStrength 0
      }
      pavementAppearance StonePavement {
        colorOverride 0 0 0
      }
    }
  ]
  name "environment"
}
Floor {
  size 176 176
  tileSize 0.1 0.1
  appearance PBRAppearance {
    baseColor 0.5 0.5 0.5
    transparency 0.9
    metalness 0
  }
}
