#VRML_SIM R2020a utf8
WorldInfo {
  basicTimeStep 16
}
Viewpoint {
  orientation 0.6264432095956959 -0.7159941516700028 -0.3080929728601352 5.389813767096276
  position 98.68051784069583 117.81183664907921 58.66033578527826
}
TexturedBackground {
  luminosity 2
  reflections FALSE
}
DEF Cab1 Robot {
  translation -9.316424413040542e-05 0.39866967936831976 -29.200002401192766
  rotation -0.00011349074066596113 0.9999999864427972 -0.00011930740695284313 -1.5723853225127584
  children [
    DEF cam_f Camera {
      translation 0 0.1 1
      rotation 0 1 0 3.14
      children [
        Shape {
          appearance PBRAppearance {
            baseColor 0.4 0 0
          }
          geometry Cylinder {
            height 0.1
            radius 0.05
          }
        }
      ]
      boundingObject Cylinder {
        height 0.1
        radius 0.05
      }
      physics Physics {
        density 1
      }
      fieldOfView 0.75
      width 18
      height 10
      far 10
    }
    DEF ls_f LightSensor {
      translation 0 0 1
      rotation 0 1 0 -1.57
      children [
        Shape {
          appearance PBRAppearance {
            baseColor 0 0 0
            metalness 0
          }
          geometry Box {
            size 0.1 0.1 0.1
          }
        }
      ]
      name "ls_front"
      boundingObject Shape {
        appearance PBRAppearance {
        }
        geometry Cylinder {
          height 0.1
          radius 0.05
        }
      }
      physics Physics {
        density 1
      }
      lookupTable [
        0 0 0
        5 1000 0
      ]
    }
    DEF ds_fl DistanceSensor {
      translation 0.45 0.2 1
      rotation 0 1 0 -1.047
      children [
        Shape {
          appearance PBRAppearance {
          }
          geometry Box {
            size 0.1 0.1 0.1
          }
        }
      ]
      name "ds_fl"
      boundingObject Shape {
        appearance PBRAppearance {
        }
        geometry Box {
          size 0.1 0.1 0.1
        }
      }
      physics Physics {
        density 1
      }
      lookupTable [
        0 0 0
        5 1000 0
      ]
    }
    DEF ds_lf DistanceSensor {
      translation 0.5 0.2 0.95
      children [
        Shape {
          appearance PBRAppearance {
          }
          geometry Box {
            size 0.1 0.1 0.1
          }
        }
      ]
      name "ds_lf"
      boundingObject Shape {
        appearance PBRAppearance {
        }
        geometry Box {
          size 0.1 0.1 0.1
        }
      }
      physics Physics {
        density 1
      }
      lookupTable [
        0 0 0
        5 1000 0
      ]
    }
    DEF ds_lc DistanceSensor {
      translation 0.5 0.2 0
      children [
        Shape {
          appearance PBRAppearance {
          }
          geometry Box {
            size 0.1 0.1 0.1
          }
        }
      ]
      name "ds_lc"
      boundingObject Shape {
        appearance PBRAppearance {
        }
        geometry Box {
          size 0.1 0.1 0.1
        }
      }
      physics Physics {
        density 1
      }
      lookupTable [
        0 0 0
        5 1000 0
      ]
    }
    DEF ds_fr DistanceSensor {
      translation -0.45 0.2 1
      rotation 0 1 0 -2.09
      children [
        Shape {
          appearance PBRAppearance {
          }
          geometry Box {
            size 0.1 0.1 0.1
          }
        }
      ]
      name "ds_fr"
      boundingObject Shape {
        appearance PBRAppearance {
        }
        geometry Box {
          size 0.1 0.1 0.1
        }
      }
      physics Physics {
        density 1
      }
      lookupTable [
        0 0 0
        5 1000 0
      ]
    }
    DEF ds_rf DistanceSensor {
      translation -0.5 0.2 0.95
      rotation 0 1 0 -3.14
      children [
        Shape {
          appearance PBRAppearance {
          }
          geometry Box {
            size 0.1 0.1 0.1
          }
        }
      ]
      name "ds_rf"
      boundingObject Shape {
        appearance PBRAppearance {
        }
        geometry Box {
          size 0.1 0.1 0.1
        }
      }
      physics Physics {
        density 1
      }
      lookupTable [
        0 0 0
        5 1000 0
      ]
    }
    DEF ds_rc DistanceSensor {
      translation -0.5 0.2 0
      rotation 0 1 0 -3.14
      children [
        Shape {
          appearance PBRAppearance {
          }
          geometry Box {
            size 0.1 0.1 0.1
          }
        }
      ]
      name "ds_rc"
      boundingObject Shape {
        appearance PBRAppearance {
        }
        geometry Box {
          size 0.1 0.1 0.1
        }
      }
      physics Physics {
        density 1
      }
      lookupTable [
        0 0 0
        5 1000 0
      ]
    }
    DEF ds_fc DistanceSensor {
      translation 0 0.2 1
      rotation 0 1 0 -1.57
      children [
        Shape {
          appearance PBRAppearance {
          }
          geometry Box {
            size 0.1 0.1 0.1
          }
        }
      ]
      name "ds_fc"
      boundingObject Shape {
        appearance PBRAppearance {
        }
        geometry Box {
          size 0.1 0.1 0.1
        }
      }
      physics Physics {
        density 1
      }
      lookupTable [
        0 0 0
        5 1000 0
      ]
    }
    DEF ds_fcr DistanceSensor {
      translation -0.225 0.2 1
      rotation 0 1 0 -1.833
      children [
        Shape {
          appearance PBRAppearance {
          }
          geometry Box {
            size 0.1 0.1 0.1
          }
        }
      ]
      name "ds_fcr"
      boundingObject Shape {
        appearance PBRAppearance {
        }
        geometry Box {
          size 0.1 0.1 0.1
        }
      }
      physics Physics {
        density 1
      }
      lookupTable [
        0 0 0
        5 1000 0
      ]
    }
    DEF ds_fcl DistanceSensor {
      translation 0.225 0.2 1
      rotation 0 1 0 -1.309
      children [
        Shape {
          appearance PBRAppearance {
          }
          geometry Box {
            size 0.1 0.1 0.1
          }
        }
      ]
      name "ds_fcl"
      boundingObject Shape {
        appearance PBRAppearance {
        }
        geometry Box {
          size 0.1 0.1 0.1
        }
      }
      physics Physics {
        density 1
      }
      lookupTable [
        0 0 0
        5 1000 0
      ]
    }
    Transform {
      translation 0 0.5 -0.3
      rotation 1 0 0 0
      children [
        Shape {
          appearance PBRAppearance {
            baseColor 0.5 0.5 0.5
            transparency 0.3
          }
          geometry Box {
            size 0.9 0.5 1.2
          }
        }
      ]
    }
    Transform {
      translation 0 0.8 -0.3
      rotation 1 0 0 0
      children [
        Shape {
          appearance PBRAppearance {
            baseColor 0 0 0
          }
          geometry Box {
            size 1 0.1 1.3
          }
        }
      ]
    }
    DEF wheelFL HingeJoint {
      jointParameters HingeJointParameters {
        position 6.56496126078052e-08
        anchor 0.55 -0.1 0.55
      }
      device [
        DEF wheelFL RotationalMotor {
          name "wheelFL"
          maxTorque 30
        }
      ]
      endPoint DEF wheelFL Solid {
        translation 0.55 -0.1 0.55
        rotation 3.28509559899295e-08 -3.2824806303902586e-08 0.999999999999999 1.5699999999999972
        children [
          DEF wheel Shape {
            appearance PBRAppearance {
              baseColor 0 0 0
              metalness 0
            }
            geometry Cylinder {
              height 0.1
              radius 0.3
            }
          }
        ]
        name "wheelFL"
        boundingObject USE wheel
        physics DEF physics_wheel Physics {
          density 10
        }
        linearVelocity -7.952689960275746e-08 -2.9284674799839716e-09 -1.7196542811796785e-08
        angularVelocity -9.367780055304274e-09 -7.840100620077063e-08 3.193891608964457e-07
      }
    }
    DEF wheelRL HingeJoint {
      jointParameters HingeJointParameters {
        position 6.848277939036311e-08
        anchor 0.55 -0.1 -0.7
      }
      device [
        DEF wheelRL RotationalMotor {
          name "wheelRL"
          maxTorque 30
        }
      ]
      endPoint DEF wheelRL Solid {
        translation 0.55 -0.1 -0.7
        rotation 3.426866789391222e-08 -3.4241389695181536e-08 0.999999999999999 1.5699999999999974
        children [
          DEF wheel Shape {
            appearance PBRAppearance {
              baseColor 0 0 0
              metalness 0
            }
            geometry Cylinder {
              height 0.1
              radius 0.3
            }
          }
        ]
        name "wheelRL"
        boundingObject USE wheel
        physics DEF physics_wheel Physics {
          density 10
        }
        linearVelocity -8.228707718248101e-08 -2.5633998891337403e-09 1.7398992807622218e-08
        angularVelocity 9.79373876913185e-09 -7.840034583306914e-08 3.3238522803859037e-07
      }
    }
    DEF wheelRR HingeJoint {
      jointParameters HingeJointParameters {
        position 1.0696807176889511e-10
        anchor -0.55 -0.1 -0.7
      }
      device [
        DEF wheelRR RotationalMotor {
          name "wheelRR"
          maxTorque 30
        }
      ]
      endPoint DEF wheelRR Solid {
        translation -0.55 -0.1 -0.7
        rotation 5.352664362241973e-11 -5.348403588444522e-11 1 1.5699999999999963
        children [
          DEF wheel Shape {
            appearance PBRAppearance {
              baseColor 0 0 0
              metalness 0
            }
            geometry Cylinder {
              height 0.1
              radius 0.3
            }
          }
        ]
        name "wheelRR"
        boundingObject USE wheel
        physics DEF physics_wheel Physics {
          density 10
        }
        linearVelocity 8.183137160929722e-08 -1.7839375804079646e-09 1.765976628450676e-08
        angularVelocity 1.0848242312436692e-08 -7.841956987644865e-08 -3.3126625239609927e-07
      }
    }
    DEF wheelFR HingeJoint {
      jointParameters HingeJointParameters {
        position -2.843734819969593e-11
        anchor -0.55 -0.1 0.55
      }
      device [
        DEF wheelFR RotationalMotor {
          name "wheelFR"
          maxTorque 30
        }
      ]
      endPoint DEF wheelFR Solid {
        translation -0.55 -0.1 0.55
        rotation -1.4230001321705361e-11 1.4218674099850307e-11 1 1.5699999999999956
        children [
          DEF wheel Shape {
            appearance PBRAppearance {
              baseColor 0 0 0
              metalness 0
            }
            geometry Cylinder {
              height 0.1
              radius 0.3
            }
          }
        ]
        name "wheelFR"
        boundingObject USE wheel
        physics DEF physics_wheel Physics {
          density 10
        }
        linearVelocity 7.935536720459413e-08 -2.149002306015198e-09 -1.694406273272891e-08
        angularVelocity -8.35393424571879e-09 -7.841895487915821e-08 -3.186640607521307e-07
      }
    }
    DEF car_body Shape {
      appearance PBRAppearance {
        baseColor 1 1 0
      }
      geometry Box {
        size 1 0.6 2
      }
    }
  ]
  name "Cab1"
  boundingObject USE car_body
  physics Physics {
    density 10
  }
  recognitionColors [
    0 0 0
  ]
  controller "controller"
  linearVelocity -1.7473944955702864e-10 -2.3617092427230786e-09 -5.6454167953159086e-09
  angularVelocity 7.231699990888482e-10 -7.884602062214951e-08 2.872330909087987e-10
}
DEF Cab2 Robot {
  translation 9.999906835755867 0.3986696793683197 -29.100002401192782
  rotation -0.0001134907406659767 0.999999986442797 -0.00011930740695281215 -1.5723853225127629
  children [
    DEF cam_f Camera {
      translation 0 0.1 1
      rotation 0 1 0 3.14
      children [
        Shape {
          appearance PBRAppearance {
            baseColor 0.4 0 0
          }
          geometry Cylinder {
            height 0.1
            radius 0.05
          }
        }
      ]
      boundingObject Cylinder {
        height 0.1
        radius 0.05
      }
      physics Physics {
        density 1
      }
      fieldOfView 0.75
      width 18
      height 10
      far 10
    }
    DEF ls_f LightSensor {
      translation 0 0 1
      rotation 0 1 0 -1.57
      children [
        Shape {
          appearance PBRAppearance {
            baseColor 0 0 0
            metalness 0
          }
          geometry Box {
            size 0.1 0.1 0.1
          }
        }
      ]
      name "ls_front"
      boundingObject Shape {
        appearance PBRAppearance {
        }
        geometry Cylinder {
          height 0.1
          radius 0.05
        }
      }
      physics Physics {
        density 1
      }
      lookupTable [
        0 0 0
        5 1000 0
      ]
    }
    DEF ds_fl DistanceSensor {
      translation 0.45 0.2 1
      rotation 0 1 0 -1.047
      children [
        Shape {
          appearance PBRAppearance {
          }
          geometry Box {
            size 0.1 0.1 0.1
          }
        }
      ]
      name "ds_fl"
      boundingObject Shape {
        appearance PBRAppearance {
        }
        geometry Box {
          size 0.1 0.1 0.1
        }
      }
      physics Physics {
        density 1
      }
      lookupTable [
        0 0 0
        5 1000 0
      ]
    }
    DEF ds_lf DistanceSensor {
      translation 0.5 0.2 0.95
      children [
        Shape {
          appearance PBRAppearance {
          }
          geometry Box {
            size 0.1 0.1 0.1
          }
        }
      ]
      name "ds_lf"
      boundingObject Shape {
        appearance PBRAppearance {
        }
        geometry Box {
          size 0.1 0.1 0.1
        }
      }
      physics Physics {
        density 1
      }
      lookupTable [
        0 0 0
        5 1000 0
      ]
    }
    DEF ds_lc DistanceSensor {
      translation 0.5 0.2 0
      children [
        Shape {
          appearance PBRAppearance {
          }
          geometry Box {
            size 0.1 0.1 0.1
          }
        }
      ]
      name "ds_lc"
      boundingObject Shape {
        appearance PBRAppearance {
        }
        geometry Box {
          size 0.1 0.1 0.1
        }
      }
      physics Physics {
        density 1
      }
      lookupTable [
        0 0 0
        5 1000 0
      ]
    }
    DEF ds_fr DistanceSensor {
      translation -0.45 0.2 1
      rotation 0 1 0 -2.09
      children [
        Shape {
          appearance PBRAppearance {
          }
          geometry Box {
            size 0.1 0.1 0.1
          }
        }
      ]
      name "ds_fr"
      boundingObject Shape {
        appearance PBRAppearance {
        }
        geometry Box {
          size 0.1 0.1 0.1
        }
      }
      physics Physics {
        density 1
      }
      lookupTable [
        0 0 0
        5 1000 0
      ]
    }
    DEF ds_rf DistanceSensor {
      translation -0.5 0.2 0.95
      rotation 0 1 0 -3.14
      children [
        Shape {
          appearance PBRAppearance {
          }
          geometry Box {
            size 0.1 0.1 0.1
          }
        }
      ]
      name "ds_rf"
      boundingObject Shape {
        appearance PBRAppearance {
        }
        geometry Box {
          size 0.1 0.1 0.1
        }
      }
      physics Physics {
        density 1
      }
      lookupTable [
        0 0 0
        5 1000 0
      ]
    }
    DEF ds_rc DistanceSensor {
      translation -0.5 0.2 0
      rotation 0 1 0 -3.14
      children [
        Shape {
          appearance PBRAppearance {
          }
          geometry Box {
            size 0.1 0.1 0.1
          }
        }
      ]
      name "ds_rc"
      boundingObject Shape {
        appearance PBRAppearance {
        }
        geometry Box {
          size 0.1 0.1 0.1
        }
      }
      physics Physics {
        density 1
      }
      lookupTable [
        0 0 0
        5 1000 0
      ]
    }
    DEF ds_fc DistanceSensor {
      translation 0 0.2 1
      rotation 0 1 0 -1.57
      children [
        Shape {
          appearance PBRAppearance {
          }
          geometry Box {
            size 0.1 0.1 0.1
          }
        }
      ]
      name "ds_fc"
      boundingObject Shape {
        appearance PBRAppearance {
        }
        geometry Box {
          size 0.1 0.1 0.1
        }
      }
      physics Physics {
        density 1
      }
      lookupTable [
        0 0 0
        5 1000 0
      ]
    }
    DEF ds_fcr DistanceSensor {
      translation -0.225 0.2 1
      rotation 0 1 0 -1.833
      children [
        Shape {
          appearance PBRAppearance {
          }
          geometry Box {
            size 0.1 0.1 0.1
          }
        }
      ]
      name "ds_fcr"
      boundingObject Shape {
        appearance PBRAppearance {
        }
        geometry Box {
          size 0.1 0.1 0.1
        }
      }
      physics Physics {
        density 1
      }
      lookupTable [
        0 0 0
        5 1000 0
      ]
    }
    DEF ds_fcl DistanceSensor {
      translation 0.225 0.2 1
      rotation 0 1 0 -1.309
      children [
        Shape {
          appearance PBRAppearance {
          }
          geometry Box {
            size 0.1 0.1 0.1
          }
        }
      ]
      name "ds_fcl"
      boundingObject Shape {
        appearance PBRAppearance {
        }
        geometry Box {
          size 0.1 0.1 0.1
        }
      }
      physics Physics {
        density 1
      }
      lookupTable [
        0 0 0
        5 1000 0
      ]
    }
    Transform {
      translation 0 0.5 -0.3
      rotation 1 0 0 0
      children [
        Shape {
          appearance PBRAppearance {
            baseColor 0.5 0.5 0.5
            transparency 0.3
          }
          geometry Box {
            size 0.9 0.5 1.2
          }
        }
      ]
    }
    Transform {
      translation 0 0.8 -0.3
      rotation 1 0 0 0
      children [
        Shape {
          appearance PBRAppearance {
            baseColor 0 0 0
          }
          geometry Box {
            size 1 0.1 1.3
          }
        }
      ]
    }
    DEF wheelFL HingeJoint {
      jointParameters HingeJointParameters {
        position 6.564961255015656e-08
        anchor 0.55 -0.1 0.55
      }
      device [
        DEF wheelFL RotationalMotor {
          name "wheelFL"
          maxTorque 30
        }
      ]
      endPoint DEF wheelFL Solid {
        translation 0.55 -0.1 0.55
        rotation 3.285095596108222e-08 -3.2824806275078266e-08 0.999999999999999 1.5699999999999972
        children [
          DEF wheel Shape {
            appearance PBRAppearance {
              baseColor 0 0 0
              metalness 0
            }
            geometry Cylinder {
              height 0.1
              radius 0.3
            }
          }
        ]
        name "wheelFL"
        boundingObject USE wheel
        physics DEF physics_wheel Physics {
          density 10
        }
        linearVelocity -7.952689040023336e-08 -2.92846778086188e-09 -1.7196544396940225e-08
        angularVelocity -9.36778397459748e-09 -7.840098982654462e-08 3.1938915054369297e-07
      }
    }
    DEF wheelRL HingeJoint {
      jointParameters HingeJointParameters {
        position 6.848277965949068e-08
        anchor 0.55 -0.1 -0.7
      }
      device [
        DEF wheelRL RotationalMotor {
          name "wheelRL"
          maxTorque 30
        }
      ]
      endPoint DEF wheelRL Solid {
        translation 0.55 -0.1 -0.7
        rotation 3.426866802858321e-08 -3.424138982974532e-08 0.999999999999999 1.5699999999999974
        children [
          DEF wheel Shape {
            appearance PBRAppearance {
              baseColor 0 0 0
              metalness 0
            }
            geometry Cylinder {
              height 0.1
              radius 0.3
            }
          }
        ]
        name "wheelRL"
        boundingObject USE wheel
        physics DEF physics_wheel Physics {
          density 10
        }
        linearVelocity -8.228707901847423e-08 -2.5633993360571014e-09 1.7398984746284358e-08
        angularVelocity 9.793732560878459e-09 -7.840033015161333e-08 3.323852174084679e-07
      }
    }
    DEF wheelRR HingeJoint {
      jointParameters HingeJointParameters {
        position 1.0696791883094226e-10
        anchor -0.55 -0.1 -0.7
      }
      device [
        DEF wheelRR RotationalMotor {
          name "wheelRR"
          maxTorque 30
        }
      ]
      endPoint DEF wheelRR Solid {
        translation -0.55 -0.1 -0.7
        rotation 5.352656709252008e-11 -5.348395941546879e-11 1 1.5699999999999963
        children [
          DEF wheel Shape {
            appearance PBRAppearance {
              baseColor 0 0 0
              metalness 0
            }
            geometry Cylinder {
              height 0.1
              radius 0.3
            }
          }
        ]
        name "wheelRR"
        boundingObject USE wheel
        physics DEF physics_wheel Physics {
          density 10
        }
        linearVelocity 8.183137199009645e-08 -1.783937479546741e-09 1.765977579879039e-08
        angularVelocity 1.0848249994832288e-08 -7.841955559951475e-08 -3.312662472562038e-07
      }
    }
    DEF wheelFR HingeJoint {
      jointParameters HingeJointParameters {
        position -2.8437689021646552e-11
        anchor -0.55 -0.1 0.55
      }
      device [
        DEF wheelFR RotationalMotor {
          name "wheelFR"
          maxTorque 30
        }
      ]
      endPoint DEF wheelFR Solid {
        translation -0.55 -0.1 0.55
        rotation -1.4230171868437558e-11 1.4218844510825617e-11 1 1.5699999999999956
        children [
          DEF wheel Shape {
            appearance PBRAppearance {
              baseColor 0 0 0
              metalness 0
            }
            geometry Cylinder {
              height 0.1
              radius 0.3
            }
          }
        ]
        name "wheelFR"
        boundingObject USE wheel
        physics DEF physics_wheel Physics {
          density 10
        }
        linearVelocity 7.935536355282379e-08 -2.1490032110190914e-09 -1.694406392030755e-08
        angularVelocity -8.353935588684691e-09 -7.841893919747366e-08 -3.1866405861351515e-07
      }
    }
    DEF car_body Shape {
      appearance PBRAppearance {
        baseColor 1 1 0
      }
      geometry Box {
        size 1 0.6 2
      }
    }
  ]
  name "Cab2"
  boundingObject USE car_body
  physics Physics {
    density 10
  }
  recognitionColors [
    0 0 0
  ]
  controller "controller"
  linearVelocity -1.7473716746095253e-10 -2.3617094698889543e-09 -5.6454270969603486e-09
  angularVelocity 7.231707068769279e-10 -7.88460062537031e-08 2.87234224008002e-10
}
DEF environment Solid {
  scale 1.09819 1.09819 1.09819
  children [
    DEF PickUp1 BusStop {
      translation 0 0 -45
      rotation 0 1 0 3.14159
      name "PickUp1"
      bench FALSE
      appearance PBRAppearance {
        baseColor 0 0 0
        roughness 0.5
        metalness 0
      }
      internalAdvertisingTexture []
      externalAdvertisingTexture []
    }
    DEF PickUp2 BusStop {
      translation 45 0 0
      rotation 0 -1 0 -1.5707953071795862
      name "PickUp2"
      bench FALSE
      appearance PBRAppearance {
        baseColor 1 0 0
        roughness 0.5
        metalness 0
      }
      internalAdvertisingTexture []
      externalAdvertisingTexture []
      advertisingLightOn FALSE
    }
    DEF PickUp3 BusStop {
      translation 0 0 45
      rotation 0 1 0 -5.307179586466759e-06
      name "PickUp3"
      bench FALSE
      appearance PBRAppearance {
        baseColor 0 1 0
        roughness 0.5
        metalness 0
      }
      internalAdvertisingTexture []
      externalAdvertisingTexture []
      advertisingLightOn FALSE
    }
    DEF PickUp4 BusStop {
      translation -45 0 0
      rotation 0 1 0 -1.5707953071795862
      name "PickUp4"
      bench FALSE
      appearance PBRAppearance {
        baseColor 0 0 1
        roughness 0.5
        metalness 0
      }
      internalAdvertisingTexture []
      externalAdvertisingTexture []
      advertisingLightOn FALSE
    }
    DEF PickUp5 BusStop {
      translation 0 0 -71
      rotation 0 1 0 3.14159
      name "PickUp5"
      bench FALSE
      appearance PBRAppearance {
        baseColor 1 1 0
        roughness 0.5
        metalness 0
      }
      internalAdvertisingTexture []
      externalAdvertisingTexture []
      advertisingLightOn FALSE
    }
    DEF PickUp6 BusStop {
      translation 71 0 0
      rotation 0 -1 0 -1.5707953071795862
      name "PickUp6"
      bench FALSE
      appearance PBRAppearance {
        baseColor 1 0 1
        roughness 0.5
        metalness 0
      }
      internalAdvertisingTexture []
      externalAdvertisingTexture []
      advertisingLightOn FALSE
    }
    DEF PickUp7 BusStop {
      translation 0 0 71
      rotation 0 1 0 -5.307179586466759e-06
      name "PickUp7"
      bench FALSE
      appearance PBRAppearance {
        baseColor 0 1 1
        roughness 0.5
        metalness 0
      }
      internalAdvertisingTexture []
      externalAdvertisingTexture []
      advertisingLightOn FALSE
    }
    DEF PickUp8 BusStop {
      translation -71 0 0
      rotation 0 1 0 -1.5707953071795862
      name "PickUp8"
      bench FALSE
      appearance PBRAppearance {
        roughness 0.5
        metalness 0
      }
      internalAdvertisingTexture []
      externalAdvertisingTexture []
      advertisingLightOn FALSE
    }
    CurvedRoadSegment {
      translation -56 0 33
      rotation 0 1 0 -1.570796
      name "road(1)"
      width 6
      numberOfForwardLanes 2
      lines [
        RoadLine {
          type "continuous"
          width 0.1
        }
      ]
      rightBarrier TRUE
      leftBarrier TRUE
      bottom TRUE
      curvatureRadius 20
      appearance Asphalt {
        colorOverride 0 0 0
        IBLStrength 0
      }
      pavementAppearance StonePavement {
        colorOverride 0 0 0
      }
    }
    CurvedRoadSegment {
      translation -56 0 -33
      rotation 0 1 0 3.14
      name "road(7)"
      width 6
      numberOfForwardLanes 2
      lines [
        RoadLine {
          type "continuous"
          width 0.1
        }
      ]
      rightBarrier TRUE
      leftBarrier TRUE
      bottom TRUE
      curvatureRadius 20
      appearance Asphalt {
        colorOverride 0 0 0
        IBLStrength 0
      }
      pavementAppearance StonePavement {
        colorOverride 0 0 0
      }
    }
    CurvedRoadSegment {
      translation -33 0 -56
      rotation 0 1 0 3.14
      name "road(8)"
      width 6
      numberOfForwardLanes 2
      lines [
        RoadLine {
          type "continuous"
          width 0.1
        }
      ]
      rightBarrier TRUE
      leftBarrier TRUE
      bottom TRUE
      curvatureRadius 20
      appearance Asphalt {
        colorOverride 0 0 0
        IBLStrength 0
      }
      pavementAppearance StonePavement {
        colorOverride 0 0 0
      }
    }
    CurvedRoadSegment {
      translation 33 0 -56
      rotation 0 1 0 1.57
      name "road(9)"
      width 6
      numberOfForwardLanes 2
      lines [
        RoadLine {
          type "continuous"
          width 0.1
        }
      ]
      rightBarrier TRUE
      leftBarrier TRUE
      bottom TRUE
      curvatureRadius 20
      appearance Asphalt {
        colorOverride 0 0 0
        IBLStrength 0
      }
      pavementAppearance StonePavement {
        colorOverride 0 0 0
      }
    }
    CurvedRoadSegment {
      translation 56 0 -33
      rotation 0 1 0 1.57
      name "road(10)"
      width 6
      numberOfForwardLanes 2
      lines [
        RoadLine {
          type "continuous"
          width 0.1
        }
      ]
      rightBarrier TRUE
      leftBarrier TRUE
      bottom TRUE
      curvatureRadius 20
      appearance Asphalt {
        colorOverride 0 0 0
        IBLStrength 0
      }
      pavementAppearance StonePavement {
        colorOverride 0 0 0
      }
    }
    CurvedRoadSegment {
      translation 56 0 33
      name "road(11)"
      width 6
      numberOfForwardLanes 2
      lines [
        RoadLine {
          type "continuous"
          width 0.1
        }
      ]
      rightBarrier TRUE
      leftBarrier TRUE
      bottom TRUE
      curvatureRadius 20
      appearance Asphalt {
        colorOverride 0 0 0
        IBLStrength 0
      }
      pavementAppearance StonePavement {
        colorOverride 0 0 0
      }
    }
    CurvedRoadSegment {
      translation 33 0 56
      name "road(12)"
      width 6
      numberOfForwardLanes 2
      lines [
        RoadLine {
          type "continuous"
          width 0.1
        }
      ]
      rightBarrier TRUE
      leftBarrier TRUE
      bottom TRUE
      curvatureRadius 20
      appearance Asphalt {
        colorOverride 0 0 0
        IBLStrength 0
      }
      pavementAppearance StonePavement {
        colorOverride 0 0 0
      }
    }
    CurvedRoadSegment {
      translation -33 0 56
      rotation 0 1 0 -1.57
      name "road(13)"
      width 6
      numberOfForwardLanes 2
      lines [
        RoadLine {
          type "continuous"
          width 0.1
        }
      ]
      rightBarrier TRUE
      leftBarrier TRUE
      bottom TRUE
      curvatureRadius 20
      appearance Asphalt {
        colorOverride 0 0 0
        IBLStrength 0
      }
      pavementAppearance StonePavement {
        colorOverride 0 0 0
      }
    }
    RoadIntersection {
      translation -53 0 53
      rotation 0 1 0 0.785
      roadsWidth 6
      startRoadsLength [
        -0.1
      ]
      startRoadsStartLine [
        ""
        ""
      ]
      startRoadsLine [
        RoadLine {
          type "continuous"
          width 0.3
        }
      ]
      startRoadBorderWidth 0.5
      bottom TRUE
      appearance Asphalt {
        colorOverride 0.5 0.5 0
      }
    }
    RoadIntersection {
      translation 53 0 53
      rotation 0 1 0 0.785
      name "road intersection(1)"
      roadsWidth 6
      startRoadsLength [
        -0.1
      ]
      startRoadsStartLine [
        ""
        ""
      ]
      startRoadsLine [
        RoadLine {
          type "continuous"
          width 0.3
        }
      ]
      startRoadBorderWidth 0.5
      bottom TRUE
      appearance Asphalt {
        colorOverride 0.5 0.5 0
      }
    }
    RoadIntersection {
      translation 53 0 -53
      rotation 0 1 0 0.785
      name "road intersection(2)"
      roadsWidth 6
      startRoadsLength [
        -0.1
      ]
      startRoadsStartLine [
        ""
        ""
      ]
      startRoadsLine [
        RoadLine {
          type "continuous"
          width 0.3
        }
      ]
      startRoadBorderWidth 0.5
      bottom TRUE
      appearance Asphalt {
        colorOverride 0.5 0.5 0
      }
    }
    RoadIntersection {
      translation -53 0 -53
      rotation 0 1 0 0.785
      name "road intersection(3)"
      roadsWidth 6
      startRoadsLength [
        -0.1
      ]
      startRoadsStartLine [
        ""
        ""
      ]
      startRoadsLine [
        RoadLine {
          type "continuous"
          width 0.3
        }
      ]
      startRoadBorderWidth 0.5
      bottom TRUE
      appearance Asphalt {
        colorOverride 0.5 0.5 0
      }
    }
    StraightRoadSegment {
      translation -53 0 20
      name "road(20)"
      width 6
      numberOfForwardLanes 2
      lines [
        RoadLine {
          type "continuous"
          width 0.1
        }
      ]
      rightBarrier TRUE
      leftBarrier TRUE
      bottom TRUE
      length 30
      appearance Asphalt {
        colorOverride 0 0 0
        IBLStrength 0
      }
      pavementAppearance StonePavement {
        colorOverride 0 0 0
      }
    }
    AddLanesRoadSegment {
      translation -53 0 20
      rotation 0 1 0 3.14
      width 6
      length 10
      numberOfNewLanes 1
      newLaneLeft FALSE
      lines [
        RoadLine {
          type "continuous"
          width 0.1
        }
      ]
      rightBarrier TRUE
      leftBarrier TRUE
      bottom TRUE
      appearance Asphalt {
        colorOverride 0 0 0
        IBLStrength 0
      }
      pavementAppearance StonePavement {
        colorOverride 0 0 0
      }
    }
    Solid {
      translation -51.48 0 15.5
      rotation 0 1 0 -0.2617996938995747
      children [
        Shape {
          appearance PBRAppearance {
            roughness 1
            metalness 0
          }
          geometry Box {
            size 0.08 0.01 11.6
          }
        }
      ]
      name "solid(1)"
    }
    StraightRoadSegment {
      translation -51.5 0 -10
      name "road(17)"
      width 9
      numberOfLanes 3
      numberOfForwardLanes 2
      lines [
        RoadLine {
          type "continuous"
          width 0.1
        }
        RoadLine {
          type "continuous"
          width 0.1
        }
      ]
      rightBarrier TRUE
      leftBarrier TRUE
      bottom TRUE
      length 20
      appearance Asphalt {
        colorOverride 0 0 0
        IBLStrength 0
      }
      pavementAppearance StonePavement {
        colorOverride 0 0 0
      }
    }
    AddLanesRoadSegment {
      translation -53 0 -20
      name "road(3)"
      width 6
      length 10
      numberOfNewLanes 1
      lines [
        RoadLine {
          type "continuous"
          width 0.1
        }
      ]
      rightBarrier TRUE
      leftBarrier TRUE
      bottom TRUE
      appearance Asphalt {
        colorOverride 0 0 0
        IBLStrength 0
      }
      pavementAppearance StonePavement {
        colorOverride 0 0 0
      }
    }
    Solid {
      translation -51.48 0 -15.5
      rotation 0 1 0 0.2618
      children [
        Shape {
          appearance PBRAppearance {
            roughness 1
            metalness 0
          }
          geometry Box {
            size 0.08 0.01 11.6
          }
        }
      ]
      name "solid(2)"
    }
    StraightRoadSegment {
      translation -53 0 -50
      name "road(5)"
      width 6
      numberOfForwardLanes 2
      lines [
        RoadLine {
          type "continuous"
          width 0.1
        }
      ]
      rightBarrier TRUE
      leftBarrier TRUE
      bottom TRUE
      length 30
      appearance Asphalt {
        colorOverride 0 0 0
        IBLStrength 0
      }
      pavementAppearance StonePavement {
        colorOverride 0 0 0
      }
    }
    StraightRoadSegment {
      translation -50 0 -53
      rotation 0 1 0 1.57
      name "road(4)"
      width 6
      numberOfForwardLanes 2
      lines [
        RoadLine {
          type "continuous"
          width 0.1
        }
      ]
      rightBarrier TRUE
      leftBarrier TRUE
      bottom TRUE
      length 30
      appearance Asphalt {
        colorOverride 0 0 0
        IBLStrength 0
      }
      pavementAppearance StonePavement {
        colorOverride 0 0 0
      }
    }
    AddLanesRoadSegment {
      translation -10 0 -51.5
      rotation 0 1 0 -1.57
      name "road(2)"
      width 9
      length 10
      numberOfLanes 3
      numberOfNewLanes 1
      lines [
        RoadLine {
          type "continuous"
          width 0.1
        }
        RoadLine {
          type "continuous"
          width -1.73472e-18
        }
      ]
      rightBarrier TRUE
      leftBarrier TRUE
      bottom TRUE
      appearance Asphalt {
        colorOverride 0 0 0
        IBLStrength 0
      }
      pavementAppearance StonePavement {
        colorOverride 0 0 0
      }
    }
    Solid {
      translation 15.5 0 -51.48
      rotation 0 1 0 1.8326
      children [
        Shape {
          appearance PBRAppearance {
            roughness 1
            metalness 0
          }
          geometry Box {
            size 0.08 0.01 11.6
          }
        }
      ]
      name "solid(3)"
    }
    StraightRoadSegment {
      translation -10 0 -51.5
      rotation 0 1 0 1.571
      name "road(18)"
      width 9
      numberOfLanes 3
      numberOfForwardLanes 2
      lines [
        RoadLine {
          type "continuous"
          width 0.1
        }
        RoadLine {
          type "continuous"
          width 0.1
        }
      ]
      rightBarrier TRUE
      leftBarrier TRUE
      bottom TRUE
      length 20
      appearance Asphalt {
        colorOverride 0 0 0
        IBLStrength 0
      }
      pavementAppearance StonePavement {
        colorOverride 0 0 0
      }
    }
    AddLanesRoadSegment {
      translation 10 0 -51.5
      rotation 0 1 0 1.57
      name "road(19)"
      width 9
      length 10
      numberOfLanes 3
      numberOfNewLanes 1
      newLaneLeft FALSE
      lines [
        RoadLine {
          type "continuous"
          width 0.1
        }
        RoadLine {
          type "continuous"
          width -1.73472e-18
        }
      ]
      rightBarrier TRUE
      leftBarrier TRUE
      bottom TRUE
      startLine [
        ""
      ]
      appearance Asphalt {
        colorOverride 0 0 0
        IBLStrength 0
      }
      pavementAppearance StonePavement {
        colorOverride 0 0 0
      }
    }
    Solid {
      translation -15.5 0 -51.48
      rotation 0 1 0 -1.8326
      children [
        Shape {
          appearance PBRAppearance {
            roughness 1
            metalness 0
          }
          geometry Box {
            size 0.08 0.01 11.6
          }
        }
      ]
      name "solid(4)"
    }
    CurvedRoadSegment {
      translation 20 0 -36.8
      rotation 0 1 0 1.571
      name "road(33)"
      width 5.8
      numberOfForwardLanes 2
      lines [
        RoadLine {
          type "continuous"
          width 0.1
        }
      ]
      roadBorderWidth [
        0
      ]
      rightBarrier TRUE
      leftBarrier TRUE
      bottom TRUE
      totalAngle 3.14
      subdivision 21
      appearance Asphalt {
        colorOverride 0 0 0
        IBLStrength 0
      }
      pavementAppearance StonePavement {
        colorOverride 0 0 0
      }
    }
    StraightRoadSegment {
      translation -20 0 -26.8
      rotation 0 1 0 1.571
      name "road(35)"
      width 5.8
      numberOfForwardLanes 2
      lines [
        RoadLine {
          type "continuous"
          width 0.1
        }
      ]
      rightBarrier TRUE
      leftBarrier TRUE
      bottom TRUE
      length 40
      appearance Asphalt {
        colorOverride 0 0 0
        IBLStrength 0
      }
      pavementAppearance StonePavement {
        colorOverride 0 0 0
      }
    }
    CurvedRoadSegment {
      translation -20 0 -36.8
      rotation 0 1 0 -1.571
      name "road(34)"
      width 5.8
      numberOfForwardLanes 2
      lines [
        RoadLine {
          type "continuous"
          width 0.1
        }
      ]
      roadBorderWidth [
        0
      ]
      rightBarrier TRUE
      leftBarrier TRUE
      bottom TRUE
      totalAngle 3.14
      subdivision 21
      appearance Asphalt {
        colorOverride 0 0 0
        IBLStrength 0
      }
      pavementAppearance StonePavement {
        colorOverride 0 0 0
      }
    }
    StraightRoadSegment {
      translation 20 0 -53
      rotation 0 1 0 1.57
      name "road(21)"
      width 6
      numberOfForwardLanes 2
      lines [
        RoadLine {
          type "continuous"
          width 0.1
        }
      ]
      rightBarrier TRUE
      leftBarrier TRUE
      bottom TRUE
      length 30
      appearance Asphalt {
        colorOverride 0 0 0
        IBLStrength 0
      }
      pavementAppearance StonePavement {
        colorOverride 0 0 0
      }
    }
    StraightRoadSegment {
      translation 53 0 -50
      name "road(22)"
      width 6
      numberOfForwardLanes 2
      lines [
        RoadLine {
          type "continuous"
          width 0.1
        }
      ]
      rightBarrier TRUE
      leftBarrier TRUE
      bottom TRUE
      length 30
      appearance Asphalt {
        colorOverride 0 0 0
        IBLStrength 0
      }
      pavementAppearance StonePavement {
        colorOverride 0 0 0
      }
    }
    AddLanesRoadSegment {
      translation 53 0 -20
      name "road(23)"
      width 6
      length 10
      numberOfNewLanes 1
      newLaneLeft FALSE
      lines [
        RoadLine {
          type "continuous"
          width 0.1
        }
      ]
      rightBarrier TRUE
      leftBarrier TRUE
      bottom TRUE
      appearance Asphalt {
        colorOverride 0 0 0
        IBLStrength 0
      }
      pavementAppearance StonePavement {
        colorOverride 0 0 0
      }
    }
    Solid {
      translation 51.48 0 -15.5
      rotation 0 1 0 -0.2617996938995747
      children [
        Shape {
          appearance PBRAppearance {
            roughness 1
            metalness 0
          }
          geometry Box {
            size 0.08 0.01 11.6
          }
        }
      ]
      name "solid(5)"
    }
    StraightRoadSegment {
      translation 51.5 0 -10
      name "road(24)"
      width 9
      numberOfLanes 3
      numberOfForwardLanes 2
      lines [
        RoadLine {
          type "continuous"
          width 0.1
        }
        RoadLine {
          type "continuous"
          width 0.1
        }
      ]
      rightBarrier TRUE
      leftBarrier TRUE
      bottom TRUE
      length 20
      appearance Asphalt {
        colorOverride 0 0 0
        IBLStrength 0
      }
      pavementAppearance StonePavement {
        colorOverride 0 0 0
      }
    }
    AddLanesRoadSegment {
      translation 53 0 20
      rotation 0 1 0 3.14
      name "road(25)"
      width 6
      length 10
      numberOfNewLanes 1
      lines [
        RoadLine {
          type "continuous"
          width 0.1
        }
      ]
      rightBarrier TRUE
      leftBarrier TRUE
      bottom TRUE
      appearance Asphalt {
        colorOverride 0 0 0
        IBLStrength 0
      }
      pavementAppearance StonePavement {
        colorOverride 0 0 0
      }
    }
    Solid {
      translation 51.48 0 15.5
      rotation 0 1 0 0.2618
      children [
        Shape {
          appearance PBRAppearance {
            roughness 1
            metalness 0
          }
          geometry Box {
            size 0.08 0.01 11.6
          }
        }
      ]
      name "solid(6)"
    }
    StraightRoadSegment {
      translation 53 0 20
      name "road(26)"
      width 6
      numberOfForwardLanes 2
      lines [
        RoadLine {
          type "continuous"
          width 0.1
        }
      ]
      rightBarrier TRUE
      leftBarrier TRUE
      bottom TRUE
      length 30
      appearance Asphalt {
        colorOverride 0 0 0
        IBLStrength 0
      }
      pavementAppearance StonePavement {
        colorOverride 0 0 0
      }
    }
    StraightRoadSegment {
      translation 20 0 53
      rotation 0 1 0 1.57
      name "road(27)"
      width 6
      numberOfForwardLanes 2
      lines [
        RoadLine {
          type "continuous"
          width 0.1
        }
      ]
      rightBarrier TRUE
      leftBarrier TRUE
      bottom TRUE
      length 30
      appearance Asphalt {
        colorOverride 0 0 0
        IBLStrength 0
      }
      pavementAppearance StonePavement {
        colorOverride 0 0 0
      }
    }
    AddLanesRoadSegment {
      translation 20 0 53
      rotation -8.069599999950631e-07 -0.999999999993882 -3.4036599999791764e-06 1.57
      name "road(28)"
      width 6
      length 10
      numberOfNewLanes 1
      newLaneLeft FALSE
      lines [
        RoadLine {
          type "continuous"
          width 0.1
        }
      ]
      rightBarrier TRUE
      leftBarrier TRUE
      bottom TRUE
      appearance Asphalt {
        colorOverride 0 0 0
        IBLStrength 0
      }
      pavementAppearance StonePavement {
        colorOverride 0 0 0
      }
    }
    Solid {
      translation 15.5 0 51.48
      rotation 0 1 0 -1.8326
      children [
        Shape {
          appearance PBRAppearance {
            roughness 1
            metalness 0
          }
          geometry Box {
            size 0.08 0.01 11.6
          }
        }
      ]
      name "solid(7)"
    }
    StraightRoadSegment {
      translation -10 0 51.5
      rotation 0 1 0 1.57
      name "road(29)"
      width 9
      numberOfLanes 3
      numberOfForwardLanes 2
      lines [
        RoadLine {
          type "continuous"
          width 0.1
        }
        RoadLine {
          type "continuous"
          width 0.1
        }
      ]
      rightBarrier TRUE
      leftBarrier TRUE
      bottom TRUE
      length 20
      appearance Asphalt {
        colorOverride 0 0 0
        IBLStrength 0
      }
      pavementAppearance StonePavement {
        colorOverride 0 0 0
      }
    }
    AddLanesRoadSegment {
      translation -20 0 53
      rotation 0 1 0 1.57
      name "road(30)"
      width 6
      length 10
      numberOfNewLanes 1
      lines [
        RoadLine {
          type "continuous"
          width 0.1
        }
      ]
      rightBarrier TRUE
      leftBarrier TRUE
      bottom TRUE
      appearance Asphalt {
        colorOverride 0 0 0
        IBLStrength 0
      }
      pavementAppearance StonePavement {
        colorOverride 0 0 0
      }
    }
    Solid {
      translation -15.5 0 51.48
      rotation 0 1 0 1.8326
      children [
        Shape {
          appearance PBRAppearance {
            roughness 1
            metalness 0
          }
          geometry Box {
            size 0.08 0.01 11.6
          }
        }
      ]
      name "solid(8)"
    }
    StraightRoadSegment {
      translation -50 0 53
      rotation 0 1 0 1.57
      name "road(32)"
      width 6
      numberOfForwardLanes 2
      lines [
        RoadLine {
          type "continuous"
          width 0.1
        }
      ]
      rightBarrier TRUE
      leftBarrier TRUE
      bottom TRUE
      length 30
      appearance Asphalt {
        colorOverride 0 0 0
        IBLStrength 0
      }
      pavementAppearance StonePavement {
        colorOverride 0 0 0
      }
    }
    StraightRoadSegment {
      translation 53 0 20
      name "road(31)"
      width 6
      numberOfForwardLanes 2
      lines [
        RoadLine {
          type "continuous"
          width 0.1
        }
      ]
      rightBarrier TRUE
      leftBarrier TRUE
      bottom TRUE
      length 30
      appearance Asphalt {
        colorOverride 0 0 0
        IBLStrength 0
      }
      pavementAppearance StonePavement {
        colorOverride 0 0 0
      }
    }
    StraightRoadSegment {
      translation -76 0 -33
      name "road(6)"
      width 6
      numberOfForwardLanes 2
      lines [
        RoadLine {
          type "continuous"
          width 0.1
        }
      ]
      rightBarrier TRUE
      leftBarrier TRUE
      bottom TRUE
      length 66
      appearance Asphalt {
        colorOverride 0 0 0
        IBLStrength 0
      }
      pavementAppearance StonePavement {
        colorOverride 0 0 0
      }
    }
    StraightRoadSegment {
      translation -33 0 -76
      rotation 0 1 0 1.57
      name "road(14)"
      width 6
      numberOfForwardLanes 2
      lines [
        RoadLine {
          type "continuous"
          width 0.1
        }
      ]
      rightBarrier TRUE
      leftBarrier TRUE
      bottom TRUE
      length 66
      appearance Asphalt {
        colorOverride 0 0 0
        IBLStrength 0
      }
      pavementAppearance StonePavement {
        colorOverride 0 0 0
      }
    }
    StraightRoadSegment {
      translation 76 0 -33
      name "road(15)"
      width 6
      numberOfForwardLanes 2
      lines [
        RoadLine {
          type "continuous"
          width 0.1
        }
      ]
      rightBarrier TRUE
      leftBarrier TRUE
      bottom TRUE
      length 66
      appearance Asphalt {
        colorOverride 0 0 0
        IBLStrength 0
      }
      pavementAppearance StonePavement {
        colorOverride 0 0 0
      }
    }
    StraightRoadSegment {
      translation -33 0 76
      rotation 0 1 0 1.57
      name "road(16)"
      width 6
      numberOfForwardLanes 2
      lines [
        RoadLine {
          type "continuous"
          width 0.1
        }
      ]
      rightBarrier TRUE
      leftBarrier TRUE
      bottom TRUE
      length 66
      appearance Asphalt {
        colorOverride 0 0 0
        IBLStrength 0
      }
      pavementAppearance StonePavement {
        colorOverride 0 0 0
      }
    }
    Solid {
      translation -15 0 -48.41
      rotation 0 1 0 -1.26
      children [
        Shape {
          appearance PBRAppearance {
            roughness 1
            metalness 0
          }
          geometry Box {
            size 0.08 0.01 10.67
          }
        }
      ]
      name "solid(9)"
    }
    Solid {
      translation 15 0 -48.39
      rotation 0 1 0 -1.88
      children [
        Shape {
          appearance PBRAppearance {
            roughness 1
            metalness 0
          }
          geometry Box {
            size 0.08 0.01 10.67
          }
        }
      ]
      name "solid(10)"
    }
  ]
  name "environment"
}
Floor {
  size 176 176
  tileSize 0.1 0.1
  appearance PBRAppearance {
    baseColor 0.5 0.5 0.5
    transparency 0.9
    metalness 0
  }
}
