#VRML_SIM R2020a utf8
WorldInfo {
  basicTimeStep 16
}
Viewpoint {
  orientation -0.4461727308645599 0.8306950139021306 0.3329800115787737 1.2059813250092664
  position 12.980528048219444 22.731682014645823 -12.209330787330611
}
TexturedBackground {
  luminosity 2
  reflections FALSE
}
DEF Cab1 Robot {
  translation -0.00011293391705434344 0.3986624226528907 -29.200004982776218
  rotation -0.00013508640652596017 0.9999999800245202 -0.00014731809684204243 -1.5723853294035264
  children [
    DEF cam_f Camera {
      translation 0 0.1 1
      rotation 0 1 0 3.14
      children [
        Shape {
          appearance PBRAppearance {
            baseColor 0.4 0 0
          }
          geometry Cylinder {
            height 0.1
            radius 0.05
          }
        }
      ]
      boundingObject Cylinder {
        height 0.1
        radius 0.05
      }
      physics Physics {
        density 1
      }
      fieldOfView 0.75
      width 18
      height 10
      far 10
    }
    DEF ls_f LightSensor {
      translation 0 0 1
      rotation 0 1 0 -1.57
      children [
        Shape {
          appearance PBRAppearance {
            baseColor 0 0 0
            metalness 0
          }
          geometry Box {
            size 0.1 0.1 0.1
          }
        }
      ]
      name "ls_front"
      boundingObject Shape {
        appearance PBRAppearance {
        }
        geometry Cylinder {
          height 0.1
          radius 0.05
        }
      }
      physics Physics {
        density 1
      }
      lookupTable [
        0 0 0
        5 1000 0
      ]
    }
    DEF ds_fl DistanceSensor {
      translation 0.45 0.2 1
      rotation 0 1 0 -1.047
      children [
        Shape {
          appearance PBRAppearance {
          }
          geometry Box {
            size 0.1 0.1 0.1
          }
        }
      ]
      name "ds_fl"
      boundingObject Shape {
        appearance PBRAppearance {
        }
        geometry Box {
          size 0.1 0.1 0.1
        }
      }
      physics Physics {
        density 1
      }
      lookupTable [
        0 0 0
        5 1000 0
      ]
    }
    DEF ds_lf DistanceSensor {
      translation 0.5 0.2 0.95
      children [
        Shape {
          appearance PBRAppearance {
          }
          geometry Box {
            size 0.1 0.1 0.1
          }
        }
      ]
      name "ds_lf"
      boundingObject Shape {
        appearance PBRAppearance {
        }
        geometry Box {
          size 0.1 0.1 0.1
        }
      }
      physics Physics {
        density 1
      }
      lookupTable [
        0 0 0
        5 1000 0
      ]
    }
    DEF ds_lc DistanceSensor {
      translation 0.5 0.2 0
      children [
        Shape {
          appearance PBRAppearance {
          }
          geometry Box {
            size 0.1 0.1 0.1
          }
        }
      ]
      name "ds_lc"
      boundingObject Shape {
        appearance PBRAppearance {
        }
        geometry Box {
          size 0.1 0.1 0.1
        }
      }
      physics Physics {
        density 1
      }
      lookupTable [
        0 0 0
        5 1000 0
      ]
    }
    DEF ds_fr DistanceSensor {
      translation -0.45 0.2 1
      rotation 0 1 0 -2.09
      children [
        Shape {
          appearance PBRAppearance {
          }
          geometry Box {
            size 0.1 0.1 0.1
          }
        }
      ]
      name "ds_fr"
      boundingObject Shape {
        appearance PBRAppearance {
        }
        geometry Box {
          size 0.1 0.1 0.1
        }
      }
      physics Physics {
        density 1
      }
      lookupTable [
        0 0 0
        5 1000 0
      ]
    }
    DEF ds_rf DistanceSensor {
      translation -0.5 0.2 0.95
      rotation 0 1 0 -3.14
      children [
        Shape {
          appearance PBRAppearance {
          }
          geometry Box {
            size 0.1 0.1 0.1
          }
        }
      ]
      name "ds_rf"
      boundingObject Shape {
        appearance PBRAppearance {
        }
        geometry Box {
          size 0.1 0.1 0.1
        }
      }
      physics Physics {
        density 1
      }
      lookupTable [
        0 0 0
        5 1000 0
      ]
    }
    DEF ds_rc DistanceSensor {
      translation -0.5 0.2 0
      rotation 0 1 0 -3.14
      children [
        Shape {
          appearance PBRAppearance {
          }
          geometry Box {
            size 0.1 0.1 0.1
          }
        }
      ]
      name "ds_rc"
      boundingObject Shape {
        appearance PBRAppearance {
        }
        geometry Box {
          size 0.1 0.1 0.1
        }
      }
      physics Physics {
        density 1
      }
      lookupTable [
        0 0 0
        5 1000 0
      ]
    }
    DEF ds_fc DistanceSensor {
      translation 0 0.2 1
      rotation 0 1 0 -1.57
      children [
        Shape {
          appearance PBRAppearance {
          }
          geometry Box {
            size 0.1 0.1 0.1
          }
        }
      ]
      name "ds_fc"
      boundingObject Shape {
        appearance PBRAppearance {
        }
        geometry Box {
          size 0.1 0.1 0.1
        }
      }
      physics Physics {
        density 1
      }
      lookupTable [
        0 0 0
        5 1000 0
      ]
    }
    DEF ds_fcr DistanceSensor {
      translation -0.225 0.2 1
      rotation 0 1 0 -1.833
      children [
        Shape {
          appearance PBRAppearance {
          }
          geometry Box {
            size 0.1 0.1 0.1
          }
        }
      ]
      name "ds_fcr"
      boundingObject Shape {
        appearance PBRAppearance {
        }
        geometry Box {
          size 0.1 0.1 0.1
        }
      }
      physics Physics {
        density 1
      }
      lookupTable [
        0 0 0
        5 1000 0
      ]
    }
    DEF ds_fcl DistanceSensor {
      translation 0.225 0.2 1
      rotation 0 1 0 -1.309
      children [
        Shape {
          appearance PBRAppearance {
          }
          geometry Box {
            size 0.1 0.1 0.1
          }
        }
      ]
      name "ds_fcl"
      boundingObject Shape {
        appearance PBRAppearance {
        }
        geometry Box {
          size 0.1 0.1 0.1
        }
      }
      physics Physics {
        density 1
      }
      lookupTable [
        0 0 0
        5 1000 0
      ]
    }
    Transform {
      translation 0 0.5 -0.3
      rotation 1 0 0 0
      children [
        Shape {
          appearance PBRAppearance {
            baseColor 0.5 0.5 0.5
            transparency 0.3
          }
          geometry Box {
            size 0.9 0.5 1.2
          }
        }
      ]
    }
    Transform {
      translation 0 0.8 -0.3
      rotation 1 0 0 0
      children [
        Shape {
          appearance PBRAppearance {
            baseColor 0 0 0
          }
          geometry Box {
            size 1 0.1 1.3
          }
        }
      ]
    }
    DEF wheelFL HingeJoint {
      jointParameters HingeJointParameters {
        position 9.59481811156483e-11
        anchor 0.55 -0.1 0.55
      }
      device [
        DEF wheelFL RotationalMotor {
          name "wheelFL"
          maxTorque 30
        }
      ]
      endPoint DEF wheelFL Solid {
        translation 0.55 -0.1 0.55
        rotation 4.801230883073333e-11 -4.7974090557824154e-11 1 1.5699999999999963
        children [
          DEF wheel Shape {
            appearance PBRAppearance {
              baseColor 0 0 0
              metalness 0
            }
            geometry Cylinder {
              height 0.1
              radius 0.3
            }
          }
        ]
        name "wheelFL"
        boundingObject USE wheel
        physics DEF physics_wheel Physics {
          density 10
        }
        linearVelocity -7.880343507369163e-08 -6.913071464918105e-11 -1.7695559262754097e-08
        angularVelocity -9.553956666681941e-09 -7.937625386704606e-08 3.146166529024849e-07
      }
    }
    DEF wheelRL HingeJoint {
      jointParameters HingeJointParameters {
        position -3.193782733352813e-11
        anchor 0.55 -0.1 -0.7
      }
      device [
        DEF wheelRL RotationalMotor {
          name "wheelRL"
          maxTorque 30
        }
      ]
      endPoint DEF wheelRL Solid {
        translation 0.55 -0.1 -0.7
        rotation -1.5981635206528458e-11 1.5968913666764065e-11 1 1.5699999999999963
        children [
          DEF wheel Shape {
            appearance PBRAppearance {
              baseColor 0 0 0
              metalness 0
            }
            geometry Cylinder {
              height 0.1
              radius 0.3
            }
          }
        ]
        name "wheelRL"
        boundingObject USE wheel
        physics DEF physics_wheel Physics {
          density 10
        }
        linearVelocity -8.204481564714706e-08 -1.4635695707566187e-10 1.7281580205251744e-08
        angularVelocity 9.856134704979224e-09 -7.937536808268507e-08 3.3085932129860284e-07
      }
    }
    DEF wheelRR HingeJoint {
      jointParameters HingeJointParameters {
        position -6.799918105284854e-08
        anchor -0.55 -0.1 -0.7
      }
      device [
        DEF wheelRR RotationalMotor {
          name "wheelRR"
          maxTorque 30
        }
      ]
      endPoint DEF wheelRR Solid {
        translation -0.55 -0.1 -0.7
        rotation -3.4026676097290324e-08 3.399959052642425e-08 0.999999999999999 1.5699999999999974
        children [
          DEF wheel Shape {
            appearance PBRAppearance {
              baseColor 0 0 0
              metalness 0
            }
            geometry Cylinder {
              height 0.1
              radius 0.3
            }
          }
        ]
        name "wheelRR"
        boundingObject USE wheel
        physics DEF physics_wheel Physics {
          density 10
        }
        linearVelocity 8.179374225620005e-08 7.746909675544751e-10 1.754066409535473e-08
        angularVelocity 1.0906889230919579e-08 -7.939848526775738e-08 -3.301864865141811e-07
      }
    }
    DEF wheelFR HingeJoint {
      jointParameters HingeJointParameters {
        position -9.566134800755359e-11
        anchor -0.55 -0.1 0.5
      }
      device [
        DEF wheelFR RotationalMotor {
          name "wheelFR"
          maxTorque 30
        }
      ]
      endPoint DEF wheelFR Solid {
        translation -0.55 -0.1 0.5
        rotation -4.786877802474422e-11 4.7830674003776796e-11 1 1.5699999999999956
        children [
          DEF wheel Shape {
            appearance PBRAppearance {
              baseColor 0 0 0
              metalness 0
            }
            geometry Cylinder {
              height 0.1
              radius 0.3
            }
          }
        ]
        name "wheelFR"
        boundingObject USE wheel
        physics DEF physics_wheel Physics {
          density 10
        }
        linearVelocity 7.878772915166407e-08 8.488291977144405e-10 -1.6047146344397073e-08
        angularVelocity -7.776273515205326e-09 -7.939763562978393e-08 -3.146476277023679e-07
      }
    }
    DEF car_body Shape {
      appearance PBRAppearance {
        baseColor 1 1 0
      }
      geometry Box {
        size 1 0.6 2
      }
    }
  ]
  name "Cab1"
  boundingObject USE car_body
  physics Physics {
    density 10
  }
  recognitionColors [
    0 0 0
  ]
  controller "controller"
  linearVelocity -5.7661162444099e-11 -1.1178301477277344e-11 -6.660739960204138e-09
  angularVelocity 8.506702979332187e-10 -7.982881322961399e-08 2.4996748901896284e-11
}
DEF Cab2 Robot {
  translation -24.656400008080226 0.3986624226528906 -50.65609998320368
  rotation 0.0001165280500251796 0.9999999838780561 -0.0001366202795807189 1.8141852894735404
  children [
    DEF cam_f Camera {
      translation 0 0.1 1
      rotation 0 1 0 3.14
      children [
        Shape {
          appearance PBRAppearance {
            baseColor 0.4 0 0
          }
          geometry Cylinder {
            height 0.1
            radius 0.05
          }
        }
      ]
      boundingObject Cylinder {
        height 0.1
        radius 0.05
      }
      physics Physics {
        density 1
      }
      fieldOfView 0.75
      width 18
      height 10
      far 10
    }
    DEF ls_f LightSensor {
      translation 0 0 1
      rotation 0 1 0 -1.57
      children [
        Shape {
          appearance PBRAppearance {
            baseColor 0 0 0
            metalness 0
          }
          geometry Box {
            size 0.1 0.1 0.1
          }
        }
      ]
      name "ls_front"
      boundingObject Shape {
        appearance PBRAppearance {
        }
        geometry Cylinder {
          height 0.1
          radius 0.05
        }
      }
      physics Physics {
        density 1
      }
      lookupTable [
        0 0 0
        5 1000 0
      ]
    }
    DEF ds_fl DistanceSensor {
      translation 0.45 0.2 1
      rotation 0 1 0 -1.047
      children [
        Shape {
          appearance PBRAppearance {
          }
          geometry Box {
            size 0.1 0.1 0.1
          }
        }
      ]
      name "ds_fl"
      boundingObject Shape {
        appearance PBRAppearance {
        }
        geometry Box {
          size 0.1 0.1 0.1
        }
      }
      physics Physics {
        density 1
      }
      lookupTable [
        0 0 0
        5 1000 0
      ]
    }
    DEF ds_lf DistanceSensor {
      translation 0.5 0.2 0.95
      children [
        Shape {
          appearance PBRAppearance {
          }
          geometry Box {
            size 0.1 0.1 0.1
          }
        }
      ]
      name "ds_lf"
      boundingObject Shape {
        appearance PBRAppearance {
        }
        geometry Box {
          size 0.1 0.1 0.1
        }
      }
      physics Physics {
        density 1
      }
      lookupTable [
        0 0 0
        5 1000 0
      ]
    }
    DEF ds_lc DistanceSensor {
      translation 0.5 0.2 0
      children [
        Shape {
          appearance PBRAppearance {
          }
          geometry Box {
            size 0.1 0.1 0.1
          }
        }
      ]
      name "ds_lc"
      boundingObject Shape {
        appearance PBRAppearance {
        }
        geometry Box {
          size 0.1 0.1 0.1
        }
      }
      physics Physics {
        density 1
      }
      lookupTable [
        0 0 0
        5 1000 0
      ]
    }
    DEF ds_fr DistanceSensor {
      translation -0.45 0.2 1
      rotation 0 1 0 -2.09
      children [
        Shape {
          appearance PBRAppearance {
          }
          geometry Box {
            size 0.1 0.1 0.1
          }
        }
      ]
      name "ds_fr"
      boundingObject Shape {
        appearance PBRAppearance {
        }
        geometry Box {
          size 0.1 0.1 0.1
        }
      }
      physics Physics {
        density 1
      }
      lookupTable [
        0 0 0
        5 1000 0
      ]
    }
    DEF ds_rf DistanceSensor {
      translation -0.5 0.2 0.95
      rotation 0 1 0 -3.14
      children [
        Shape {
          appearance PBRAppearance {
          }
          geometry Box {
            size 0.1 0.1 0.1
          }
        }
      ]
      name "ds_rf"
      boundingObject Shape {
        appearance PBRAppearance {
        }
        geometry Box {
          size 0.1 0.1 0.1
        }
      }
      physics Physics {
        density 1
      }
      lookupTable [
        0 0 0
        5 1000 0
      ]
    }
    DEF ds_rc DistanceSensor {
      translation -0.5 0.2 0
      rotation 0 1 0 -3.14
      children [
        Shape {
          appearance PBRAppearance {
          }
          geometry Box {
            size 0.1 0.1 0.1
          }
        }
      ]
      name "ds_rc"
      boundingObject Shape {
        appearance PBRAppearance {
        }
        geometry Box {
          size 0.1 0.1 0.1
        }
      }
      physics Physics {
        density 1
      }
      lookupTable [
        0 0 0
        5 1000 0
      ]
    }
    DEF ds_fc DistanceSensor {
      translation 0 0.2 1
      rotation 0 1 0 -1.57
      children [
        Shape {
          appearance PBRAppearance {
          }
          geometry Box {
            size 0.1 0.1 0.1
          }
        }
      ]
      name "ds_fc"
      boundingObject Shape {
        appearance PBRAppearance {
        }
        geometry Box {
          size 0.1 0.1 0.1
        }
      }
      physics Physics {
        density 1
      }
      lookupTable [
        0 0 0
        5 1000 0
      ]
    }
    DEF ds_fcr DistanceSensor {
      translation -0.225 0.2 1
      rotation 0 1 0 -1.833
      children [
        Shape {
          appearance PBRAppearance {
          }
          geometry Box {
            size 0.1 0.1 0.1
          }
        }
      ]
      name "ds_fcr"
      boundingObject Shape {
        appearance PBRAppearance {
        }
        geometry Box {
          size 0.1 0.1 0.1
        }
      }
      physics Physics {
        density 1
      }
      lookupTable [
        0 0 0
        5 1000 0
      ]
    }
    DEF ds_fcl DistanceSensor {
      translation 0.225 0.2 1
      rotation 0 1 0 -1.309
      children [
        Shape {
          appearance PBRAppearance {
          }
          geometry Box {
            size 0.1 0.1 0.1
          }
        }
      ]
      name "ds_fcl"
      boundingObject Shape {
        appearance PBRAppearance {
        }
        geometry Box {
          size 0.1 0.1 0.1
        }
      }
      physics Physics {
        density 1
      }
      lookupTable [
        0 0 0
        5 1000 0
      ]
    }
    Transform {
      translation 0 0.5 -0.3
      rotation 1 0 0 0
      children [
        Shape {
          appearance PBRAppearance {
            baseColor 0.5 0.5 0.5
            transparency 0.3
          }
          geometry Box {
            size 0.9 0.5 1.2
          }
        }
      ]
    }
    Transform {
      translation 0 0.8 -0.3
      rotation 1 0 0 0
      children [
        Shape {
          appearance PBRAppearance {
            baseColor 0 0 0
          }
          geometry Box {
            size 1 0.1 1.3
          }
        }
      ]
    }
    DEF wheelFL HingeJoint {
      jointParameters HingeJointParameters {
        position 3.2258187174821837e-08
        anchor 0.55 -0.1 0.55
      }
      device [
        DEF wheelFL RotationalMotor {
          name "wheelFL"
          maxTorque 30
        }
      ]
      endPoint DEF wheelFL Solid {
        translation 0.55 -0.1 0.55
        rotation 1.995557020958283e-08 -1.9939685377623346e-08 0.9999999999999996 1.569999999999995
        children [
          DEF wheel Shape {
            appearance PBRAppearance {
              baseColor 0 0 0
              metalness 0
            }
            geometry Cylinder {
              height 0.1
              radius 0.3
            }
          }
        ]
        name "wheelFL"
        boundingObject USE wheel
        physics DEF physics_wheel Physics {
          density 10
        }
        linearVelocity 8.074228402761955e-08 -6.913252398811174e-11 -1.9453678930150545e-09
        angularVelocity -6.70367483792865e-08 -7.93762357400193e-08 -3.0753991544304526e-07
      }
    }
    DEF wheelRL HingeJoint {
      jointParameters HingeJointParameters {
        position 3.3002033938718573e-08
        anchor 0.55 -0.1 -0.7
      }
      device [
        DEF wheelRL RotationalMotor {
          name "wheelRL"
          maxTorque 30
        }
      ]
      endPoint DEF wheelRL Solid {
        translation 0.55 -0.1 -0.7
        rotation 1.3941625779198073e-08 -1.39305281071277e-08 0.9999999999999999 1.5699999999999974
        children [
          DEF wheel Shape {
            appearance PBRAppearance {
              baseColor 0 0 0
              metalness 0
            }
            geometry Cylinder {
              height 0.1
              radius 0.3
            }
          }
        ]
        name "wheelRL"
        boundingObject USE wheel
        physics DEF physics_wheel Physics {
          density 10
        }
        linearVelocity 7.540373509507352e-08 -1.463594701301728e-10 -3.666432265932707e-08
        angularVelocity -8.980674444157366e-08 -7.937534925457238e-08 -3.185900879949746e-07
      }
    }
    DEF wheelRR HingeJoint {
      jointParameters HingeJointParameters {
        position -3.4434831580189206e-08
        anchor -0.55 -0.1 -0.7
      }
      device [
        DEF wheelRR RotationalMotor {
          name "wheelRR"
          maxTorque 30
        }
      ]
      endPoint DEF wheelRR Solid {
        translation -0.55 -0.1 -0.7
        rotation -1.7677388853914416e-08 1.766331747762298e-08 0.9999999999999998 1.5699999999999956
        children [
          DEF wheel Shape {
            appearance PBRAppearance {
              baseColor 0 0 0
              metalness 0
            }
            geometry Cylinder {
              height 0.1
              radius 0.3
            }
          }
        ]
        name "wheelRR"
        boundingObject USE wheel
        physics DEF physics_wheel Physics {
          density 10
        }
        linearVelocity -8.360587639150191e-08 7.746947873958011e-10 2.8209216007310183e-09
        angularVelocity 6.950054712816382e-08 -7.939846834837124e-08 3.2297350216128485e-07
      }
    }
    DEF wheelFR HingeJoint {
      jointParameters HingeJointParameters {
        position -1.8292018931241497e-09
        anchor -0.55 -0.1 0.5
      }
      device [
        DEF wheelFR RotationalMotor {
          name "wheelFR"
          maxTorque 30
        }
      ]
      endPoint DEF wheelFR Solid {
        translation -0.55 -0.1 0.5
        rotation -3.954030068500204e-09 3.950882621440112e-09 1 1.569999999999995
        children [
          DEF wheel Shape {
            appearance PBRAppearance {
              baseColor 0 0 0
              metalness 0
            }
            geometry Cylinder {
              height 0.1
              radius 0.3
            }
          }
        ]
        name "wheelFR"
        boundingObject USE wheel
        physics DEF physics_wheel Physics {
          density 10
        }
        linearVelocity -7.254344374432346e-08 8.488344248782648e-10 3.467682198720736e-08
        angularVelocity 8.385718298093584e-08 -7.93976193686151e-08 3.033673415725937e-07
      }
    }
    DEF car_body Shape {
      appearance PBRAppearance {
        baseColor 1 1 0
      }
      geometry Box {
        size 1 0.6 2
      }
    }
  ]
  name "Cab2"
  boundingObject USE car_body
  physics Physics {
    density 10
  }
  recognitionColors [
    0 0 0
  ]
  controller "controller"
  linearVelocity 1.671358689571932e-09 -1.1176844010167153e-11 6.4478633587467694e-09
  angularVelocity -8.313414198509614e-10 -7.982879747127662e-08 1.8206951238417406e-10
}
DEF environment Solid {
  scale 1.09819 1.09819 1.09819
  children [
    DEF PickUp1 BusStop {
      translation 0 0 -45
      rotation 0 1 0 3.14159
      name "PickUp1"
      bench FALSE
      appearance PBRAppearance {
        baseColor 0 0 0
        roughness 0.5
        metalness 0
      }
      internalAdvertisingTexture []
      externalAdvertisingTexture []
    }
    DEF PickUp2 BusStop {
      translation 45 0 0
      rotation 0 -1 0 -1.5707953071795862
      name "PickUp2"
      bench FALSE
      appearance PBRAppearance {
        baseColor 1 0 0
        roughness 0.5
        metalness 0
      }
      internalAdvertisingTexture []
      externalAdvertisingTexture []
      advertisingLightOn FALSE
    }
    DEF PickUp3 BusStop {
      translation 0 0 45
      rotation 0 1 0 -5.307179586466759e-06
      name "PickUp3"
      bench FALSE
      appearance PBRAppearance {
        baseColor 0 1 0
        roughness 0.5
        metalness 0
      }
      internalAdvertisingTexture []
      externalAdvertisingTexture []
      advertisingLightOn FALSE
    }
    DEF PickUp4 BusStop {
      translation -45 0 0
      rotation 0 1 0 -1.5707953071795862
      name "PickUp4"
      bench FALSE
      appearance PBRAppearance {
        baseColor 0 0 1
        roughness 0.5
        metalness 0
      }
      internalAdvertisingTexture []
      externalAdvertisingTexture []
      advertisingLightOn FALSE
    }
    DEF PickUp5 BusStop {
      translation 0 0 -71
      rotation 0 1 0 3.14159
      name "PickUp5"
      bench FALSE
      appearance PBRAppearance {
        baseColor 1 1 0
        roughness 0.5
        metalness 0
      }
      internalAdvertisingTexture []
      externalAdvertisingTexture []
      advertisingLightOn FALSE
    }
    DEF PickUp6 BusStop {
      translation 71 0 0
      rotation 0 -1 0 -1.5707953071795862
      name "PickUp6"
      bench FALSE
      appearance PBRAppearance {
        baseColor 1 0 1
        roughness 0.5
        metalness 0
      }
      internalAdvertisingTexture []
      externalAdvertisingTexture []
      advertisingLightOn FALSE
    }
    DEF PickUp7 BusStop {
      translation 0 0 71
      rotation 0 1 0 -5.307179586466759e-06
      name "PickUp7"
      bench FALSE
      appearance PBRAppearance {
        baseColor 0 1 1
        roughness 0.5
        metalness 0
      }
      internalAdvertisingTexture []
      externalAdvertisingTexture []
      advertisingLightOn FALSE
    }
    DEF PickUp8 BusStop {
      translation -71 0 0
      rotation 0 1 0 -1.5707953071795862
      name "PickUp8"
      bench FALSE
      appearance PBRAppearance {
        roughness 0.5
        metalness 0
      }
      internalAdvertisingTexture []
      externalAdvertisingTexture []
      advertisingLightOn FALSE
    }
    CurvedRoadSegment {
      translation -56 0 33
      rotation 0 1 0 -1.570796
      name "road(1)"
      width 6
      numberOfForwardLanes 2
      lines [
        RoadLine {
          type "continuous"
          width 0.3
        }
      ]
      rightBarrier TRUE
      leftBarrier TRUE
      bottom TRUE
      curvatureRadius 20
      appearance Asphalt {
        colorOverride 0 0 0
        IBLStrength 0
      }
      pavementAppearance StonePavement {
        colorOverride 0 0 0
      }
    }
    CurvedRoadSegment {
      translation -56 0 -33
      rotation 0 1 0 3.14
      name "road(7)"
      width 6
      numberOfForwardLanes 2
      lines [
        RoadLine {
          type "continuous"
          width 0.3
        }
      ]
      rightBarrier TRUE
      leftBarrier TRUE
      bottom TRUE
      curvatureRadius 20
      appearance Asphalt {
        colorOverride 0 0 0
        IBLStrength 0
      }
      pavementAppearance StonePavement {
        colorOverride 0 0 0
      }
    }
    CurvedRoadSegment {
      translation -33 0 -56
      rotation 0 1 0 3.14
      name "road(8)"
      width 6
      numberOfForwardLanes 2
      lines [
        RoadLine {
          type "continuous"
          width 0.3
        }
      ]
      rightBarrier TRUE
      leftBarrier TRUE
      bottom TRUE
      curvatureRadius 20
      appearance Asphalt {
        colorOverride 0 0 0
        IBLStrength 0
      }
      pavementAppearance StonePavement {
        colorOverride 0 0 0
      }
    }
    CurvedRoadSegment {
      translation 33 0 -56
      rotation 0 1 0 1.57
      name "road(9)"
      width 6
      numberOfForwardLanes 2
      lines [
        RoadLine {
          type "continuous"
          width 0.3
        }
      ]
      rightBarrier TRUE
      leftBarrier TRUE
      bottom TRUE
      curvatureRadius 20
      appearance Asphalt {
        colorOverride 0 0 0
        IBLStrength 0
      }
      pavementAppearance StonePavement {
        colorOverride 0 0 0
      }
    }
    CurvedRoadSegment {
      translation 56 0 -33
      rotation 0 1 0 1.57
      name "road(10)"
      width 6
      numberOfForwardLanes 2
      lines [
        RoadLine {
          type "continuous"
          width 0.3
        }
      ]
      rightBarrier TRUE
      leftBarrier TRUE
      bottom TRUE
      curvatureRadius 20
      appearance Asphalt {
        colorOverride 0 0 0
        IBLStrength 0
      }
      pavementAppearance StonePavement {
        colorOverride 0 0 0
      }
    }
    CurvedRoadSegment {
      translation 56 0 33
      name "road(11)"
      width 6
      numberOfForwardLanes 2
      lines [
        RoadLine {
          type "continuous"
          width 0.3
        }
      ]
      rightBarrier TRUE
      leftBarrier TRUE
      bottom TRUE
      curvatureRadius 20
      appearance Asphalt {
        colorOverride 0 0 0
        IBLStrength 0
      }
      pavementAppearance StonePavement {
        colorOverride 0 0 0
      }
    }
    CurvedRoadSegment {
      translation 33 0 56
      name "road(12)"
      width 6
      numberOfForwardLanes 2
      lines [
        RoadLine {
          type "continuous"
          width 0.3
        }
      ]
      rightBarrier TRUE
      leftBarrier TRUE
      bottom TRUE
      curvatureRadius 20
      appearance Asphalt {
        colorOverride 0 0 0
        IBLStrength 0
      }
      pavementAppearance StonePavement {
        colorOverride 0 0 0
      }
    }
    CurvedRoadSegment {
      translation -33 0 56
      rotation 0 1 0 -1.57
      name "road(13)"
      width 6
      numberOfForwardLanes 2
      lines [
        RoadLine {
          type "continuous"
          width 0.3
        }
      ]
      rightBarrier TRUE
      leftBarrier TRUE
      bottom TRUE
      curvatureRadius 20
      appearance Asphalt {
        colorOverride 0 0 0
        IBLStrength 0
      }
      pavementAppearance StonePavement {
        colorOverride 0 0 0
      }
    }
    RoadIntersection {
      translation -53 0 53
      rotation 0 1 0 0.785
      roadsWidth 6
      startRoadsLength [
        -0.1
      ]
      startRoadsStartLine [
        ""
        ""
      ]
      startRoadsLine [
        RoadLine {
          type "continuous"
          width 0.3
        }
      ]
      startRoadBorderWidth 0.5
      bottom TRUE
      appearance Asphalt {
        colorOverride 0 1 0.5
      }
    }
    RoadIntersection {
      translation 53 0 53
      rotation 0 1 0 0.785
      name "road intersection(1)"
      roadsWidth 6
      startRoadsLength [
        -0.1
      ]
      startRoadsStartLine [
        ""
        ""
      ]
      startRoadsLine [
        RoadLine {
          type "continuous"
          width 0.3
        }
      ]
      startRoadBorderWidth 0.5
      bottom TRUE
      appearance Asphalt {
        colorOverride 1 0 0.5
      }
    }
    RoadIntersection {
      translation 53 0 -53
      rotation 0 1 0 0.785
      name "road intersection(2)"
      roadsWidth 6
      startRoadsLength [
        -0.1
      ]
      startRoadsStartLine [
        ""
        ""
      ]
      startRoadsLine [
        RoadLine {
          type "continuous"
          width 0.3
        }
      ]
      startRoadBorderWidth 0.5
      bottom TRUE
      appearance Asphalt {
        colorOverride 0.5 0.5 0
      }
    }
    RoadIntersection {
      translation -53 0 -53
      rotation 0 1 0 0.785
      name "road intersection(3)"
      roadsWidth 6
      startRoadsLength [
        -0.1
      ]
      startRoadsStartLine [
        ""
        ""
      ]
      startRoadsLine [
        RoadLine {
          type "continuous"
          width 0.3
        }
      ]
      startRoadBorderWidth 0.5
      bottom TRUE
      appearance Asphalt {
        colorOverride 0.5 0.5 1
      }
    }
    StraightRoadSegment {
      translation -53 0 20
      name "road(20)"
      width 6
      numberOfForwardLanes 2
      lines [
        RoadLine {
          type "continuous"
          width 0.3
        }
      ]
      rightBarrier TRUE
      leftBarrier TRUE
      bottom TRUE
      length 30
      appearance Asphalt {
        colorOverride 0 0 0
        IBLStrength 0
      }
      pavementAppearance StonePavement {
        colorOverride 0 0 0
      }
    }
    AddLanesRoadSegment {
      translation -53 0 20
      rotation 0 1 0 3.14
      width 6
      length 10
      numberOfNewLanes 1
      newLaneLeft FALSE
      lines [
        RoadLine {
          type "continuous"
          width 0.3
        }
      ]
      rightBarrier TRUE
      leftBarrier TRUE
      bottom TRUE
      appearance Asphalt {
        colorOverride 0 0 0
        IBLStrength 0
      }
      pavementAppearance StonePavement {
        colorOverride 0 0 0
      }
    }
    StraightRoadSegment {
      translation -51.5 0 -10
      name "road(17)"
      width 9
      numberOfLanes 3
      numberOfForwardLanes 2
      lines [
        RoadLine {
          type "continuous"
          width 0.3
        }
        RoadLine {
          type "continuous"
          width 0.3
        }
      ]
      rightBarrier TRUE
      leftBarrier TRUE
      bottom TRUE
      length 20
      appearance Asphalt {
        colorOverride 0 0 0
        IBLStrength 0
      }
      pavementAppearance StonePavement {
        colorOverride 0 0 0
      }
    }
    AddLanesRoadSegment {
      translation -53 0 -20
      name "road(3)"
      width 6
      length 10
      numberOfNewLanes 1
      lines [
        RoadLine {
          type "continuous"
          width 0.3
        }
      ]
      rightBarrier TRUE
      leftBarrier TRUE
      bottom TRUE
      appearance Asphalt {
        colorOverride 0 0 0
        IBLStrength 0
      }
      pavementAppearance StonePavement {
        colorOverride 0 0 0
      }
    }
    StraightRoadSegment {
      translation -53 0 -50
      name "road(5)"
      width 6
      numberOfForwardLanes 2
      lines [
        RoadLine {
          type "continuous"
          width 0.3
        }
      ]
      rightBarrier TRUE
      leftBarrier TRUE
      bottom TRUE
      length 30
      appearance Asphalt {
        colorOverride 0 0 0
        IBLStrength 0
      }
      pavementAppearance StonePavement {
        colorOverride 0 0 0
      }
    }
    StraightRoadSegment {
      translation -50 0 -53
      rotation 0 1 0 1.57
      name "road(4)"
      width 6
      numberOfForwardLanes 2
      lines [
        RoadLine {
          type "continuous"
          width 0.3
        }
      ]
      rightBarrier TRUE
      leftBarrier TRUE
      bottom TRUE
      length 30
      appearance Asphalt {
        colorOverride 0 0 0
        IBLStrength 0
      }
      pavementAppearance StonePavement {
        colorOverride 0 0 0
      }
    }
    AddLanesRoadSegment {
      translation -10 0 -51.5
      rotation 0 1 0 -1.57
      name "road(2)"
      width 9
      length 10
      numberOfLanes 3
      numberOfNewLanes 1
      lines [
        RoadLine {
          type "continuous"
          width 0.3
        }
        RoadLine {
        }
      ]
      rightBarrier TRUE
      leftBarrier TRUE
      bottom TRUE
      appearance Asphalt {
        colorOverride 0 0 0
        IBLStrength 0
      }
      pavementAppearance StonePavement {
        colorOverride 0 0 0
      }
    }
    StraightRoadSegment {
      translation -10 0 -51.5
      rotation 0 1 0 1.571
      name "road(18)"
      width 9
      numberOfLanes 3
      numberOfForwardLanes 2
      lines [
        RoadLine {
          type "continuous"
          width 0.3
        }
        RoadLine {
          type "continuous"
          width 0.3
        }
      ]
      rightBarrier TRUE
      leftBarrier TRUE
      bottom TRUE
      length 20
      appearance Asphalt {
        colorOverride 0 0 0
        IBLStrength 0
      }
      pavementAppearance StonePavement {
        colorOverride 0 0 0
      }
    }
    AddLanesRoadSegment {
      translation 10 0 -51.5
      rotation 0 1 0 1.57
      name "road(19)"
      width 9
      length 10
      numberOfLanes 3
      numberOfNewLanes 1
      newLaneLeft FALSE
      lines [
        RoadLine {
          type "continuous"
          width 0.3
        }
        RoadLine {
        }
      ]
      rightBarrier TRUE
      leftBarrier TRUE
      bottom TRUE
      appearance Asphalt {
        colorOverride 0 0 0
        IBLStrength 0
      }
      pavementAppearance StonePavement {
        colorOverride 0 0 0
      }
    }
    CurvedRoadSegment {
      translation 20 0 -36.6
      rotation 0 1 0 1.571
      name "road(33)"
      width 6
      numberOfForwardLanes 2
      lines [
        RoadLine {
          type "continuous"
          width 0.3
        }
      ]
      roadBorderWidth [
        0
      ]
      rightBarrier TRUE
      leftBarrier TRUE
      bottom TRUE
      totalAngle 3.14
      subdivision 21
      appearance Asphalt {
        colorOverride 0 0 0
        IBLStrength 0
      }
      pavementAppearance StonePavement {
        colorOverride 0 0 0
      }
    }
    StraightRoadSegment {
      translation -20 0 -26.6
      rotation 0 1 0 1.571
      name "road(35)"
      width 6
      numberOfForwardLanes 2
      lines [
        RoadLine {
          type "continuous"
          width 0.3
        }
      ]
      rightBarrier TRUE
      leftBarrier TRUE
      bottom TRUE
      length 40
      appearance Asphalt {
        colorOverride 0 0 0
        IBLStrength 0
      }
      pavementAppearance StonePavement {
        colorOverride 0 0 0
      }
    }
    CurvedRoadSegment {
      translation -20 0 -36.6
      rotation 0 1 0 -1.571
      name "road(34)"
      width 6
      numberOfForwardLanes 2
      lines [
        RoadLine {
          type "continuous"
          width 0.3
        }
      ]
      roadBorderWidth [
        0
      ]
      rightBarrier TRUE
      leftBarrier TRUE
      bottom TRUE
      totalAngle 3.14
      subdivision 21
      appearance Asphalt {
        colorOverride 0 0 0
        IBLStrength 0
      }
      pavementAppearance StonePavement {
        colorOverride 0 0 0
      }
    }
    StraightRoadSegment {
      translation 20 0 -53
      rotation 0 1 0 1.57
      name "road(21)"
      width 6
      numberOfForwardLanes 2
      lines [
        RoadLine {
          type "continuous"
          width 0.3
        }
      ]
      rightBarrier TRUE
      leftBarrier TRUE
      bottom TRUE
      length 30
      appearance Asphalt {
        colorOverride 0 0 0
        IBLStrength 0
      }
      pavementAppearance StonePavement {
        colorOverride 0 0 0
      }
    }
    StraightRoadSegment {
      translation 53 0 -50
      name "road(22)"
      width 6
      numberOfForwardLanes 2
      lines [
        RoadLine {
          type "continuous"
          width 0.3
        }
      ]
      rightBarrier TRUE
      leftBarrier TRUE
      bottom TRUE
      length 30
      appearance Asphalt {
        colorOverride 0 0 0
        IBLStrength 0
      }
      pavementAppearance StonePavement {
        colorOverride 0 0 0
      }
    }
    AddLanesRoadSegment {
      translation 53 0 -20
      name "road(23)"
      width 6
      length 10
      numberOfNewLanes 1
      newLaneLeft FALSE
      lines [
        RoadLine {
          type "continuous"
          width 0.3
        }
      ]
      rightBarrier TRUE
      leftBarrier TRUE
      bottom TRUE
      appearance Asphalt {
        colorOverride 0 0 0
        IBLStrength 0
      }
      pavementAppearance StonePavement {
        colorOverride 0 0 0
      }
    }
    StraightRoadSegment {
      translation 51.5 0 -10
      name "road(24)"
      width 9
      numberOfLanes 3
      numberOfForwardLanes 2
      lines [
        RoadLine {
          type "continuous"
          width 0.3
        }
        RoadLine {
          type "continuous"
          width 0.3
        }
      ]
      rightBarrier TRUE
      leftBarrier TRUE
      bottom TRUE
      length 20
      appearance Asphalt {
        colorOverride 0 0 0
        IBLStrength 0
      }
      pavementAppearance StonePavement {
        colorOverride 0 0 0
      }
    }
    AddLanesRoadSegment {
      translation 53 0 20
      rotation 0 1 0 3.14
      name "road(25)"
      width 6
      length 10
      numberOfNewLanes 1
      lines [
        RoadLine {
          type "continuous"
          width 0.3
        }
      ]
      rightBarrier TRUE
      leftBarrier TRUE
      bottom TRUE
      appearance Asphalt {
        colorOverride 0 0 0
        IBLStrength 0
      }
      pavementAppearance StonePavement {
        colorOverride 0 0 0
      }
    }
    StraightRoadSegment {
      translation 53 0 20
      name "road(26)"
      width 6
      numberOfForwardLanes 2
      lines [
        RoadLine {
          type "continuous"
          width 0.3
        }
      ]
      rightBarrier TRUE
      leftBarrier TRUE
      bottom TRUE
      length 30
      appearance Asphalt {
        colorOverride 0 0 0
        IBLStrength 0
      }
      pavementAppearance StonePavement {
        colorOverride 0 0 0
      }
    }
    StraightRoadSegment {
      translation 20 0 53
      rotation 0 1 0 1.57
      name "road(27)"
      width 6
      numberOfForwardLanes 2
      lines [
        RoadLine {
          type "continuous"
          width 0.3
        }
      ]
      rightBarrier TRUE
      leftBarrier TRUE
      bottom TRUE
      length 30
      appearance Asphalt {
        colorOverride 0 0 0
        IBLStrength 0
      }
      pavementAppearance StonePavement {
        colorOverride 0 0 0
      }
    }
    AddLanesRoadSegment {
      translation 20 0 53
      rotation 0 1 0 -1.57
      name "road(28)"
      width 6
      length 10
      numberOfNewLanes 1
      newLaneLeft FALSE
      lines [
        RoadLine {
          type "continuous"
          width 0.3
        }
      ]
      rightBarrier TRUE
      leftBarrier TRUE
      bottom TRUE
      appearance Asphalt {
        colorOverride 0 0 0
        IBLStrength 0
      }
      pavementAppearance StonePavement {
        colorOverride 0 0 0
      }
    }
    StraightRoadSegment {
      translation -10 0 51.5
      rotation 0 1 0 1.57
      name "road(29)"
      width 9
      numberOfLanes 3
      numberOfForwardLanes 2
      lines [
        RoadLine {
          type "continuous"
          width 0.3
        }
        RoadLine {
          type "continuous"
          width 0.3
        }
      ]
      rightBarrier TRUE
      leftBarrier TRUE
      bottom TRUE
      length 20
      appearance Asphalt {
        colorOverride 0 0 0
        IBLStrength 0
      }
      pavementAppearance StonePavement {
        colorOverride 0 0 0
      }
    }
    AddLanesRoadSegment {
      translation -20 0 53
      rotation 0 1 0 1.57
      name "road(30)"
      width 6
      length 10
      numberOfNewLanes 1
      lines [
        RoadLine {
          type "continuous"
          width 0.3
        }
      ]
      rightBarrier TRUE
      leftBarrier TRUE
      bottom TRUE
      appearance Asphalt {
        colorOverride 0 0 0
        IBLStrength 0
      }
      pavementAppearance StonePavement {
        colorOverride 0 0 0
      }
    }
    StraightRoadSegment {
      translation -50 0 53
      rotation 0 1 0 1.57
      name "road(32)"
      width 6
      numberOfForwardLanes 2
      lines [
        RoadLine {
          type "continuous"
          width 0.3
        }
      ]
      rightBarrier TRUE
      leftBarrier TRUE
      bottom TRUE
      length 30
      appearance Asphalt {
        colorOverride 0 0 0
        IBLStrength 0
      }
      pavementAppearance StonePavement {
        colorOverride 0 0 0
      }
    }
    StraightRoadSegment {
      translation 53 0 20
      name "road(31)"
      width 6
      numberOfForwardLanes 2
      lines [
        RoadLine {
          type "continuous"
          width 0.3
        }
      ]
      rightBarrier TRUE
      leftBarrier TRUE
      bottom TRUE
      length 30
      appearance Asphalt {
        colorOverride 0 0 0
        IBLStrength 0
      }
      pavementAppearance StonePavement {
        colorOverride 0 0 0
      }
    }
    StraightRoadSegment {
      translation -76 0 -33
      name "road(6)"
      width 6
      numberOfForwardLanes 2
      lines [
        RoadLine {
          type "continuous"
          width 0.3
        }
      ]
      rightBarrier TRUE
      leftBarrier TRUE
      bottom TRUE
      length 66
      appearance Asphalt {
        colorOverride 0 0 0
        IBLStrength 0
      }
      pavementAppearance StonePavement {
        colorOverride 0 0 0
      }
    }
    StraightRoadSegment {
      translation -33 0 -76
      rotation 0 1 0 1.57
      name "road(14)"
      width 6
      numberOfForwardLanes 2
      lines [
        RoadLine {
          type "continuous"
          width 0.3
        }
      ]
      rightBarrier TRUE
      leftBarrier TRUE
      bottom TRUE
      length 66
      appearance Asphalt {
        colorOverride 0 0 0
        IBLStrength 0
      }
      pavementAppearance StonePavement {
        colorOverride 0 0 0
      }
    }
    StraightRoadSegment {
      translation 76 0 -33
      name "road(15)"
      width 6
      numberOfForwardLanes 2
      lines [
        RoadLine {
          type "continuous"
          width 0.3
        }
      ]
      rightBarrier TRUE
      leftBarrier TRUE
      bottom TRUE
      length 66
      appearance Asphalt {
        colorOverride 0 0 0
        IBLStrength 0
      }
      pavementAppearance StonePavement {
        colorOverride 0 0 0
      }
    }
    StraightRoadSegment {
      translation -33 0 76
      rotation 0 1 0 1.57
      name "road(16)"
      width 6
      numberOfForwardLanes 2
      lines [
        RoadLine {
          type "continuous"
          width 0.3
        }
      ]
      rightBarrier TRUE
      leftBarrier TRUE
      bottom TRUE
      length 66
      appearance Asphalt {
        colorOverride 0 0 0
        IBLStrength 0
      }
      pavementAppearance StonePavement {
        colorOverride 0 0 0
      }
    }
  ]
  name "environment"
}
Floor {
  size 176 176
  tileSize 0.1 0.1
  appearance PBRAppearance {
    baseColor 0.5 0.5 0.5
    transparency 0.9
    metalness 0
  }
}
